Workbook

Sheet Trading Multiples
A1: Company Comp Set
A2: Company Name | B2: EV/Total Revenue | C2: EV/EBITDA | D2: TEV/EBIT LTM - Latest | E2: P/E | F2: P/TangBV LTM - Latest | G2: NTM TEV/Forward Total Revenue (Capital IQ) | H2: NTM TEV/Forward EBITDA (Capital IQ) | I2: NTM Forward P/E (Capital IQ)
A3: The TJX Companies, Inc. (NYSE:TJX) | B3: 2.5 | C3: 13 | D3: 22.6 | E3: 28.1 | F3: 16.4 | G3: 2.41 | H3: 18.15 | I3: 26.6
A4: Kohl's Corporation (NYSE:KSS) | B4: 0.5 | C4: 5.3 | D4: 16.2 | E4: 9.3 | F4: 0.3 | G4: 0.55 | H4: 7.31 | I4: 23.07
A5: The Gap, Inc. (NYSE:GAP) | B5: 0.7 | C5: 3.8 | D5: 9.8 | E5: 9.8 | F5: 2.7 | G5: 0.72 | H5: 6.32 | I5: 8.97
A6: Nordstrom, Inc. (NYSE:JWN) | B6: 0.5 | C6: 4.8 | D6: 13.4 | E6: 14 | F6: 4.5 | G6: 0.48 | H6: 6.27 | I6: 11.11
A7: Dillard's, Inc. (NYSE:DDS) | B7: 0.8 | C7: 5.7 | D7: 7.2 | E7: 10 | F7: 3.3 | G7: 0.83 | H7: 7.08 | I7: 12.85
A8: Macy's, Inc. (NYSE:M) | B8: =75700/'Implied Valuation'!B3 -> 3.1718763 | C8: =75700/'Implied Valuation'!C3 -> 59.936659 | D8: 9.4 | E8: =11/0.16 -> 68.75 | F8: =11/(4035/278) -> 0.75786865 | G8: 0.4 | H8: 4.69 | I8: 6.42
A10: Summary Statistics | B10: TEV/Total Revenues LTM - Latest | C10: TEV/EBITDA LTM - Latest | D10: TEV/EBIT LTM - Latest | E10: P/Diluted EPS Before Extra LTM - Latest | F10: P/TangBV LTM - Latest | G10: NTM TEV/Forward Total Revenue (Capital IQ) | H10: NTM TEV/Forward EBITDA (Capital IQ) | I10: NTM Forward P/E (Capital IQ)
A11: High | B11: =MAX(B3:B7) -> 2.5 | C11: =MAX(C3:C7) -> 13 | D11: =MAX(D3:D7) -> 22.6 | E11: =MAX(E3:E7) -> 28.1 | F11: =MAX(F3:F7) -> 16.4 | G11: =MAX(G3:G7) -> 2.41 | H11: =MAX(H3:H7) -> 18.15 | I11: =MAX(I3:I7) -> 26.6
A12: Low | B12: =MIN(B3:B7) -> 0.5 | C12: =MIN(C3:C7) -> 3.8 | D12: =MIN(D3:D7) -> 7.2 | E12: =MIN(E3:E7) -> 9.3 | F12: =MIN(F3:F7) -> 0.3 | G12: =MIN(G3:G7) -> 0.48 | H12: =MIN(H3:H7) -> 6.27 | I12: =MIN(I3:I7) -> 8.97
A13: Mean | B13: =AVERAGE(B3:B7) -> 1 | C13: =AVERAGE(C3:C7) -> 6.52 | D13: =AVERAGE(D3:D7) -> 13.84 | E13: =AVERAGE(E3:E7) -> 14.24 | F13: =AVERAGE(F3:F7) -> 5.44 | G13: =AVEDEV(G3:G7) -> 0.5648 | H13: =AVEDEV(H3:H7) -> 3.6496 | I13: =AVEDEV(I3:I7) -> 6.652
A14: Median | B14: =MEDIAN(B3:B7) -> 0.7 | C14: =MEDIAN(C3:C7) -> 5.3 | D14: =MEDIAN(D3:D7) -> 13.4 | E14: =MEDIAN(E3:E7) -> 10 | F14: =MEDIAN(F3:F7) -> 3.3 | G14: =MEDIAN(G3:G7) -> 0.72 | H14: =MEDIAN(H3:H7) -> 7.08 | I14: =MEDIAN(I3:I7) -> 12.85

Sheet Implied Valuation
A1: Company Comp Set
A2: Company Name | B2: LTM Total Revenue | C2: LTM EBITDA | D2: LTM EBIT | E2: NTM Revenue (Capital IQ) | F2: NTM EBITDA (Capital IQ) | G2: LTM Basic EPS | H2: NTM EPS (Capital IQ) | I2: LTM Tangible Book Value/Share
A3: Macy's, Inc. (NYSE:M) | B3: 23866 | C3: 1263 | D3: 913 | E3: 21372 | F3: -1490.7 | G3: =0.16 -> 0.16 | H3: 0.1 | I3: 8.99
E5: Total Enterprise Value Multiples | H5: Pricing Multiples
B6: LTM TEV/Total Revenues | C6: LTM TEV/EBITDA | D6: LTM TEV/EBIT | E6: NTM TEV/Forward Total Revenue | F6: NTM TEV/Forward EBITDA | G6: LTM P/Diluted EPS Before Extra | H6: NTM Forward P/E | I6: LTM P/TangBV
A7: High | B7: ='[1]Trading Multiples'!B11 -> 2.5 | C7: ='[1]Trading Multiples'!C11 -> 13 | D7: ='[1]Trading Multiples'!D11 -> 22.6 | E7: ='[1]Trading Multiples'!G11 -> 2.41 | F7: ='[1]Trading Multiples'!H11 -> 18.15 | G7: ='[1]Trading Multiples'!E11 -> 28.1 | H7: ='[1]Trading Multiples'!I11 -> 26.6 | I7: ='[1]Trading Multiples'!F11 -> 16.4
A8: Low | B8: ='[1]Trading Multiples'!B12 -> 0.5 | C8: ='[1]Trading Multiples'!C12 -> 3.8 | D8: 7.2 | E8: ='[1]Trading Multiples'!G12 -> 0.48 | F8: ='[1]Trading Multiples'!H12 -> 6.27 | G8: ='[1]Trading Multiples'!E12 -> 9.3 | H8: ='[1]Trading Multiples'!I12 -> 8.97 | I8: ='[1]Trading Multiples'!F12 -> 0.3
A9: Mean | B9: ='[1]Trading Multiples'!B13 -> 1 | C9: ='[1]Trading Multiples'!C13 -> 6.52 | D9: 4.448 | E9: ='[1]Trading Multiples'!G13 -> 0.5648 | F9: ='[1]Trading Multiples'!H13 -> 3.6496 | G9: ='[1]Trading Multiples'!E13 -> 14.24 | H9: ='[1]Trading Multiples'!I13 -> 6.652 | I9: ='[1]Trading Multiples'!F13 -> 5.44
A10: Median | B10: ='[1]Trading Multiples'!B14 -> 0.7 | C10: ='[1]Trading Multiples'!C14 -> 5.3 | D10: 13.4 | E10: ='[1]Trading Multiples'!G14 -> 0.72 | F10: ='[1]Trading Multiples'!H14 -> 7.08 | G10: ='[1]Trading Multiples'!E14 -> 10 | H10: ='[1]Trading Multiples'!I14 -> 12.85 | I10: ='[1]Trading Multiples'!F14 -> 3.3
A12: Implied Enterprise Value
A13: High | B13: =B$3*B7 -> 59665 | C13: =C$3*C7 -> 16419 | D13: =D$3*D7 -> 20633.8 | E13: =E$3*E7 -> 51506.52 | F13: =F$3*F7 -> -27056.205
A14: Low | B14: =B$3*B8 -> 11933 | C14: =C$3*C8 -> 4799.4 | D14: =D$3*D8 -> 6573.6 | E14: =E$3*E8 -> 10258.56 | F14: =F$3*F8 -> -9346.689
A15: Mean | B15: =B$3*B9 -> 23866 | C15: =C$3*C9 -> 8234.76 | D15: =D$3*D9 -> 4061.024 | E15: =E$3*E9 -> 12070.906 | F15: =F$3*F9 -> -5440.4587
A16: Median | B16: =B$3*B10 -> 16706.2 | C16: =C$3*C10 -> 6693.9 | D16: =D$3*D10 -> 12234.2 | E16: =E$3*E10 -> 15387.84 | F16: =F$3*F10 -> -10554.156
A18: + Total Cash & ST Investments | B18: 1306 | C18: 1306 | D18: 1306 | E18: 1306 | F18: 1306
A19: - Total Debt | B19: 6073 | C19: 6073 | D19: 6073 | E19: 6073 | F19: 6073
A20: - Total Pref. Equity | B20: - | C20: - | D20: - | E20: - | F20: -
A21: - Minority Interest | B21: - | C21: - | D21: - | E21: - | F21: -
A23: = Implied Equity Value
A24: High | B24: =B13+B$18-B$19 -> 54898 | C24: =C13+C$18-C$19 -> 11652 | D24: =D13+D$18-D$19 -> 15866.8 | E24: =E13+E$18-E$19 -> 46739.52 | F24: =F13+F$18-F$19 -> -31823.205 | G24: =G$3*G7*G$29 -> 1249.888 | H24: =H$3*H7*H$29 -> 739.48 | I24: =I$3*I7*I$29 -> 40987.208
A25: Low | B25: =B14+B$18-B$19 -> 7166 | C25: =C14+C$18-C$19 -> 32.4 | D25: =D14+D$18-D$19 -> 1806.6 | E25: =E14+E$18-E$19 -> 5491.56 | F25: =F14+F$18-F$19 -> -14113.689 | G25: =G$3*G8*G$29 -> 413.664 | H25: =H$3*H8*H$29 -> 249.366 | I25: =I$3*I8*I$29 -> 749.766
A26: Mean | B26: =B15+B$18-B$19 -> 19099 | C26: =C15+C$18-C$19 -> 3467.76 | D26: =D15+D$18-D$19 -> -705.976 | E26: =E15+E$18-E$19 -> 7303.9056 | F26: =F15+F$18-F$19 -> -10207.459 | G26: =G$3*G9*G$29 -> 633.3952 | H26: =H$3*H9*H$29 -> 184.9256 | I26: =I$3*I9*I$29 -> 13595.757
A27: Median | B27: =B16+B$18-B$19 -> 11939.2 | C27: =C16+C$18-C$19 -> 1926.9 | D27: =D16+D$18-D$19 -> 7467.2 | E27: =E16+E$18-E$19 -> 10620.84 | F27: =F16+F$18-F$19 -> -15321.156 | G27: =G$3*G10*G$29 -> 444.8 | H27: =H$3*H10*H$29 -> 357.23 | I27: =I$3*I10*I$29 -> 8247.426
A29: / Shares Outstanding | B29: 278 | C29: 278 | D29: 278 | E29: 278 | F29: 278 | G29: 278 | H29: 278 | I29: 278
A31: = Implied Price per Share
A32: High | B32: =B24/B$29 -> 197.47482 | C32: =C24/C$29 -> 41.913669 | D32: =D24/D$29 -> 57.07482 | E32: =E24/E$29 -> 168.12777 | F32: =F24/F$29 -> -114.47196 | G32: =G24/G$29 -> 4.496 | H32: =H24/H$29 -> 2.66 | I32: =I24/I$29 -> 147.436
A33: Low | B33: =B25/B$29 -> 25.776978 | C33: =C25/C$29 -> 0.11654676 | D33: =D25/D$29 -> 6.4985612 | E33: =E25/E$29 -> 19.753813 | F33: =F25/F$29 -> -50.768665 | G33: =G25/G$29 -> 1.488 | H33: =H25/H$29 -> 0.897 | I33: =I25/I$29 -> 2.697
A34: Mean | B34: =B26/B$29 -> 68.701439 | C34: =C26/C$29 -> 12.473957 | D34: =D26/D$29 -> -2.539482 | E34: =E26/E$29 -> 26.273042 | F34: =F26/F$29 -> -36.717477 | G34: =G26/G$29 -> 2.2784 | H34: =H26/H$29 -> 0.6652 | I34: =I26/I$29 -> 48.9056
A35: Median | B35: =B27/B$29 -> 42.946763 | C35: =C27/C$29 -> 6.931295 | D35: =D27/D$29 -> 26.860432 | E35: =E27/E$29 -> 38.20446 | F35: =F27/F$29 -> -55.112072 | G35: =G27/G$29 -> 1.6 | H35: =H27/H$29 -> 1.285 | I35: =I27/I$29 -> 29.667
A37: Mean Equity Value Across Multiples | B37: Equity Value | C37: Price Per Share
A38: High | B38: =AVERAGE(B24:I24) -> 17538.711 | C38: =B38/C$29 -> 63.08889
A39: Low | B39: =AVERAGE(B25:I25) -> 224.45837 | C39: =B39/C$29 -> 0.80740423
A40: Mean | B40: =AVERAGE(B26:I26) -> 4171.4136 | C40: =B40/C$29 -> 15.005085
A41: Median | B41: =AVERAGE(B27:I27) -> 3210.305 | C41: =B41/C$29 -> 11.54786

Sheet Cover
A1: Macy's, Inc. (NYSE:"M")
A2: Financial Statements (Exported from S&P Cap IQ)
A4: Template: | B4: Standard | D4: Restatement: | E4: Latest Filings
A5: Period Type: | B5: Annual | D5: Order: | E5: Latest on Right
A6: Currency: | B6: US Dollar | D6: Conversion: | E6: Historical
A7: Units: | B7: Millions (mm) | D7: Decimals: | E7: Capital IQ (Default)
A8: Source: | B8: Capital IQ & Proprietary Data

Sheet Key Stats
A5: Macy's, Inc. (NYSE:M) > Financials > Key Stats
A7: In Millions of USD, except per share items. | B7: Currency: | C7: US Dollar | E7: Conversion: | F7: Historical
B8: Order: | C8: Latest on Right | E8: Units: | F8: Millions (mm)
B9: Decimals: | C9: Capital IQ (Default) | E9: Dilution: | F9: Basic
A12: Key Financials¹ | B12: 2019A | C12: 2020A | D12: 2021A | E12: 2022A | F12: 2023A | G12: 2024A | H12: 2025A | I12: 2025E
A13: For the Fiscal Period Ending | B13: 12 months Feb-02-2019A | C13: 12 months Feb-01-2020A | D13: 12 months Jan-30-2021A | E13: 12 months Jan-29-2022A | F13: 12 months Jan-28-2023A | G13: 12 months Feb-03-2024A | H13: 12 months Feb-01-2025A | I13: 12 months† Jan-31-2026E
A14: Currency | B14: USD | C14: USD | D14: USD | E14: USD | F14: USD | G14: USD | H14: USD | I14: USD
A16: Total Revenue | B16: 25739 | C16: 25331 | D16: 18097 | E16: 25399 | F16: 25449 | G16: 23866 | H16: 23006 | I16: 21240.837
A17: Growth Over Prior Year | B17: 0.003822 | C17: -0.015852 | D17: -0.285579 | E17: 0.403492 | F17: 0.001968 | G17: -0.062203 | H17: -0.036035 | I17: -
A19: Gross Profit | B19: 10524 | C19: 10160 | D19: 5811 | E19: 10443 | F19: 10102 | G19: 9642 | H19: 9266 | I19: -
A20: Margin % | B20: 0.408873 | C20: 0.401089 | D20: 0.321102 | E20: 0.411157 | F20: 0.39695 | G20: 0.404005 | H20: 0.402764 | I20: 0.3905
A22: EBITDA | B22: 2198 | C22: 1855 | D22: -211 | E22: 2970 | F22: 2262 | G22: 1891 | H22: 1484 | I22: 1820.5283
A23: Margin % | B23: 0.085395 | C23: 0.07323 | D23: -0.011659 | E23: 0.116933 | F23: 0.088883 | G23: 0.079234 | H23: 0.064504 | I23: 0.085708875
A25: EBIT | B25: 1532 | C25: 1159 | D25: -902 | E25: 2334 | F25: 1640 | G25: 1263 | H25: 913 | I25: 895.74194
A26: Margin % | B26: 0.05952 | C26: 0.045754 | D26: -0.049842 | E26: 0.091893 | F26: 0.064442 | G26: 0.05292 | H26: 0.039685 | I26: 0.042170746
A28: Earnings from Cont. Ops. | B28: 1098 | C28: 564 | D28: -3944 | E28: 1430 | F28: 1146 | G28: 45 | H28: 582 | I28: -
A29: Margin % | B29: 0.042658 | C29: 0.022265 | D29: -0.217936 | E29: 0.056301 | F29: 0.045031 | G29: 0.001885 | H29: 0.025297 | I29: -
A31: Net Income | B31: 1108 | C31: 564 | D31: -3944 | E31: 1430 | F31: 1146 | G31: 45 | H31: 582 | I31: 594.09608
A32: Margin % | B32: 0.043047 | C32: 0.022265 | D32: -0.217936 | E32: 0.056301 | F32: 0.045031 | G32: 0.001885 | H32: 0.025297 | I32: 0.027969523
A34: Diluted EPS Excl. Extra Items³ | B34: 3.56 | C34: 1.81 | D34: -12.68 | E34: 4.55 | F34: 4.08 | G34: 0.16 | H34: 2.07 | I34: 2.11394
A35: Growth Over Prior Year | B35: -0.301961 | C35: -0.491574 | D35: NM | E35: NM | F35: -0.103297 | G35: -0.960785 | H35: 11.9375 | I35: -
A37: Same Store Sales Growth % | B37: 0.017 | C37: -0.008 | D37: -0.279 | E37: 0.43 | F37: 0.003 | G37: -0.069 | H37: -0.02 | I37: -
A39: Currency | B39: USD | C39: USD | D39: USD | E39: USD | F39: USD | G39: USD | H39: USD | I39: USD
A40: Exchange Rate | B40: 1 | C40: 1 | D40: 1 | E40: 1 | F40: 1 | G40: 1 | H40: 1 | I40: 1
A41: Conversion Method | B41: H | C41: H | D41: H | E41: H | F41: H | G41: H | H41: H | I41: S
A43: ¹All results are taken from the most recently filed statement for each period. When there has been more than one, earlier filings can be viewed on the individual statement pages.
A44: ³All forward period figures are consensus mean estimates provided by the brokers and may not be on a comparable basis as financials.
A45: †Growth rates for forward periods are calculated against prior period estimates or actual pro forma results as disclosed on the Estimates Consensus page.
A46: Growth Rates are calculated in originally reported currency only and will not reflect any currency conversion selected above.
A48: Current Capitalization (Millions of USD)
A49: Currency | B49: USD
A50: Share Price | B50: 13.24
A51: Shares Out. | B51: 277.71764
A53: Market Capitalization | B53: 3676.9815 | C53: =B53*10^6 -> 3676981513
A54: - Cash & Short Term Investments | B54: 1306 | C54: =C53/10^9 -> 3.6769815
A55: + Total Debt | B55: 6073
A56: + Pref. Equity | B56: -
A57: + Total Minority Interest | B57: -
A58: - Long Term Marketable Securities | B58: -
A59: = Total Enterprise Value (TEV) | B59: 8443.9815
...

Sheet FA
A1: FA - Financial Analysis
A2: don't have to necessary analyse every formula below: | L2: FYs
A3: 1) Profitability (IS) | J3: 1) Profitability | L3: 2019 | M3: 2020 | N3: 2021 | O3: 2022 | P3: 2023 | Q3: 2024
J4: Gross Margin | L4: 0.40887369 | M4: 0.40108957 | N4: 0.32110295 | O4: 0.40866677 | P4: 0.39856183 | Q4: 0.40739965
A5: Gross Margin = (Revenue - COGS) / Revenue | J5: Gross Margin (%) | L5: =L4 -> 0.40887369 | M5: =M4 -> 0.40108957 | N5: =N4 -> 0.32110295 | O5: =O4 -> 0.40866677 | P5: =P4 -> 0.39856183 | Q5: =Q4 -> 0.40739965
A6: Operating Margin = Operating Income / Revenue
A7: Net Profit Margin = Net Income / Revenue | J7: EBITDA Margin | L7: 0.067523991 | M7: 0.038293001 | N7: -0.24727855 | O7: 0.092914756 | P7: 0.067979095 | Q7: 0.016006034
A8: Return on Assets (ROA) = Net Income / Average Total Assets | J8: EBITDA Margin (%) | L8: =L7 -> 0.067523991 | M8: =M7 -> 0.038293001 | N8: =N7 -> -0.24727855 | O8: =O7 -> 0.092914756 | P8: =P7 -> 0.067979095 | Q8: =Q7 -> 0.016006034
A9: Return on Equity (ROE) = Net Income / Average Shareholders’ Equity
A10: Return on Invested Capital (ROIC) = NOPAT / Average Invested Capital | J10: Net Profit Margin | L10: 0.043047515 | M10: 0.022265209 | N10: -0.21793667 | O10: 0.056539617 | P10: 0.046249361 | Q10: 0.0043995642
J11: Net Profit Margin (%) | L11: =L10 -> 0.043047515 | M11: =M10 -> 0.022265209 | N11: =N10 -> -0.21793667 | O11: =O10 -> 0.056539617 | P11: =P10 -> 0.046249361 | Q11: =Q10 -> 0.0043995642
A13: 2) Liquidity (BS) | J13: ROA | L13: 0.057726373 | M13: 0.026638957 | N13: -0.22274935 | O13: 0.081296191 | P13: 0.069785367 | Q13: 0.0064631294
J14: ROE | L14: 0.17215662 | M14: 0.088442841 | N14: -1.5448492 | O14: 0.39491853 | P14: 0.28833905 | Q14: 0.025380711
A15: Current Ratio = Current Assets / Current Liabilities
A16: Quick Ratio = (Current Assets - Inventory) / Current Liabilities
L17: FYs
J18: 2) Liquidity | L18: 2019 | M18: 2020 | N18: 2021 | O18: 2022 | P18: 2023 | Q18: 2024
A19: 3) Leverage & Solvency (BS) | J19: Current Ratio | L19: 1.422974 | M19: 1.1843478 | N19: 1.1543775 | O19: 1.2477843 | P19: 1.2040732 | Q19: 1.3744921
A21: Debt-to-Equity = Total Debt / Shareholders’ Equity | J21: Quick Ratio | L21: 0.41704893 | M21: 0.28208696 | N21: 0.44987866 | O21: 0.43851551 | P21: 0.32627031 | Q21: 0.39006772
A22: Debt-to-Assets = Total Debt / Total Assets
A23: Interest Coverage Ratio = EBIT / Interest Expense
A24: Debt Service Coverage Ratio (DSCR) = EBITDA / Total Debt Service | L24: FYs
J25: 3) Leverage & Solvency | L25: 2019 | M25: 2020 | N25: 2021 | O25: 2022 | P25: 2023 | Q25: 2024
J26: Debt-to-Equity
A27: 4) Efficiency (BS & IS) | J27: Debt-to-Assets
J28: Interest Coverage Ratio
A29: Asset Turnover = Revenue / Average Total Assets | J29: DSCR
A30: Inventory Turnover = COGS / Average Inventory
A31: Receivables Turnover = Revenue / Average Accounts Receivable
A32: Days Sales Outstanding (DSO) = (Accounts Receivable / Revenue) × 365 | L32: FYs
A33: Days Inventory Outstanding (DIO) = (Average Inventory / COGS) × 365 | J33: 4) Efficiecny | L33: 2019 | M33: 2020 | N33: 2021 | O33: 2022 | P33: 2023 | Q33: 2024
A34: Cash Conversion Cycle (CCC) = DIO + DSO - Days Payables Outstanding (DPO) | J34: Asset Turnover
J35: Inventory Turnover
J36: Receivabls Turnover
A38: 5) Cash Flow Analysis (CFS) | J38: Days Sales Outs. (days)
J39: Days Sales Outs. (Months) | L39: =L38/12 -> 0 | M39: =M38/12 -> 0 | N39: =N38/12 -> 0 | O39: =O38/12 -> 0 | P39: =P38/12 -> 0 | Q39: =Q38/12 -> 0
A40: Operating Cash Flow (OCF) = Cash Flow from Operations
A41: Free Cash Flow (FCF) = OCF - Capital Expenditures | J41: Days Inventory Outs (days)
A42: FCF Yield = FCF / Market Capitalization | J42: Days Inventory Outs (Months) | L42: =L41/12 -> 0 | M42: =M41/12 -> 0 | N42: =N41/12 -> 0 | O42: =O41/12 -> 0 | P42: =P41/12 -> 0 | Q42: =Q41/12 -> 0
A43: Cash Flow to Debt Ratio = OCF / Total Debt
...

Sheet Financial Analysis
A6: Macy's, Inc. (NYSE:M) > Financial Analysis
A8: In Millions of USD, except per share items.
A10: Don’t have to calculate everything
A11: FA content
A12: Revenue breakdown analysis
A13: Profitability analysis
A14: Balance sheet
A15: Cash flow
A16: 1) Profitability | G16: 2019 | L16: 2020 | Q16: 2021 | V16: 2022 | AA16: 2023 | AF16: 2024
A17: For the Fiscal Period Ending | C17: 1Q 2019 | D17: 2Q 2019 | E17: 3Q 2019 | F17: 4Q 2019 | G17: 2019A | H17: 1Q 2020 | I17: 2Q 2020 | J17: 3Q 2020 | K17: 4Q 2020 | L17: 2020A | M17: 1Q 2021 | N17: 2Q 2021 | O17: 3Q 2021 | P17: 4Q 2021 | Q17: 2021A | R17: 1Q 2022 | S17: 2Q 2022 | T17: 3Q 2022 | U17: 4Q 2022 | V17: 2022A | W17: 1Q 2023 | X17: 2Q 2023 | Y17: 3Q 2023 | Z17: 4Q2023 | AA17: 2023A | AB17: 1Q 2024 | AC17: 2Q 2024 | AD17: 3Q 2024 | AE17: 4Q2024 | AF17: 2024A
A18: Currency: USD
A20: Revenue | C20: ='3FS'!C21 -> 5698 | D20: ='3FS'!D21 -> 5758 | E20: ='3FS'!E21 -> 5589 | F20: ='3FS'!F21 -> 8695 | G20: ='3FS'!G21 -> 25739 | H20: ='3FS'!H21 -> 5676 | I20: ='3FS'!I21 -> 5722 | J20: ='3FS'!J21 -> 5356 | ... AF20: ='3FS'!AF21 -> 23866
A21: EBITDA | C21: ='3FS'!C34 -> 244 | D21: ='3FS'!D34 -> 285 | E21: ='3FS'!E34 -> 117 | F21: ='3FS'!F34 -> 885 | G21: ='3FS'!G34 -> 1532 | H21: ='3FS'!H34 -> 167 | I21: ='3FS'!I34 -> 157 | J21: ='3FS'!J34 -> 48 | ... AF21: ='3FS'!AF34 -> 1263
A23: Gross Margin = (Revenue - COGS) / Revenue | C23: ='3FS'!C25/'3FS'!C21 -> 0.40645841 | D23: ='3FS'!D25/'3FS'!D21 -> 0.42341091 | E23: ='3FS'!E25/'3FS'!E21 -> 0.42279478 | F23: ='3FS'!F25/'3FS'!F21 -> 0.39183439 | G23: ='3FS'!G25/'3FS'!G21 -> 0.40887369 | H23: ='3FS'!H25/'3FS'!H21 -> 0.40045807 | I23: ='3FS'!I25/'3FS'!I21 -> 0.40667599 | J23: ='3FS'!J25/'3FS'!J21 -> 0.42008962 | ... AF23: ='3FS'!AF25/'3FS'!AF21 -> 0.4040057
A24: Gross Margin (%) | C24: =C23 -> 0.40645841 | D24: =D23 -> 0.42341091 | E24: =E23 -> 0.42279478 | F24: =F23 -> 0.39183439 | G24: =G23 -> 0.40887369 | H24: =H23 -> 0.40045807 | I24: =I23 -> 0.40667599 | J24: =J23 -> 0.42008962 | ... AF24: =AF23 -> 0.4040057
A25: Operating Margin = Operating Income / Revenue | C25: ='3FS'!C34/'3FS'!C21 -> 0.042822043 | D25: ='3FS'!D34/'3FS'!D21 -> 0.049496353 | E25: ='3FS'!E34/'3FS'!E21 -> 0.020933977 | F25: ='3FS'!F34/'3FS'!F21 -> 0.10178263 | G25: ='3FS'!G34/'3FS'!G21 -> 0.059520572 | H25: ='3FS'!H34/'3FS'!H21 -> 0.029422128 | I25: ='3FS'!I34/'3FS'!I21 -> 0.027437959 | J25: ='3FS'!J34/'3FS'!J21 -> 0.0089619119 | ... AF25: ='3FS'!AF34/'3FS'!AF21 -> 0.052920473
A26: EBITDA Margin (%) | C26: =C25 -> 0.042822043 | D26: =D25 -> 0.049496353 | E26: =E25 -> 0.020933977 | F26: =F25 -> 0.10178263 | G26: =G25 -> 0.059520572 | H26: =H25 -> 0.029422128 | I26: =I25 -> 0.027437959 | J26: =J25 -> 0.0089619119 | ... AF26: =AF25 -> 0.052920473
A27: Net Profit Margin = Net Income / Revenue | C27: ='3FS'!C59/'3FS'!C21 -> 0.024394524 | D27: ='3FS'!D59/'3FS'!D21 -> 0.028829455 | E27: ='3FS'!E59/'3FS'!E21 -> 0.011093219 | F27: ='3FS'!F59/'3FS'!F21 -> 0.085106383 | G27: ='3FS'!G59/'3FS'!G21 -> 0.043047515 | H27: ='3FS'!H59/'3FS'!H21 -> 0.023960536 | I27: ='3FS'!I59/'3FS'!I21 -> 0.01502971 | J27: ='3FS'!J59/'3FS'!J21 -> 0.00037341299 | ... AF27: ='3FS'!AF59/'3FS'!AF21 -> 0.0018855275
A28: Net Profit Margin (%) | C28: =C27 -> 0.024394524 | D28: =D27 -> 0.028829455 | E28: =E27 -> 0.011093219 | F28: =F27 -> 0.085106383 | G28: =G27 -> 0.043047515 | H28: =H27 -> 0.023960536 | I28: =I27 -> 0.01502971 | J28: =J27 -> 0.00037341299 | ... AF28: =AF27 -> 0.0018855275
A30: Return on Assets (ROA) = Net Income / Average Total Assets | C30: ='3FS'!C59/'3FS'!C95 -> 0.0071034342 | D30: ='3FS'!D59/'3FS'!D95 -> 0.008892222 | E30: ='3FS'!E59/'3FS'!E95 -> 0.0030450371 | F30: ='3FS'!F59/'3FS'!F95 -> 0.038553715 | G30: ='3FS'!G59/'3FS'!G95 -> 0.057726373 | H30: ='3FS'!H59/'3FS'!H95 -> 0.0063861758 | I30: ='3FS'!I59/'3FS'!I95 -> 0.0041463767 | J30: ='3FS'!J59/'3FS'!J95 -> 8.8703597e-05 | ... AF30: ='3FS'!AF59/'3FS'!AF95 -> 0.0027699126
A31: Return on Equity (ROE) = Net Income / Average Shareholders’ Equity | C31: ='3FS'!C59/'3FS'!C126 -> 0.023961386 | D31: ='3FS'!D59/'3FS'!D126 -> 0.028164235 | E31: ='3FS'!E59/'3FS'!E126 -> 0.010983171 | F31: ='3FS'!F59/'3FS'!F126 -> 0.11497825 | G31: ='3FS'!G59/'3FS'!G126 -> 0.17215662 | H31: ='3FS'!H59/'3FS'!H126 -> 0.018712163 | I31: ='3FS'!I59/'3FS'!I126 -> 0.011853894 | J31: ='3FS'!J59/'3FS'!J126 -> 0.00028433324 | ... AF31: ='3FS'!AF59/'3FS'!AF126 -> 0.011152416
A33: 2) Liquidity | G33: 2019 | L33: 2020 | Q33: 2021 | V33: 2022 | AA33: 2023 | AF33: 2024
A34: For the Fiscal Period Ending | C34: 1Q 2019 | D34: 2Q 2019 | E34: 3Q 2019 | F34: 4Q 2019 | G34: 2019A | H34: 1Q 2020 | I34: 2Q 2020 | J34: 3Q 2020 | K34: 4Q 2020 | L34: 2020A | M34: 1Q 2021 | N34: 2Q 2021 | O34: 3Q 2021 | P34: 4Q 2021 | Q34: 2021A | R34: 1Q 2022 | S34: 2Q 2022 | T34: 3Q 2022 | U34: 4Q 2022 | V34: 2022A | W34: 1Q 2023 | X34: 2Q 2023 | Y34: 3Q 2023 | Z34: 4Q2023 | AA34: 2023A | AB34: 1Q 2024 | AC34: 2Q 2024 | AD34: 3Q 2024 | AE34: 4Q2024 | AF34: 2024A
A35: Currency: USD
A37: Current Ratio = Current Assets / Current Liabilities | C37: ='3FS'!C84/'3FS'!C106 -> 1.5186134 | D37: ='3FS'!D84/'3FS'!D106 -> 1.5320241 | E37: ='3FS'!E84/'3FS'!E106 -> 1.3449721 | F37: ='3FS'!F84/'3FS'!F106 -> 1.422974 | G37: ='3FS'!G84/'3FS'!G106 -> 1.422974 | H37: ='3FS'!H84/'3FS'!H106 -> 1.4156206 | I37: ='3FS'!I84/'3FS'!I106 -> 1.4746565 | J37: ='3FS'!J84/'3FS'!J106 -> 1.2812162 | ... AF37: ='3FS'!AF84/'3FS'!AF106 -> 1.3435569
A38: Quick Ratio = (Current Assets - Inventory) / Current Liabilities | C38: =('3FS'!C84-'3FS'!C80)/'3FS'!C106 -> 0.47646248 | D38: =('3FS'!D84-'3FS'!D80)/'3FS'!D106 -> 0.42602098 | E38: =('3FS'!E84-'3FS'!E80)/'3FS'!E106 -> 0.23587834 | F38: =('3FS'!F84-'3FS'!F80)/'3FS'!F106 -> 0.41704893 | G38: =('3FS'!G84-'3FS'!G80)/'3FS'!G106 -> 0.41704893 | H38: =('3FS'!H84-'3FS'!H80)/'3FS'!H106 -> 0.3201833 | I38: =('3FS'!I84-'3FS'!I80)/'3FS'!I106 -> 0.34174364 | J38: =('3FS'!J84-'3FS'!J80)/'3FS'!J106 -> 0.16129032 | ... AF38: =('3FS'!AF84-'3FS'!AF80)/'3FS'!AF106 -> 0.38128861
A40: 3) Leverage, Solvency | G40: 2019 | L40: 2020 | Q40: 2021 | V40: 2022 | AA40: 2023 | AF40: 2024
A41: For the Fiscal Period Ending | C41: 1Q 2019 | D41: 2Q 2019 | E41: 3Q 2019 | F41: 4Q 2019 | G41: 2019A | H41: 1Q 2020 | I41: 2Q 2020 | J41: 3Q 2020 | K41: 4Q 2020 | L41: 2020A | M41: 1Q 2021 | N41: 2Q 2021 | O41: 3Q 2021 | P41: 4Q 2021 | Q41: 2021A | R41: 1Q 2022 | S41: 2Q 2022 | T41: 3Q 2022 | U41: 4Q 2022 | V41: 2022A | W41: 1Q 2023 | X41: 2Q 2023 | Y41: 3Q 2023 | Z41: 4Q2023 | AA41: 2023A | AB41: 1Q 2024 | AC41: 2Q 2024 | AD41: 3Q 2024 | AE41: 4Q2024 | AF41: 2024A
A42: Currency: USD
A44: Debt-to-Equity = Total Debt / Shareholders’ Equity | C44: ='3FS'!C115/'3FS'!C126 -> 2.3732115 | D44: ='3FS'!D115/'3FS'!D126 -> 2.1672888 | E44: ='3FS'!E115/'3FS'!E126 -> 2.6069088 | F44: ='3FS'!F115/'3FS'!F126 -> 1.9822871 | G44: ='3FS'!G115/'3FS'!G126 -> 1.9822871 | H44: ='3FS'!H115/'3FS'!H126 -> 2.0601266 | I44: ='3FS'!I115/'3FS'!I126 -> 1.9884218 | J44: ='3FS'!J115/'3FS'!J126 -> 2.3443276 | ... AF44: ='3FS'!AF115/'3FS'!AF126 -> 3.0262701
A45: Debt-to-Assets = Total Debt / Total Assets | C45: ='3FS'!C115/'3FS'!C95 -> 0.70354661 | D45: ='3FS'!D115/'3FS'!D95 -> 0.68427255 | E45: ='3FS'!E115/'3FS'!E95 -> 0.72275429 | F45: ='3FS'!F115/'3FS'!F95 -> 0.66468688 | G45: ='3FS'!G115/'3FS'!G95 -> 0.66468688 | H45: ='3FS'!H115/'3FS'!H95 -> 0.70308978 | I45: ='3FS'!I115/'3FS'!I95 -> 0.69553059 | J45: ='3FS'!J115/'3FS'!J95 -> 0.73136116 | ... AF45: ='3FS'!AF115/'3FS'!AF95 -> 0.75163117
A46: Interest Coverage Ratio = EBITDA / Interest Expense | C46: ='3FS'!C34/'3FS'!C39 -> -3.6969697 | D46: ='3FS'!D34/'3FS'!D39 -> -4.5967742 | E46: ='3FS'!E34/'3FS'!E39 -> -1.9830508 | F46: ='3FS'!F34/'3FS'!F39 -> -18.061224 | G46: ='3FS'!G34/'3FS'!G39 -> -6.4915254 | H46: ='3FS'!H34/'3FS'!H39 -> -3.5531915 | I46: ='3FS'!I34/'3FS'!I39 -> -3.3404255 | J46: ='3FS'!J34/'3FS'!J39 -> -1 | ... AF46: ='3FS'!AF34/'3FS'!AF39 -> -9.3555556
A47: Debt Service Coverage Ratio (DSCR) = EBITDA / Total Debt Service Debt service = (Interest + Debt Repayments) | C47: ='3FS'!C34/('3FS'!C39+'3FS'!C164) -> -3.0886076 | D47: ='3FS'!D34/('3FS'!D39+'3FS'!D164) -> -0.57459677 | E47: ='3FS'!E34/('3FS'!E39+'3FS'!E164) -> 4.3333333 | F47: ='3FS'!F34/('3FS'!F39+'3FS'!F164) -> -1.0573477 | G47: ='3FS'!G34/('3FS'!G39+'3FS'!G164) -> -1.1061372 | H47: ='3FS'!H34/('3FS'!H39+'3FS'!H164) -> -1.7578947 | I47: ='3FS'!I34/('3FS'!I39+'3FS'!I164) -> -0.94578313 | J47: ='3FS'!J34/('3FS'!J39+'3FS'!J164) -> 0.62337662 | ... AF47: ='3FS'!AF34/('3FS'!AF39+'3FS'!AF164) -> -1.1502732
A49: 4) Efficiency | G49: 2019 | L49: 2020 | Q49: 2021 | V49: 2022 | AA49: 2023 | AF49: 2024
A50: For the Fiscal Period Ending | C50: 1Q 2019 | D50: 2Q 2019 | E50: 3Q 2019 | F50: 4Q 2019 | G50: 2019A | H50: 1Q 2020 | I50: 2Q 2020 | J50: 3Q 2020 | K50: 4Q 2020 | L50: 2020A | M50: 1Q 2021 | N50: 2Q 2021 | O50: 3Q 2021 | P50: 4Q 2021 | Q50: 2021A | R50: 1Q 2022 | S50: 2Q 2022 | T50: 3Q 2022 | U50: 4Q 2022 | V50: 2022A | W50: 1Q 2023 | X50: 2Q 2023 | Y50: 3Q 2023 | Z50: 4Q 2023 | AA50: 2023A | AB50: 1Q 2024 | AC50: 2Q 2024 | AD50: 3Q 2024 | AE50: 4Q 2024 | AF50: 2024A
A51: Currency: USD
A53: Asset Turnover = Revenue / Average Total Assets | C53: =C54/C55 -> 0.2911897 | D53: =D54/D55 -> 0.30844225 | E53: =E54/E55 -> 0.27449536 | F53: =F54/F55 -> 0.45300615 | G53: =G54/G55 -> 1.340992 | H53: =H54/AVERAGE(C55,H55) -> 0.26938136 | I53: =I54/AVERAGE(D55,I55) -> 0.29039052 | J53: =J54/AVERAGE(E55,J55) -> 0.24965041 | K53: =K54/AVERAGE(F55,K55) -> 0.4249616 | L53: =L54/AVERAGE(G55,L55) -> 1.2465441 | M53: =M54/AVERAGE(H55,M55) -> 0.1578855 | N53: =N54/AVERAGE(I55,N55) -> 0.19434233 | O53: =O54/AVERAGE(J55,O55) -> 0.20042624 | ... AF53: =AF54/AVERAGE(AA55,AF55) -> 1.4415318
A54: Total Revenue | C54: 5698 | D54: 5758 | E54: 5589 | F54: 8695 | G54: 25739 | H54: 5504 | I54: 5722 | J54: 5356 | K54: 8577 | L54: 25159 | M54: 3148 | N54: 3727 | O54: 4185 | P54: 7037 | Q54: 18097 | R54: 4865 | S54: 5844 | T54: 5653 | U54: 8930 | V54: 25399 | W54: 5565 | X54: 5834 | Y54: 5467 | Z54: 8583 | AA54: 25449 | AB54: 5173 | AC54: 5280 | AD54: 5038 | AE54: 8375 | AF54: 23866
A55: Total Assets | C55: 19568 | D55: 18668 | E55: 20361 | F55: 19194 | G55: 19194 | H55: 21296 | I55: 20741 | J55: 22547 | K55: 21172 | L55: 21172 | M55: 18581 | N55: 17614 | O55: 19214 | P55: 17706 | Q55: 17706 | R55: 18082 | S55: 18417 | T55: 18279 | U55: 17590 | V55: 17590 | W55: 16972 | X55: 16342 | Y55: 18230 | Z55: 16866 | AA55: 16866 | AB55: 16868 | AC55: 16304 | AD55: 18111 | AE55: 16246 | AF55: 16246
A57: Inventory Turnover = COGS / Average Inventory | C57: =C58/C59 -> 0.63919864 | D57: =D58/D59 -> 0.66989508 | E57: =E58/E59 -> 0.4513782 | F57: =F58/F59 -> 1.0047501 | G57: =G58/G59 -> 2.8911267 | H57: =H58/AVERAGE(C59,H59) -> 0.63082769 | I57: =I58/AVERAGE(D59,I59) -> 0.68002003 | J57: =J58/AVERAGE(E59,J59) -> 0.43129903 | K57: =K58/AVERAGE(F59,K59) -> 1.0077505 | L57: =L58/AVERAGE(G59,L59) -> 2.9030715 | M57: =M58/AVERAGE(H59,M59) -> 0.42241627 | N57: =N58/AVERAGE(I59,N59) -> 0.63128556 | O57: =O58/AVERAGE(J59,O59) -> 0.41435484 | ... AF57: =AF58/AVERAGE(AA59,AF59) -> 3.2969402
...

Sheet FA Graphs
A6: Macy's, Inc. (NYSE:M) > Financial Analysis
A8: In Millions of USD, except per share items.
A16: 1) Profitability | C16: 2019 | D16: 2020 | E16: 2021 | F16: 2022 | G16: 2023 | H16: 2024
A17: For the Fiscal Period Ending | C17: 2019 | D17: 2020 | E17: 2021 | F17: 2022 | G17: 2023 | H17: 2024
A18: Currency: USD
A20: Revenue (US$m) | C20: 25739 | D20: 25331 | E20: 18097 | F20: 25399 | G20: 25449 | H20: 23866
A21: Operating Income (US$m) | C21: 1532 | D21: 1159 | E21: -902 | F21: 2334 | G21: 1640 | H21: 1263
A23: Gross Margin = (Revenue - COGS) / Revenue | C23: 0.40887369 | D23: 0.40108957 | E23: 0.32110295 | F23: 0.41115792 | G23: 0.39695076 | H23: 0.4040057
A24: Gross Margin (%) | C24: 0.40887369 | D24: 0.40108957 | E24: 0.32110295 | F24: 0.41115792 | G24: 0.39695076 | H24: 0.4040057
A25: Operating Margin = Operating Income / Revenue | C25: 0.059520572 | D25: 0.045754214 | E25: -0.049842515 | F25: 0.091893382 | G25: 0.064442611 | H25: 0.052920473
A26: Operating Margin (%) | C26: 0.059520572 | D26: 0.045754214 | E26: -0.049842515 | F26: 0.091893382 | G26: 0.064442611 | H26: 0.052920473
A27: Net Profit Margin = Net Income / Revenue | C27: 0.043047515 | D27: 0.022265209 | E27: -0.21793667 | F27: 0.056301429 | G27: 0.045031239 | H27: 0.0018855275
A28: Net Profit Margin (%) | C28: 0.043047515 | D28: 0.022265209 | E28: -0.21793667 | F28: 0.056301429 | G28: 0.045031239 | H28: 0.0018855275
A30: Return on Assets (ROA) = Net Income / Average Total Assets | C30: 0.057726373 | D30: 0.026638957 | E30: -0.22274935 | F30: 0.081296191 | G30: 0.06794735 | H30: 0.0027699126
A31: Return on Equity (ROE) = Net Income / Average Shareholders’ Equity | C31: 0.17215662 | D31: 0.088442841 | E31: -1.5448492 | F31: 0.39491853 | G31: 0.28074473 | H31: 0.011152416
A33: 2) Liquidity | C33: 2019 | D33: 2020 | E33: 2021 | F33: 2022 | G33: 2023 | H33: 2024
A34: For the Fiscal Period Ending | C34: 2019 | D34: 2020 | E34: 2021 | F34: 2022 | G34: 2023 | H34: 2024
A35: Currency: USD
A37: Current Ratio | C37: 1.422974 | D37: 1.1843478 | E37: 1.1543775 | F37: 1.2477843 | G37: 1.2040732 | H37: 1.3435569
A38: Quick Ratio | C38: 0.41704893 | D38: 0.28208696 | E38: 0.44987866 | F38: 0.43851551 | G38: 0.32627031 | H38: 0.38128861
A40: 3) Leverage, Solvency | C40: 2019 | D40: 2020 | E40: 2021 | F40: 2022 | G40: 2023 | H40: 2024
A41: For the Fiscal Period Ending | C41: 2019 | D41: 2020 | E41: 2021 | F41: 2022 | G41: 2023 | H41: 2024
A42: Currency: USD
A44: Debt-to-Equity Ratio | C44: 1.9822871 | D44: 2.3200565 | E44: 5.9353702 | F44: 3.8577741 | G44: 3.1317981 | H44: 3.0262701
A46: Assets | C46: 19194 | D46: 21172 | E46: 17706 | F46: 17590 | G46: 16866 | H46: 16246
A47: Liabilities | C47: 12758 | D47: 14795 | E47: 15153 | F47: 13969 | G47: 12784 | H47: 12211
A49: Debt-to-Assets (%) | C49: 0.66468688 | D49: 0.6988003 | E49: 0.85581159 | F49: 0.7941444 | G49: 0.75797462 | H49: 0.75163117
A50: Interest Coverage Ratio | C50: -6.4915254 | D50: -6.2648649 | E50: 3.2214286 | F50: -9.1529412 | G50: -10.123457 | H50: -9.3555556
A51: Debt Service Coverage Ratio | C51: -1.1061372 | D51: -1.3732227 | E51: 0.38845823 | F51: -0.78401075 | G51: -0.47632878 | H51: -1.1502732
A53: 4) Efficiency | C53: 2019 | D53: 2020 | E53: 2021 | F53: 2022 | G53: 2023 | H53: 2024
A54: For the Fiscal Period Ending | C54: 2019 | D54: 2020 | E54: 2021 | F54: 2022 | G54: 2023 | H54: 2024
A55: Currency: USD
A57: Asset Turnover | C57: 1.340992 | D57: 1.2465441 | E57: 0.93096353 | F57: 1.4391999 | G57: 1.4771883 | H57: 1.4415318
A58: Inventory Turnover | C58: 2.8911267 | D58: 2.9030715 | E58: 2.7417987 | F58: 3.6670344 | G58: 3.5391908 | H58: 3.2969402
A59: Receivables Turnover | C59: 64.3475 | D59: 62.197775 | E59: 52.837956 | F59: 88.652705 | G59: 85.256281 | H59: 80.492411
A60: Payables Turnover | C60: 5.7680061 | D60: 5.7277704 | E60: 4.455485 | F60: 4.874837 | G60: 4.9746506 | H60: 5.1402241
A63: Days Sales Outstanding (DSO) | C63: 5.672326 | D63: 5.8683771 | E63: 6.9079129 | F63: 4.1171897 | G63: 4.2812095 | H63: 4.534589
A64: Days Inventory Outstanding (DIO) | C64: 126.24836 | D64: 125.72891 | E64: 133.12429 | F64: 99.535471 | G64: 103.13092 | H64: 110.70871
A65: Days Payables Outstanding (DPO) | C65: 63.2801 | D65: 63.724621 | E65: 81.921496 | F65: 74.874298 | G65: 73.371987 | H65: 71.008578
A67: Cash Conversion Cycle (CCC) | C67: 68.640583 | D67: 67.872662 | E67: 58.110705 | F67: 28.778362 | G67: 34.040143 | H67: 44.234723
...

Sheet 3FS
A5: Macy's, Inc. (NYSE:M) > Financials > 3 Financial Statements
A7: In Millions of USD, except per share items.
A14: Income Statement | G14: 2019 | L14: 2020 | Q14: 2021 | V14: 2022 | AA14: 2023 | AF14: 2024 | AG14: 2025
A15: For the Fiscal Period Ending | C15: 1Q 2019 | D15: 2Q 2019 | E15: 3Q 2019 | F15: 4Q 2019 | G15: 2019A | H15: 1Q 2020 | I15: 2Q 2020 | J15: 3Q 2020 | K15: 4Q 2020 | L15: 2020A | M15: 1Q 2021 | N15: 2Q 2021 | O15: 3Q 2021 | P15: 4Q 2021 | Q15: 2021A | R15: 1Q 2022 | S15: 2Q 2022 | T15: 3Q 2022 | U15: 4Q 2022 | V15: 2022A | W15: 1Q 2023 | X15: 2Q 2023 | Y15: 3Q 2023 | Z15: 4Q2023 | AA15: 2023A | AB15: 1Q 2024 | AC15: 2Q 2024 | AD15: 3Q 2024 | AE15: 4Q2024 | AF15: 2024A
A16: Currency: USD
A18: Revenue | C18: 5541 | D18: 5572 | E18: 5404 | F18: 8455 | G18: =SUM(C18:F18) -> 24972 | H18: 5504 | I18: 5546 | J18: 5173 | K18: 8337 | L18: =SUM(H18:K18) -> 24560 | M18: 3017 | N18: 3559 | O18: 3990 | P18: 6780 | Q18: =SUM(M18:P18) -> 17346 | R18: 4706 | S18: 5647 | T18: 5440 | U18: 8666 | V18: =SUM(R18:U18) -> 24459 | W18: 5348 | X18: 5600 | Y18: 5230 | Z18: 8264 | AA18: =SUM(W18:Z18) -> 24442 | AB18: 4982 | AC18: 5130 | AD18: 4860 | AE18: 8120 | AF18: =SUM(AB18:AE18) -> 23092
A19: Other Revenue | C19: 157 | D19: 186 | E19: 185 | F19: 240 | G19: =SUM(C19:F19) -> 768 | H19: 172 | I19: 176 | J19: 183 | K19: 240 | L19: =SUM(H19:K19) -> 771 | M19: 131 | N19: 168 | O19: 195 | P19: 257 | Q19: =SUM(M19:P19) -> 751 | R19: 159 | S19: 197 | T19: 213 | U19: 264 | V19: =SUM(R19:U19) -> 833 | W19: 217 | X19: 234 | Y19: 237 | Z19: 319 | AA19: =SUM(W19:Z19) -> 1007 | AB19: 191 | AC19: 150 | AD19: 178 | AE19: 255 | AF19: =SUM(AB19:AE19) -> 774
A20: Year end adjustments | C20: - | D20: - | E20: - | F20: - | G20: -1 | H20: - | I20: - | J20: - | K20: - | L20: 0 | M20: - | N20: - | O20: - | P20: - | Q20: 0 | R20: - | S20: - | T20: - | U20: - | V20: 107 | W20: - | X20: - | Y20: - | Z20: - | AA20: 0 | AB20: - | AC20: - | AD20: - | AE20: - | AF20: 0
A21: Total Revenue | C21: =SUM(C18:C19) -> 5698 | D21: =SUM(D18:D19) -> 5758 | E21: =SUM(E18:E19) -> 5589 | F21: =SUM(F18:F19) -> 8695 | G21: =SUM(G18:G20) -> 25739 | H21: =SUM(H18:H19) -> 5676 | I21: =SUM(I18:I19) -> 5722 | J21: =SUM(J18:J19) -> 5356 | K21: =SUM(K18:K19) -> 8577 | L21: =SUM(L18:L20) -> 25331 | M21: =SUM(M18:M19) -> 3148 | N21: =SUM(N18:N19) -> 3727 | O21: =SUM(O18:O19) -> 4185 | P21: =SUM(P18:P19) -> 7037 | Q21: =SUM(Q18:Q20) -> 18097 | R21: =SUM(R18:R19) -> 4865 | S21: =SUM(S18:S19) -> 5844 | T21: =SUM(T18:T19) -> 5653 | U21: =SUM(U18:U19) -> 8930 | V21: =SUM(V18:V20) -> 25399 | W21: =SUM(W18:W19) -> 5565 | X21: =SUM(X18:X19) -> 5834 | Y21: =SUM(Y18:Y19) -> 5467 | Z21: =SUM(Z18:Z19) -> 8583 | AA21: =SUM(AA18:AA20) -> 25449 | AB21: =SUM(AB18:AB19) -> 5173 | AC21: =SUM(AC18:AC19) -> 5280 | AD21: =SUM(AD18:AD19) -> 5038 | AE21: =SUM(AE18:AE19) -> 8375 | AF21: =SUM(AF18:AF20) -> 23866
A23: Cost Of Goods Sold | C23: 3382 | D23: 3320 | E23: 3226 | F23: 5288 | G23: =SUM(C23:F23) -> 15216 | H23: 3403 | I23: 3395 | J23: 3106 | K23: 5266 | L23: =SUM(H23:K23) -> 15170 | M23: 2201 | N23: 2718 | O23: 2569 | P23: 4798 | Q23: =SUM(M23:P23) -> 12286 | R23: 2889 | S23: 3353 | T23: 3207 | U23: 5507 | V23: =SUM(R23:U23) -> 14956 | W23: 3231 | X23: 3422 | Y23: 3204 | Z23: 5450 | AA23: =SUM(W23:Z23) -> 15307 | AB23: 2988 | AC23: 3176 | AD23: 2905 | AE23: 5154 | AF23: =SUM(AB23:AE23) -> 14223
A24: Year end adjustments | C24: - | D24: - | E24: - | F24: - | G24: 1 | H24: - | I24: - | J24: - | K24: - | L24: -1 | M24: - | N24: - | O24: - | P24: - | Q24: 0 | R24: - | S24: - | T24: - | U24: - | V24: 0 | W24: - | X24: - | Y24: - | Z24: - | AA24: -40 | AB24: - | AC24: - | AD24: - | AE24: - | AF24: -1
A25: Gross Profit | C25: =C21-C23 -> 2316 | D25: =D21-D23 -> 2438 | E25: =E21-E23 -> 2363 | F25: =F21-F23 -> 3407 | G25: =G21-G23+G24 -> 10524 | H25: =H21-H23 -> 2273 | I25: =I21-I23 -> 2327 | J25: =J21-J23 -> 2250 | K25: =K21-K23 -> 3311 | L25: =L21-L23+L24 -> 10160 | M25: =M21-M23 -> 947 | N25: =N21-N23 -> 1009 | O25: =O21-O23 -> 1616 | P25: =P21-P23 -> 2239 | Q25: =Q21-Q23+Q24 -> 5811 | R25: =R21-R23 -> 1976 | S25: =S21-S23 -> 2491 | T25: =T21-T23 -> 2446 | U25: =U21-U23 -> 3423 | V25: =V21-V23+V24 -> 10443 | W25: =W21-W23 -> 2334 | X25: =X21-X23 -> 2412 | Y25: =Y21-Y23 -> 2263 | Z25: =Z21-Z23 -> 3133 | AA25: =AA21-AA23+AA24 -> 10102 | AB25: =AB21-AB23 -> 2185 | AC25: =AC21-AC23 -> 2104 | AD25: =AD21-AD23 -> 2133 | AE25: =AE21-AE23 -> 3221 | AF25: =AF21-AF23+AF24 -> 9642
A27: Selling General & Admin Exp. | C27: 2072 | D27: 2153 | E27: 2246 | F27: 2530 | G27: =SUM(C27:F27) -> 9001 | H27: 2105 | I27: 2169 | J27: 2194 | K27: 2501 | L27: =SUM(H27:K27) -> 8969 | M27: 1589 | N27: 1386 | O27: 1710 | P27: 2027 | Q27: 6713 | R27: 1733 | S27: 1881 | T27: 1956 | U27: 2412 | V27: =SUM(R27:U27) -> 7982 | W27: 1898 | X27: 2004 | Y27: 2081 | Z27: 2457 | AA27: =SUM(W27:Z27) -> 8440 | AB27: 1946 | AC27: 1976 | AD27: 2038 | AE27: 2404 | AF27: =SUM(AB27:AE27) -> 8364
A28: R & D Exp. | C28: - | D28: - | E28: - | F28: - | G28: =SUM(C28:F28) -> 0 | H28: - | I28: - | J28: - | K28: - | L28: =SUM(H28:K28) -> 0 | M28: - | N28: - | O28: - | P28: - | Q28: - | R28: - | S28: - | T28: - | U28: - | V28: =SUM(R28:U28) -> 0 | W28: - | X28: - | Y28: - | Z28: - | AA28: =SUM(W28:Z28) -> 0 | AB28: - | AC28: - | AD28: - | AE28: - | AF28: -
A29: Depreciation & Amort. | C29: - | D29: - | E29: - | F29: - | G29: =SUM(C29:F29) -> 0 | H29: - | I29: - | J29: - | K29: - | L29: =SUM(H29:K29) -> 0 | M29: - | N29: - | O29: - | P29: - | Q29: - | R29: - | S29: - | T29: - | U29: - | V29: =SUM(R29:U29) -> 0 | W29: - | X29: - | Y29: - | Z29: - | AA29: =SUM(W29:Z29) -> 0 | AB29: - | AC29: - | AD29: - | AE29: - | AF29: -
A30: Other Operating Expense/(Income) | C30: - | D30: - | E30: - | F30: -8 | G30: =SUM(C30:F30) -> -8 | H30: 1 | I30: 1 | J30: 8 | K30: -10 | L30: =SUM(H30:K30) -> 0 | M30: 9 | N30: 58 | O30: 12 | P30: -79 | Q30: - | R30: - | S30: - | T30: - | U30: 21 | V30: =SUM(R30:U30) -> 21 | W30: - | X30: - | Y30: - | Z30: 21 | AA30: =SUM(W30:Z30) -> 21 | AB30: - | AC30: - | AD30: - | AE30: 15 | AF30: 15
A31: Year-end Adjustments | C31: - | D31: - | E31: - | F31: - | G31: -1 | H31: - | I31: - | J31: - | K31: - | L31: 32 | M31: - | N31: - | O31: - | P31: - | Q31: 0 | R31: - | S31: - | T31: - | U31: - | V31: 106 | W31: - | X31: - | Y31: - | Z31: - | AA31: 1 | AB31: - | AC31: - | AD31: - | AE31: - | AF31: 0
A32: Other Operating Exp., Total | C32: =SUM(C27:C30) -> 2072 | D32: =SUM(D27:D30) -> 2153 | E32: =SUM(E27:E30) -> 2246 | F32: =SUM(F27:F30) -> 2522 | G32: =SUM(G27:G31) -> 8992 | H32: =SUM(H27:H30) -> 2106 | I32: =SUM(I27:I30) -> 2170 | J32: =SUM(J27:J30) -> 2202 | K32: =SUM(K27:K30) -> 2491 | L32: =SUM(L27:L31) -> 9001 | M32: =SUM(M27:M30) -> 1598 | N32: =SUM(N27:N30) -> 1444 | O32: =SUM(O27:O30) -> 1722 | P32: =SUM(P27:P30) -> 1948 | Q32: =SUM(Q27:Q31) -> 6713 | R32: =SUM(R27:R30) -> 1733 | S32: =SUM(S27:S30) -> 1881 | T32: =SUM(T27:T30) -> 1956 | U32: =SUM(U27:U30) -> 2433 | V32: =SUM(V27:V31) -> 8109 | W32: =SUM(W27:W30) -> 1898 | X32: =SUM(X27:X30) -> 2004 | Y32: =SUM(Y27:Y30) -> 2081 | Z32: =SUM(Z27:Z30) -> 2478 | AA32: =SUM(AA27:AA31) -> 8462 | AB32: =SUM(AB27:AB30) -> 1946 | AC32: =SUM(AC27:AC30) -> 1976 | AD32: =SUM(AD27:AD30) -> 2038 | AE32: =SUM(AE27:AE30) -> 2419 | AF32: =SUM(AF27:AF31) -> 8379
A34: Operating Income (EBITDA) | C34: =C25-C32 -> 244 | D34: =D25-D32 -> 285 | E34: =E25-E32 -> 117 | F34: =F25-F32 -> 885 | G34: =G25-G32 -> 1532 | H34: =H25-H32 -> 167 | I34: =I25-I32 -> 157 | J34: =J25-J32 -> 48 | ... AF34: =AF25-AF32 -> 1263
A36: Interest Expense | C36: -71 | D36: -69 | E36: -64 | F36: -57 | G36: =SUM(C36:F36) -> -261 | H36: -54 | I36: -52 | J36: -52 | K36: -46 | L36: =SUM(H36:K36) -> -204 | M36: -49 | N36: -70 | O36: -80 | P36: -85 | Q36: =SUM(M36:P36) -> -284 | R36: -79 | S36: -80 | T36: -53 | U36: -44 | V36: =SUM(R36:U36) -> -256 | W36: -47 | X36: -42 | Y36: -42 | Z36: -31 | AA36: =SUM(W36:Z36) -> -162 | AB36: -37 | AC36: -36 | AD36: -35 | AE36: -27 | AF36: =SUM(AB36:AE36) -> -135
A37: Interest and Invest. Income | C37: 5 | D37: 7 | E37: 5 | F37: 8 | G37: =SUM(C37:F37) -> 25 | H37: 7 | I37: 5 | J37: 4 | K37: 4 | L37: =SUM(H37:K37) -> 20 | M37: 2 | N37: 1 | O37: - | P37: 1 | Q37: =SUM(M37:P37) -> 4 | R37: - | S37: - | T37: - | U37: 0 | V37: =SUM(R37:U37) -> 0 | W37: - | X37: - | Y37: - | Z37: - | AA37: =SUM(W37:Z37) -> 0 | AB37: - | AC37: - | AD37: - | AE37: - | AF37: =SUM(AB37:AE37) -> 0
A38: Year-end adjustments | C38: - | D38: - | E38: - | F38: - | G38: 0 | H38: - | I38: - | J38: - | K38: - | L38: -1 | M38: - | N38: - | O38: - | P38: - | Q38: 0 | R38: - | S38: - | T38: - | U38: - | V38: 1 | W38: - | X38: - | Y38: - | Z38: - | AA38: 0 | AB38: - | AC38: - | AD38: - | AE38: - | AF38: 0
A39: Net Interest Exp. | C39: =SUM(C36:C37) -> -66 | D39: =SUM(D36:D37) -> -62 | E39: =SUM(E36:E37) -> -59 | F39: =SUM(F36:F37) -> -49 | G39: =SUM(G36:G38) -> -236 | H39: =SUM(H36:H37) -> -47 | I39: =SUM(I36:I37) -> -47 | J39: =SUM(J36:J37) -> -48 | K39: =SUM(K36:K37) -> -42 | L39: =SUM(L36:L38) -> -185 | M39: =SUM(M36:M37) -> -47 | N39: =SUM(N36:N37) -> -69 | O39: =SUM(O36:O37) -> -80 | P39: =SUM(P36:P37) -> -84 | Q39: =SUM(Q36:Q38) -> -280 | R39: =SUM(R36:R37) -> -79 | S39: =SUM(S36:S37) -> -80 | T39: =SUM(T36:T37) -> -53 | U39: =SUM(U36:U37) -> -44 | V39: =SUM(V36:V38) -> -255 | W39: =SUM(W36:W37) -> -47 | X39: =SUM(X36:X37) -> -42 | Y39: =SUM(Y36:Y37) -> -42 | Z39: =SUM(Z36:Z37) -> -31 | AA39: =SUM(AA36:AA38) -> -162 | AB39: =SUM(AB36:AB37) -> -37 | AC39: =SUM(AC36:AC37) -> -36 | AD39: =SUM(AD36:AD37) -> -35 | AE39: =SUM(AE36:AE37) -> -27 | AF39: =SUM(AF36:AF38) -> -135
A41: Other Non-Operating Inc. (Exp.) | C41: 0 | D41: 0 | E41: 0 | F41: 0 | G41: 0 | H41: 0 | I41: 0 | J41: 0 | K41: 0 | L41: 0 | M41: 0 | N41: -3 | O41: 0 | P41: -1 | Q41: =SUM(M41:P41) -> -4 | R41: 0 | S41: 0 | T41: 0 | U41: 0 | V41: 0 | W41: 0 | X41: 0 | Y41: 0 | Z41: 0 | AA41: 0 | AB41: 0 | AC41: 0 | AD41: 0 | AE41: 0 | AF41: 0
A42: Year-end Adjustments | C42: 0 | D42: 0 | E42: 0 | F42: 0 | G42: -1 | H42: 0 | I42: 0 | J42: 0 | K42: 0 | L42: 1 | M42: 0 | N42: 0 | O42: 0 | P42: 0 | Q42: -1 | R42: 0 | S42: 0 | T42: 0 | U42: 0 | V42: 0 | W42: 0 | X42: 0 | Y42: 0 | Z42: 0 | AA42: 0 | AB42: 0 | AC42: 0 | AD42: 0 | AE42: 0 | AF42: 1
A43: EBT Excl. Unusual Items | C43: =C34+C39+C41+C42 -> 178 | D43: =D34+D39+D41+D42 -> 223 | E43: =E34+E39+E41+E42 -> 58 | F43: =F34+F39+F41+F42 -> 836 | G43: =G34+G39+G41+G42 -> 1295 | H43: =H34+H39+H41+H42 -> 120 | I43: =I34+I39+I41+I42 -> 110 | J43: =J34+J39+J41+J42 -> 0 | ... AF43: =AF34+AF39+AF41+AF42 -> 1129
A45: Restructuring Charges | C45: -19 | D45: -17 | E45: -3 | F45: -41 | G45: =SUM(C45:F45) -> -80 | H45: - | I45: - | J45: -5 | K45: -313 | L45: =SUM(H45:K45) -> -318 | M45: -25 | N45: -169 | O45: -2 | P45: -28 | Q45: =SUM(M45:P45) -> -224 | R45: - | S45: - | T45: - | U45: -3 | V45: =SUM(R45:U45) -> -3 | W45: - | X45: - | Y45: - | Z45: -5 | AA45: =SUM(W45:Z45) -> -5 | AB45: - | AC45: - | AD45: - | AE45: -55 | AF45: =SUM(AB45:AE45) -> -55
A46: Impairment of Goodwill | C46: - | D46: - | E46: - | F46: - | G46: =SUM(C46:F46) -> 0 | H46: - | I46: - | J46: - | K46: - | L46: =SUM(H46:K46) -> 0 | M46: -3070 | N46: - | O46: - | P46: 0 | Q46: =SUM(M46:P46) -> -3070 | R46: - | S46: - | T46: - | U46: - | V46: =SUM(R46:U46) -> 0 | W46: - | X46: - | Y46: - | Z46: - | AA46: =SUM(W46:Z46) -> 0 | AB46: - | AC46: - | AD46: - | AE46: - | AF46: =SUM(AB46:AE46) -> 0
A47: Gain (Loss) On Sale Of Assets | C47: 24 | D47: 46 | E47: 42 | F47: 278 | G47: =SUM(C47:F47) -> 390 | H47: 43 | I47: 7 | J47: 17 | K47: 95 | L47: =SUM(H47:K47) -> 162 | M47: 16 | N47: - | O47: 3 | P47: 40 | Q47: =SUM(M47:P47) -> 59 | R47: 6 | S47: 6 | T47: 50 | U47: 30 | V47: =SUM(R47:U47) -> 92 | W47: 42 | X47: - | Y47: 32 | Z47: 15 | AA47: =SUM(W47:Z47) -> 89 | AB47: 11 | AC47: 4 | AD47: 5 | AE47: 41 | AF47: =SUM(AB47:AE47) -> 61
A48: Asset Writedown | C48: - | D48: - | E48: - | F48: -64 | G48: =SUM(C48:F48) -> -64 | H48: - | I48: -1 | J48: - | K48: -35 | L48: =SUM(H48:K48) -> -36 | M48: -380 | N48: -15 | O48: -6 | P48: 190 | Q48: =SUM(M48:P48) -> -211 | R48: -19 | S48: -2 | T48: - | U48: 15 | V48: =SUM(R48:U48) -> -6 | W48: -8 | X48: -2 | Y48: -15 | Z48: 10 | AA48: =SUM(W48:Z48) -> -15 | AB48: -2 | AC48: -4 | AD48: -15 | AE48: -936 | AF48: =SUM(AB48:AE48) -> -957
A49: Gain (Loss) on Early Retirement of Debt | C49: - | D49: -5 | E49: - | F49: - | G49: =SUM(C49:F49) -> -5 | H49: - | I49: - | J49: - | K49: - | L49: =SUM(H49:K49) -> 0 | M49: - | N49: - | O49: - | P49: - | Q49: =SUM(M49:P49) -> 0 | R49: -11 | S49: -3 | T49: -185 | U49: - | V49: =SUM(R49:U49) -> -199 | W49: -31 | X49: - | Y49: - | Z49: - | AA49: =SUM(W49:Z49) -> -31 | AB49: - | AC49: - | AD49: - | AE49: - | AF49: =SUM(AB49:AE49) -> 0
A50: Settlement Charges | C50: - | D50: -50 | E50: -23 | F50: -43 | G50: =SUM(C50:F50) -> -116 | H50: - | I50: - | J50: -12 | K50: -76 | L50: =SUM(H50:K50) -> -88 | M50: - | N50: -38 | O50: -26 | P50: -94 | Q50: =SUM(M50:P50) -> -158 | R50: - | S50: -81 | T50: -8 | U50: -6 | V50: =SUM(R50:U50) -> -95 | W50: - | X50: - | Y50: -32 | Z50: -7 | AA50: =SUM(W50:Z50) -> -39 | AB50: - | AC50: -122 | AD50: -7 | AE50: -5 | AF50: =SUM(AB50:AE50) -> -134
A51: Year-end Adjustments | C51: - | D51: - | E51: - | F51: - | G51: 0 | H51: - | I51: - | J51: - | K51: - | L51: 33 | M51: - | N51: - | O51: - | P51: - | Q51: 1 | R51: - | S51: 0 | T51: - | U51: - | V51: -2 | W51: - | X51: - | Y51: - | Z51: - | AA51: 0 | AB51: - | AC51: - | AD51: - | AE51: - | AF51: -1
A52: EBT Incl. Unusual Items | C52: =C43+SUM(C45:C51) -> 183 | D52: =D43+SUM(D45:D51) -> 197 | E52: =E43+SUM(E45:E51) -> 74 | F52: =F43+SUM(F45:F51) -> 966 | G52: =G43+SUM(G45:G51) -> 1420 | H52: =H43+SUM(H45:H51) -> 163 | I52: =I43+SUM(I45:I51) -> 116 | J52: =J43+SUM(J45:J51) -> 0 | ... AF52: =AF43+SUM(AF45:AF51) -> 43
A55: Income Tax Expense | C55: 52 | D55: 33 | E55: 12 | F55: 226 | G55: 322 | H55: 27 | I55: 30 | J55: -2 | K55: 109 | L55: =SUM(H55:K55) -> 164 | M55: -576 | N55: -298 | O55: -126 | P55: 154 | Q55: =SUM(M55:P55) -> -846 | R55: 37 | S55: 105 | T55: 55 | U55: 239 | V55: =SUM(R55:U55) -> 436 | W55: 106 | X55: 89 | Y55: 17 | Z55: 128 | AA55: 331 | AB55: 56 | AC55: -8 | AD55: 2 | AE55: -52 | AF55: =SUM(AB55:AE55) -> -2
A56: Net Income to Company | C56: =C52-C55 -> 131 | D56: =D52-D55 -> 164 | E56: =E52-E55 -> 62 | F56: =F52-F55 -> 740 | G56: =G52-G55 -> 1098 | H56: =H52-H55 -> 136 | I56: =I52-I55 -> 86 | J56: =J52-J55 -> 2 | ... AF56: =AF52-AF55 -> 45
A58: Minority Int. in Earnings | C58: 8 | D58: 2 | E58: 0 | F58: 0 | G58: =SUM(C58:F58) -> 10 | H58: 0 | I58: 0 | J58: 0 | K58: 0 | L58: 0 | M58: 0 | N58: 0 | O58: 0 | P58: 0 | Q58: 0 | R58: 0 | S58: 0 | T58: 0 | U58: 0 | V58: 0 | W58: 0 | X58: 0 | Y58: 0 | Z58: 0 | AA58: 0 | AB58: 0 | AC58: 0 | AD58: 0 | AE58: 0 | AF58: 0
A59: Net Income | C59: =C56+C58 -> 139 | D59: =D56+D58 -> 166 | E59: =E56+E58 -> 62 | F59: =F56+F58 -> 740 | G59: =G56+G58 -> 1108 | H59: =H56+H58 -> 136 | I59: =I56+I58 -> 86 | J59: =J56+J58 -> 2 | ... AF59: =AF56+AF58 -> 45
A62: Basic EPS | C62: 0.45 | D62: 0.54 | E62: 0.2 | F62: 2.4 | G62: 3.6 | H62: 0.44 | I62: 0.28 | J62: 0.01 | K62: 1.1 | L62: 1.82 | M62: -11.53 | N62: -1.38 | O62: -0.29 | P62: 0.51 | Q62: -12.68 | R62: 0.33 | S62: 1.1 | T62: 0.78 | U62: 2.51 | V62: 4.66 | W62: 1.01 | X62: 1.01 | Y62: 0.4 | Z62: 1.87 | AA62: 4.17 | AB62: 0.57 | AC62: -0.08 | AD62: 0.15 | AE62: -0.47 | AF62: 0.16
A63: Weighted Avg. Basic Shares Out. | C63: 306.6 | D63: 307.7 | E63: 308.1 | F63: 308.4 | G63: 307.7 | H63: 309.1 | I63: 309.8 | J63: 309.9 | K63: 309.9 | L63: 309.7 | M63: 310.6 | N63: 311.2 | O63: 311.2 | P63: 311.4 | Q63: 311.1 | R63: 311.6 | S63: 312.4 | T63: 306.9 | U63: 296.5 | V63: 306.8 | W63: 283.6 | X63: 271.1 | Y63: 272 | Z63: 272.2 | AA63: 274.7 | AB63: 273.1 | AC63: 273.8 | AD63: 274.7 | AE63: 275 | AF63: 274.2
...

Sheet D&A
F8: HISTORICAL | AJ8: FORECASTED
A10: Average useful life | B10: 15 | F10: 19Q1 | G10: 19Q2 | H10: 19Q3 | I10: 19Q4 | J10: 2019A | K10: 20Q1 | L10: 20Q2 | M10: 20Q3 | N10: 20Q4 | O10: 2020A | P10: 21Q1 | Q10: 21Q2 | R10: 21Q3 | S10: 21Q4 | T10: 2021A | U10: 22Q1 | V10: 22Q2 | W10: 22Q3 | X10: 22Q4 | Y10: 2022A | Z10: 23Q1 | AA10: 23Q2 | AB10: 23Q3 | AC10: 23Q4 | AD10: 2023A | AE10: 24Q1 | AF10: 24Q2 | AG10: 24Q3 | AH10: 24Q4 | AI10: 2024A | AJ10: 25Q1 | AK10: 25Q2 | AL10: 25Q3 | AM10: 25Q4 | AN10: 2025E | AO10: 26Q1 | AP10: 26Q2 | AQ10: 26Q3 | AR10: 26Q4 | AS10: 2026E | AT10: 2027Q1 | AU10: 2027Q2 | AV10: 2027Q3 | AW10: 2027Q4 | AX10: 2027E | AY10: 2028Q1 | AZ10: 2028Q2 | BA10: 2028Q3 | BB10: 2028Q4 | BC10: 2028E | BD10: 2029Q1 | BE10: 2029Q2 | BF10: 2029Q3 | BG10: 2029Q4 | BH10: 2029E
A12: CAPEX | E12: USD'm | F12: =-CFS!$C$34 -> 132 | G12: =-CFS!$D$34 -> 143 | H12: =-CFS!$E$34 -> 193 | I12: =-CFS!$F$34 -> 189 | J12: =-CFS!$AA$34 -> 657 | K12: =-CFS!G34 -> 204 | L12: =-CFS!H34 -> 174 | M12: =-CFS!I34 -> 245 | N12: =-CFS!J34 -> 279 | O12: =-CFS!AB34 -> 902 | P12: =-CFS!K34 -> 122 | Q12: =-CFS!L34 -> 106 | R12: =-CFS!M34 -> 62 | S12: =-CFS!N34 -> 48 | T12: =-CFS!AC34 -> 338 | U12: =-CFS!O34 -> 61 | V12: =-CFS!P34 -> 81 | W12: =-CFS!Q34 -> 88 | X12: =-CFS!R34 -> 124 | Y12: =-CFS!AD34 -> 354 | Z12: =-CFS!S34 -> 171 | AA12: =-CFS!T34 -> 207 | AB12: =-CFS!U34 -> 277 | AC12: =-CFS!V34 -> 233 | AD12: =-CFS!AE34 -> 888 | AE12: =-CFS!W34 -> 215 | AF12: =-CFS!X34 -> 175 | AG12: =-CFS!Y34 -> 95 | AH12: =-CFS!Z34 -> 146 | AI12: =-CFS!AF34 -> 631 | AJ12: 175 | AK12: 175 | AL12: 175 | AM12: 175 | AN12: =SUM(AJ12:AM12) -> 700 | AO12: 200 | AP12: 200 | AQ12: 200 | AR12: 200 | AS12: =SUM(AO12:AR12) -> 800 | AT12: 200 | AU12: 200 | AV12: 200 | AW12: 200 | AX12: 800 | AY12: 200 | AZ12: 200 | BA12: 200 | BB12: 200 | BC12: 800 | BD12: 200 | BE12: 200 | BF12: 200 | BG12: 200 | BH12: 800
A13: % change in CAPEX | E13: % | G13: =(G12-F12)/F12 -> 0.083333333 | H13: =(H12-G12)/G12 -> 0.34965035 | I13: =(I12-H12)/H12 -> -0.020725389 | J13: =AVERAGE(G13:I13) -> 0.13741943 | K13: =(K12-I12)/I12 -> 0.079365079 | L13: =(L12-K12)/K12 -> -0.14705882 | M13: =(M12-L12)/L12 -> 0.40804598 | N13: =(N12-M12)/M12 -> 0.13877551 | O13: =AVERAGE(K13:N13) -> 0.11978194 | P13: =(P12-N12)/N12 -> -0.56272401 | Q13: =(Q12-P12)/P12 -> -0.13114754 | R13: =(R12-Q12)/Q12 -> -0.41509434 | S13: =(S12-R12)/R12 -> -0.22580645 | T13: =AVERAGE(P13:S13) -> -0.33369309 | U13: =(U12-S12)/S12 -> 0.27083333 | V13: =(V12-U12)/U12 -> 0.32786885 | W13: =(W12-V12)/V12 -> 0.086419753 | X13: =(X12-W12)/W12 -> 0.40909091 | Y13: =AVERAGE(U13:X13) -> 0.27355321 | Z13: =(Z12-X12)/X12 -> 0.37903226 | AA13: =(AA12-Z12)/Z12 -> 0.21052632 | AB13: =(AB12-AA12)/AA12 -> 0.33816425 | AC13: =(AC12-AB12)/AB12 -> -0.15884477 | AD13: =AVERAGE(Z13:AC13) -> 0.19221951 | AE13: =(AE12-AC12)/AC12 -> -0.077253219 | AF13: =(AF12-AE12)/AE12 -> -0.18604651 | AG13: =(AG12-AF12)/AF12 -> -0.45714286 | AH13: =(AH12-AG12)/AG12 -> 0.53684211 | AI13: =AVERAGE(AE13:AH13) -> -0.045900121 | AJ13: =(AJ12-AH12)/AH12 -> 0.19863014 | AK13: =(AK12-AJ12)/AJ12 -> 0 | AL13: =(AL12-AK12)/AK12 -> 0 | AM13: =(AM12-AL12)/AL12 -> 0 | AN13: =(AN12-AI12)/AI12 -> 0.10935024 | AO13: =(AO12-AM12)/AM12 -> 0.14285714 | AP13: =(AP12-AO12)/AO12 -> 0 | AQ13: =(AQ12-AP12)/AP12 -> 0 | AR13: =(AR12-AQ12)/AQ12 -> 0 | AS13: =AVERAGE(AO13:AR13) -> 0.035714286 | AT13: =(AT12-AR12)/AR12 -> 0 | AU13: =(AU12-AT12)/AT12 -> 0 | AV13: =(AV12-AU12)/AU12 -> 0 | AW13: =(AW12-AV12)/AV12 -> 0 | AX13: =(AX12-AS12)/AS12 -> 0 | AY13: =(AY12-AW12)/AW12 -> 0 | AZ13: =(AZ12-AY12)/AY12 -> 0 | BA13: =(BA12-AZ12)/AZ12 -> 0 | BB13: =(BB12-BA12)/BA12 -> 0 | BC13: =(BC12-AX12)/AX12 -> 0 | BD13: =(BD12-BB12)/BB12 -> 0 | BE13: =(BE12-BD12)/BD12 -> 0 | BF13: =(BF12-BE12)/BE12 -> 0 | BG13: =(BG12-BF12)/BF12 -> 0 | BH13: =(BH12-BC12)/BC12 -> 0
A15: PPE
A17: Beginning PPE | AN17: =AI33 -> 7613 | AS17: =AN33 -> 7758.8 | AX17: =AS33 -> 7941.5467 | BC17: =AX33 -> 8058.7769 | BH17: =BC33 -> 8114.8584
A18: Additions: CAPEX | AN18: =AN12 -> 700 | AS18: =AS12 -> 800 | AX18: =AX12 -> 800 | BC18: =BC12 -> 800 | BH18: =BH12 -> 800
A19: Additions / (subtractions) in other CAPEX | AN19: 0
A21: Depreciation of existing PPE | AN21: =-AN17/B10 -> -507.53333 | AS21: =-AS17/$B10 -> -517.25333 | AX21: =-AX17/$B10 -> -529.43644 | BC21: =-BC17/$B10 -> -537.25179 | BH21: =-BH17/$B10 -> -540.99056
A22: Depreciation of new CAPEX:
A23: 2025E | AN23: =-$AN$12/$B$10 -> -46.666667 | AS23: =-$AN$12/$B$10 -> -46.666667 | AX23: =-$AN$12/$B$10 -> -46.666667 | BC23: =-$AN$12/$B$10 -> -46.666667 | BH23: =-$AN$12/$B$10 -> -46.666667
A24: 2026E | B24: =AN12 -> 700 | AS24: =-$AS$18/$B$10 -> -53.333333 | AX24: =-$AS$18/$B$10 -> -53.333333 | BC24: =-$AS$18/$B$10 -> -53.333333 | BH24: =-$AS$18/$B$10 -> -53.333333
A25: 2027E | B25: =AS12 -> 800 | AX25: =-$AX$18/$B$10 -> -53.333333 | BC25: =-$AX$18/$B$10 -> -53.333333 | BH25: =-$AX$18/$B$10 -> -53.333333
A26: 2028E | B26: =AX12 -> 800 | BC26: =-BC18/$B10 -> -53.333333 | BH26: =-BH18/$B10 -> -53.333333
A27: 2029E | B27: =BC12 -> 800 | BH27: =-BH18/$B10 -> -53.333333
B28: =BH12 -> 800
A29: Total depreciation of new CAPEX | E29: USD'm | AN29: =SUM(AN23:AN28) -> -46.666667 | AS29: =SUM(AS23:AS28) -> -100 | AX29: =SUM(AX23:AX28) -> -153.33333 | BC29: =SUM(BC23:BC28) -> -206.66667 | BH29: =SUM(BH23:BH27) -> -260
A31: Total depreciation | E31: USD'm | AN31: =SUM(AN21,AN29) -> -554.2 | AS31: =SUM(AS21,AS29) -> -617.25333 | AX31: =SUM(AX21,AX29) -> -682.76978 | BC31: =SUM(BC21,BC29) -> -743.91846 | BH31: =SUM(BH21,BH29) -> -800.99056
A33: Closing PPE | E33: USD'm | F33: =BS!C33 -> 6575 | G33: =BS!D33 -> 6547 | H33: =BS!E33 -> 6572 | I33: =BS!F33 -> 6637 | J33: =BS!G33 -> 6637 | K33: =BS!H33 -> 9130 | L33: =BS!I33 -> 9119 | M33: =BS!J33 -> 9154 | ... AI33: =BS!AF33 -> 7613 | AN33: =SUM(AN17,AN18,AN19,AN31) -> 7758.8 | AS33: =SUM(AS17,AS18,AS19,AS31) -> 7941.5467 | AX33: =SUM(AX17,AX18,AX19,AX31) -> 8058.7769 | BC33: =SUM(BC17,BC18,BC19,BC31) -> 8114.8584 | BH33: =SUM(BH17,BH18,BH19,BH31) -> 8113.8679

Sheet Stores
B2: Count | D2: Locations
D3: 2024 | E3: 2023 | F3: 2022 | G3: 2021 | H3: 2020 | J3: 2025 | K3: 2026
B5: Macy's Department Stores | D5: 390 | E5: 435 | F5: 441 | G5: =51+395 -> 446 | H5: =58+395 -> 453
B6: Macy's Furniture | D6: 34 | E6: 45 | F6: 46 | G6: 47 | H6: 47
B7: Macy's Furniture Clearance | D7: 1 | E7: 1 | F7: 1 | G7: 2 | H7: 2
B8: Freestanding Backstage* | D8: 5 | E8: 9 | F8: 9 | G8: 8 | H8: 6
B9: Macy's Small Format | D9: 20 | E9: 12 | F9: 8 | G9: 5 | H9: 2
B10: Stores converted to Fulfillment Centers | F10: 2 | G10: 2 | H10: 2
B11: Total Macy's | D11: 450 | E11: 502 | F11: 507 | G11: 510 | H11: 512 | J11: =D11-50 -> 400 | K11: =J11-50 -> 350
B14: Bloomingdale's Department Stores | D14: 31 | E14: 32 | F14: 32 | G14: 33 | H14: 33
B15: Bloomie's | D15: 4 | E15: 3 | F15: 2 | G15: 1 | H15: 0
B16: Bloomingdale's Furniture/Other | D16: 1 | E16: 1 | F16: 1 | G16: 1 | H16: 1
B17: Bloomingdale's The Outlet | D17: 23 | E17: 21 | F17: 20 | G17: 20 | H17: 19
B18: Total Bloomingdale's | D18: 59 | E18: 57 | F18: 55 | G18: 55 | H18: 53 | J18: =ROUND(D18*SQRT(1.2),0)+2 -> 67 | K18: =ROUND(J18*SQRT(1.2),0)+1 -> 74 | M18: =K18-D18 -> 15 | N18: =K18/D18 -> 1.2542373
B20: Bluemercury | D20: 171 | E20: 159 | F20: 160 | G20: 160 | H20: 162 | J20: =ROUND(D20*SQRT(1.2),0) -> 187 | K20: =ROUND(J20*SQRT(1.2),0) -> 205 | M20: =K20-D20 -> 34 | N20: =K20/D20 -> 1.1988304
B22: Total Macy's, Inc. | D22: 680 | E22: 718 | F22: 722 | G22: 725 | H22: 727 | J22: =SUM(J11,J18,J20) -> 654 | K22: =SUM(K11,K18,K20) -> 629

Sheet Schedule's
A1: Cost Schedule | BJ1: Assumptions
E2: Units | F2: 19Q1 | G2: 19Q2 | H2: 19Q3 | I2: 19Q4 | J2: 2019A | K2: 20Q1 | L2: 20Q2 | M2: 20Q3 | N2: 20Q4 | O2: 2020A | P2: 21Q1 | Q2: 21Q2 | R2: 21Q3 | S2: 21Q4 | T2: 2021A | U2: 22Q1 | V2: 22Q2 | W2: 22Q3 | X2: 22Q4 | Y2: 2022A | Z2: 23Q1 | AA2: 23Q2 | AB2: 23Q3 | AC2: 23Q4 | AD2: 2023A | AE2: 24Q1 | AF2: 24Q2 | AG2: 24Q3 | AH2: 24Q4 | AI2: 2024A | AJ2: 25Q1 | AK2: 25Q2 | AL2: 25Q3 | AM2: 25Q4 | AN2: 2025E | AO2: 26Q1 | AP2: 26Q2 | AQ2: 26Q3 | AR2: 26Q4 | AS2: 2026E | AT2: 27Q1 | AU2: 27Q2 | AV2: 27Q3 | AW2: 27Q4 | AX2: 2027E | AY2: 2028E | AZ2: Please add all the assumption here (ex- projected sg&a as a % of sales | BJ2: Cost of sales : Base case 61.6% , Bull : 61.3% , Bear : 61.8% (the extra % is cos of π)
A3: Total Revenue | E3: USD | F3: 5698 | G3: 5758 | H3: 5589 | I3: 8695 | J3: 25739 | K3: 5676 | L3: 5722 | M3: 5356 | N3: 8577 | O3: 25331 | P3: 3148 | Q3: 3727 | R3: 4185 | S3: 7037 | T3: 18097 | U3: 4865 | V3: 5844 | W3: 5653 | X3: 8930 | Y3: 25399 | Z3: 5565 | AA3: 5834 | AB3: 5467 | AC3: 8583 | AD3: 25449 | AE3: 5173 | AF3: 5280 | AG3: 5038 | AH3: 8375 | AI3: 23866 | AJ3: =AJ16 -> 5966.4834 | AK3: =AK16 -> 5966.4834 | AL3: =AL16 -> 5966.4834 | AM3: =AM16 -> 5966.4834 | AN3: =AN16 -> 23865.934 | AO3: =AO16 -> 6309.5163 | AP3: =AP16 -> 6309.5163 | AQ3: =AQ16 -> 6309.5163 | ... AY3: =AY16 -> 25238.31
A4: YoY Growth % | K4: =(K3-F3)/F3 -> -0.0038610039 | L4: =(L3-G3)/G3 -> -0.0062521709 | M4: =(M3-H3)/H3 -> -0.041689032 | N4: =(N3-I3)/I3 -> -0.013571018 | O4: =(O3-J3)/J3 -> -0.015851432 | P4: =(P3-K3)/K3 -> -0.44538407 | Q4: =(Q3-L3)/L3 -> -0.34865432 | R4: =(R3-M3)/M3 -> -0.21863331 | ... AX4: =(AX3-AS3)/AS3 -> 3.959206e-06 | AY4: =(AY3-AX3)/AX3 -> 5.7357009e-06
A5: Cost of sales | F5: 3382 | G5: 3320 | H5: 3226 | I5: 5288 | J5: =SUM(F5:I5) -> 15216 | K5: 3403 | L5: 3395 | M5: 3106 | N5: 5266 | O5: =SUM(K5:N5) -> 15170 | P5: 2201 | Q5: 2718 | R5: 2569 | S5: 4798 | T5: =SUM(P5:S5) -> 12286 | U5: 2889 | V5: 3353 | W5: 3207 | X5: 5507 | Y5: =SUM(U5:X5) -> 14956 | Z5: 3231 | AA5: 3422 | AB5: 3204 | AC5: 5450 | AD5: =SUM(Z5:AC5) -> 15307 | AE5: 2988 | AF5: 3176 | AG5: 2905 | AH5: 5154 | AI5: =SUM(AE5:AH5) -> 14223 | AN5: =AI$5*AN6 -> 8761.368 | AS5: =AN$5*AS6 -> 5397.0027 | AX5: =AS$5*AX6 -> 3324.5537 | AY5: =AX$5*AY6 -> 2047.9251
A6: COGS Margin | E6: % | F6: =F5/F3 -> 0.59354159 | G6: =G5/G3 -> 0.57658909 | H6: =H5/H3 -> 0.57720522 | I6: =I5/I3 -> 0.60816561 | J6: =J5/J3 -> 0.59116516 | K6: =K5/K3 -> 0.59954193 | L6: =L5/L3 -> 0.59332401 | M6: =M5/M3 -> 0.57991038 | ... AI6: =AI5/AI3 -> 0.5959524 | AN6: 0.616 | AS6: 0.616 | AX6: 0.616 | AY6: 0.616
A7: Gross Margin | E7: % | F7: =1-F6 -> 0.40645841 | G7: =1-G6 -> 0.42341091 | H7: =1-H6 -> 0.42279478 | I7: =1-I6 -> 0.39183439 | J7: =1-J6 -> 0.40883484 | K7: =1-K6 -> 0.40045807 | L7: =1-L6 -> 0.40667599 | M7: =1-M6 -> 0.42008962 | ... AI7: =1-AI6 -> 0.4040476 | AN7: 0.4 | AS7: 0.4 | AX7: 0.4 | AY7: 0.4
A9: Operating Expense
A10: SG&A | F10: 2072 | G10: 2153 | H10: 2246 | I10: 2530 | J10: =SUM(F10:I10) -> 9001 | K10: 2105 | L10: 2169 | M10: 2194 | N10: 2501 | O10: =SUM(K10:N10) -> 8969 | P10: 1589 | Q10: 1386 | R10: 1710 | S10: 2027 | T10: 6713 | U10: 1733 | V10: 1881 | W10: 1956 | X10: 2412 | Y10: =SUM(U10:X10) -> 7982 | Z10: 1898 | AA10: 2004 | AB10: 2081 | AC10: 2457 | AD10: =SUM(Z10:AC10) -> 8440 | AE10: 1946 | AF10: 1976 | AG10: 2038 | AH10: 2404 | AI10: =SUM(AE10:AH10) -> 8364
A11: Impairment, Restructing and other costs | F11: - | G11: - | H11: - | I11: -8 | J11: =SUM(F11:I11) -> -8 | K11: 1 | L11: 1 | M11: 8 | N11: -10 | O11: =SUM(K11:N11) -> 0 | P11: 9 | Q11: 58 | R11: 12 | S11: -79 | T11: - | U11: - | V11: - | W11: - | X11: 21 | Y11: =SUM(U11:X11) -> 21 | Z11: - | AA11: - | AB11: - | AC11: 21 | AD11: =SUM(Z11:AC11) -> 21 | AE11: - | AF11: - | AG11: - | AH11: 15 | AI11: 15
A12: Marketing Expense | J12: 1142 | O12: 818 | T12: 1177 | Y12: 1163 | AD12: 1107 | AI12: 1102
J13: =SUM(J10:J12) -> 10135 | O13: =SUM(O10:O12) -> 9787 | T13: =SUM(T10:T12) -> 7890 | Y13: =SUM(Y10:Y12) -> 9166 | AD13: =SUM(AD10:AD12) -> 9568 | AI13: =SUM(AI10:AI12) -> 9481
A14: Revenue Schedule | B14: Base Case (Old) | AM14: Projected Revenue Schedule | BB14: MACY'S MARKET SHARE | BC14: 0.13
BA15: Industry | BB15: YoY Growth rate | BC15: EXPECTED SEGMENT GROWTH FROM MACY NEWS AND REPORTS | BR15: 2019 | BS15: 2020 | BT15: 2021 | BU15: 2022 | BV15: 2023 | BW15: 2024 | BX15: 2025 | BY15: 2026 | BZ15: 2027 | CA15: 2028 | CB15: 2029
