Workbook
Name IQ_CH: 110000
Name IQ_CQ: 5000
Name IQ_CY: 10000
Name IQ_DAILY: 500000
Name IQ_FH: 100000
Name IQ_FQ: 500
Name IQ_FY: 1000
Name IQ_LTM: 2000
Name IQ_MONTH: 15000
Name IQ_NTM: 6000
Name IQ_WEEK: 50000
Name IQ_YTD: 3000

Sheet Output
F3: Drivers set to | H3: 1
C6: Valuation Summary
D8: Equity Value | F8: Low | G8: Med | H8: High
D9: DCF - EV/EBITDA | F9: =MIN(F56:H58) -> 2.0181311e+08 | G9: =G46+O35 -> 2.2430205e+08 | H9: =MAX(F45:H47)+O35 -> 2.4773805e+08
D10: DCF - EV/EBIT | F10: =MIN(DCF!F201:H203)+O35 -> 2.88114e+08 | G10: =DCF!G202 -> 3.2206483e+08 | H10: =MAX(DCF!F201:H203)+O35 -> 3.3728752e+08
D11: DCF - EV/Sales | F11: =MIN(DCF!F194:H196)+O35 -> 1.2747693e+08 | G11: =DCF!G195+O35 -> 1.414094e+08 | H11: =MAX(DCF!F194:H196)+O35 -> 1.5593122e+08
D12: DCF - Perpetuity | F12: =MIN(F77:H79)+O35 -> 2.7428634e+08 | G12: =G78+O35 -> 3.069946e+08 | H12: =MAX(F77:H79)+O35 -> 3.4803423e+08
D13: Trading Comps | F13: =DCF!E169 -> 60907755 | G13: =DCF!E163 -> 90668714 | H13: =DCF!E175 -> 1.211517e+08
D15: Percentiles | F15: Low | G15: Med | H15: High
C16: 2 | D16: DCF - EV/EBITDA | F16: =F9/$O$36 -> 452.96854 | G16: =(G9-F9)/O36 -> 50.476308 | H16: =(H9-G9)/$O$36 -> 52.601979 | I16: 2
C17: 3 | D17: DCF - EV/EBIT | F17: =F10/$O$36 -> 646.67047 | G17: =(G10-F10)/O36 -> 76.202462 | H17: =(H10-G10)/$O$36 -> 34.167257 | I17: 3
C18: 4 | D18: DCF - EV/Sales | F18: =F11/O36 -> 286.12134 | G18: =(G11-F11)/O36 -> 31.271361 | H18: =(H11-G11)/$O$36 -> 32.59416 | I18: 4
C19: 1 | D19: DCF - Perpetuity | F19: =F12/O36 -> 615.63435 | G19: =(G12-F12)/O36 -> 73.413521 | H19: =(H12-G12)/$O$36 -> 92.113244 | I19: 1
C20: 5 | D20: Trading Comps | F20: =F13/O36 -> 136.70716 | G20: =(G13-F13)/O36 -> 66.798325 | H20: =(H13-G13)/$O$36 -> 68.418909 | I20: 5
D22: Sorted EV | F22: Low | G22: Med | H22: High
C23: {=_xlfn._xlws.SORT(C16:D20,1,-1)} -> 5 | D23: Trading Comps | F23: {=_xlfn._xlws.SORT(F16:I20,4,-1)} -> 136.70716 | G23: 66.798325 | H23: 68.418909 | I23: 5 | J23: =SUM(F23:H23) -> 271.92439
C24: 4 | D24: DCF - EV/Sales | F24: 286.12134 | G24: 31.271361 | H24: 32.59416 | I24: 4 | J24: =SUM(F24:H24) -> 349.98686
C25: 3 | D25: DCF - EV/EBIT | F25: 646.67047 | G25: 76.202462 | H25: 34.167257 | I25: 3 | J25: =SUM(F25:H25) -> 757.04019
C26: 2 | D26: DCF - EV/EBITDA | F26: 452.96854 | G26: 50.476308 | H26: 52.601979 | I26: 2 | J26: =SUM(F26:H26) -> 556.04683
C27: 1 | D27: DCF - Perpetuity | F27: 615.63435 | G27: 73.413521 | H27: 92.113244 | I27: 1 | J27: =SUM(F27:H27) -> 781.16111
C29: Dashboard: Multiples Method (EV/EBITDA)
E31: Main Outputs | M31: Selected Inputs
G32: Enterprise | H32: Equity | I32: Equity | M32: Valuation Date | O32: =DCF!D65 -> 45383
G33: Value | H33: Value | I33: Per Share | M33: Terminal Multiple | O33: =DCF!D95 -> 9.48
G34: =DCF!D178 -> 2.3341836e+08 | M34: WACC | O34: =DCF!D101 -> 0.090421772
E35: Base Case | F35: 1 | G35: 2.3341836e+08 | H35: =G35+$O$35 -> 2.235619e+08 | I35: =H35/$O$36 -> 501.78358 | M35: Net Debt | O35: =DCF!E151 -> -9856461
E36: Bull Case | F36: 2 | G36: 2.7099062e+08 | H36: =G36+$O$35 -> 2.6113416e+08 | I36: =H36/$O$36 -> 586.11435 | M36: Shares Outstanding | O36: =AVERAGE('Financial Statements'!AF32:AF33) -> 445534.5
E37: Bear Case | F37: 3 | G37: 2.1925023e+08 | H37: =G37+$O$35 -> 2.0939377e+08 | I37: =H37/$O$36 -> 469.98329 | M37: Actual Stock Price | O37: 607.33
E40: Enterprise Value | M40: Equity Value per Share
E42: Terminal Multiple | M42: Terminal Multiple
D43: =DCF!E142 -> 2.3086839e+08 | E43: =DCF!E178 -> 7.5 | F43: =DCF!F178 -> 8.5 | G43: =DCF!G178 -> 9.5 | H43: =DCF!H178 -> 10.5 | I43: =DCF!I178 -> 11.5 | M43: =E43 -> 7.5 | N43: =F43 -> 8.5 | O43: =G43 -> 9.5 | P43: =H43 -> 10.5 | Q43: =I43 -> 11.5
C44: WACC | D44: =DCF!D179 -> 0.08 | E44: =DCF!E179 -> 2.0431305e+08 | F44: =DCF!F179 -> 2.2373868e+08 | G44: =DCF!G179 -> 2.4316432e+08 | H44: =DCF!H179 -> 2.6258995e+08 | I44: =DCF!I179 -> 2.8201559e+08 | K44: WACC | L44: =D44 -> 0.08 | M44: =E55/$O$36 -> 436.45685 | N44: =F55/$O$36 -> 480.05759 | O44: =G55/$O$36 -> 523.65834 | P44: =H55/$O$36 -> 567.25908 | Q44: =I55/$O$36 -> 610.85983
D45: =DCF!D180 -> 0.085 | E45: =DCF!E180 -> 2.006152e+08 | F45: =DCF!F180 -> 2.196083e+08 | G45: =DCF!G180 -> 2.3860141e+08 | H45: =DCF!H180 -> 2.5759451e+08 | I45: =DCF!I180 -> 2.7658761e+08 | L45: =D45 -> 0.085 | M45: =E56/$O$36 -> 428.15706 | N45: =F56/$O$36 -> 470.78699 | O45: =G56/$O$36 -> 513.41691 | P45: =H56/$O$36 -> 556.04683 | Q45: =I56/$O$36 -> 598.67675
D46: =DCF!D181 -> 0.09 | E46: =DCF!E181 -> 1.9701426e+08 | F46: =DCF!F181 -> 2.1558638e+08 | G46: =DCF!G181 -> 2.3415851e+08 | H46: =DCF!H181 -> 2.5273063e+08 | I46: =DCF!I181 -> 2.7130276e+08 | L46: =D46 -> 0.09 | M46: =E57/$O$36 -> 420.07476 | N46: =F57/$O$36 -> 461.7598 | O46: =G57/$O$36 -> 503.44485 | P46: =H57/$O$36 -> 545.12989 | Q46: =I57/$O$36 -> 586.81494
D47: =DCF!D182 -> 0.095 | E47: =DCF!E182 -> 1.9350722e+08 | F47: =DCF!F182 -> 2.1166957e+08 | G47: =DCF!G182 -> 2.2983192e+08 | H47: =DCF!H182 -> 2.4799427e+08 | I47: =DCF!I182 -> 2.6615662e+08 | L47: =D47 -> 0.095 | M47: =E58/$O$36 -> 412.20323 | N47: =F58/$O$36 -> 452.96854 | O47: =G58/$O$36 -> 493.73384 | P47: =H58/$O$36 -> 534.49915 | Q47: =I58/$O$36 -> 575.26445
D48: =DCF!D183 -> 0.1 | E48: =DCF!E183 -> 1.9009122e+08 | F48: =DCF!F183 -> 2.0785464e+08 | G48: =DCF!G183 -> 2.2561807e+08 | H48: =DCF!H183 -> 2.433815e+08 | I48: =DCF!I183 -> 2.6114492e+08 | L48: =D48 -> 0.1 | M48: =E59/$O$36 -> 404.53602 | N48: =F59/$O$36 -> 444.40595 | O48: =G59/$O$36 -> 484.27587 | P48: =H59/$O$36 -> 524.1458 | Q48: =I59/$O$36 -> 564.01572
E51: Equity Value | M51: Premium (Discount) to Stock Price
E53: Terminal Multiple | M53: Terminal Multiple
D54: =DCF!E157 -> 592.95658 | E54: =E43 -> 7.5 | F54: =F43 -> 8.5 | G54: =G43 -> 9.5 | H54: =H43 -> 10.5 | I54: =I43 -> 11.5 | M54: =E43 -> 7.5 | N54: =F43 -> 8.5 | O54: =G43 -> 9.5 | P54: =H43 -> 10.5 | Q54: =I43 -> 11.5
C55: WACC | D55: =D44 -> 0.08 | E55: =E44+$O$35 -> 1.9445658e+08 | F55: =F44+$O$35 -> 2.1388222e+08 | G55: =G44+$O$35 -> 2.3330786e+08 | H55: =H44+$O$35 -> 2.5273349e+08 | I55: =I44+$O$35 -> 2.7215913e+08 | K55: WACC | L55: =D44 -> 0.08 | M55: =M44/$O$37-1 -> -0.28135141 | N55: =N44/$O$37-1 -> -0.20956055 | O55: =O44/$O$37-1 -> -0.13776968 | P55: =P44/$O$37-1 -> -0.065978821 | Q55: =Q44/$O$37-1 -> 0.0058120411
...

Sheet Financial Statements
C5: Key Financial Statements | L5: Historicals | AK5: Forecasts | BC5: CAGR
G6: Units | H6: 19Q1 | I6: 19Q2 | J6: 19Q3 | K6: 19Q4 | L6: 2019A | M6: 20Q1 | N6: 20Q2 | O6: 20Q3 | P6: 20Q4 | Q6: 2020A | R6: 21Q1 | S6: 21Q2 | T6: 21Q3 | U6: 21Q4 | V6: 2021A | W6: 22Q1 | X6: 22Q2 | Y6: 22Q3 | Z6: 22Q4 | AA6: 2022A | AB6: 23Q1 | AC6: 23Q2 | AD6: 23Q3 | AE6: 23Q4 | AF6: 2023A | AG6: 24Q1 | AH6: 24Q2 | AI6: 24Q3 | AJ6: 24Q4 | AK6: 2024E | AL6: 25Q1 | AM6: 25Q2 | AN6: 25Q3 | AO6: 25Q4 | AP6: 2025E | AQ6: 26Q1 | AR6: 26Q2 | AS6: 26Q3 | AT6: 26Q4 | AU6: 2026E | AV6: 27Q1 | AW6: 27Q2 | AX6: 27Q3 | AY6: 27Q4 | AZ6: 2027E | BA6: 2028E | BC6: 2020A - 2022A | BD6: 2023E - 2026E | BE6: 2027E - 2030E | BF6: 2023E - 2030E
A8: I | C8: Income Statement
C9: -1 | AF9: =(AF10/L10)^(1/5)-1 -> 0.10841708
C10: Revenues | G10: USD'k | H10: =Operating!H13 -> 4520992 | I10: =Operating!I13 -> 4923116 | J10: =Operating!J13 -> 5244905 | K10: =Operating!K13 -> 5467434 | L10: =Operating!L13 -> 20156447 | M10: =Operating!M13 -> 5767691 | N10: =Operating!N13 -> 6148286 | O10: =Operating!O13 -> 6435637 | ... BA10: =Operating!BA13 -> 71196534 | BC10: =IFERROR((Q10/#REF!)^(1/(_xlfn.NUMBERVALUE(LEFT(Q$6,4))-_xlfn.NUMBERVALUE(LEFT(#REF!,4))))-1,"NA") -> NA | BD10: =IFERROR((AZ10/AK10)^(1/(_xlfn.NUMBERVALUE(LEFT(AZ$6,4))-_xlfn.NUMBERVALUE(LEFT(AK$6,4))))-1,"NA") -> 0.17857271 | BE10: =IFERROR((#REF!/BA10)^(1/(_xlfn.NUMBERVALUE(LEFT(#REF!,4))-_xlfn.NUMBERVALUE(LEFT(BA$6,4))))-1,"NA") -> NA | BF10: =IFERROR((#REF!/AK10)^(1/(_xlfn.NUMBERVALUE(LEFT(#REF!,4))-_xlfn.NUMBERVALUE(LEFT(AK$6,4))))-1,"NA") -> NA
C11: Cost of sales | G11: USD'k | H11: -2870614 | I11: -3005657 | J11: -3097919 | K11: -3466023 | L11: =SUM(H11:K11) -> -12440213 | M11: -3599701 | N11: -3643707 | O11: -3867751 | P11: -4165160 | Q11: =SUM(M11:P11) -> -15276319 | R11: -3868511 | S11: -4018008 | T11: -4206589 | U11: -5239575 | V11: =SUM(R11:U11) -> -17332683 | W11: -4284705 | X11: -4690755 | Y11: -4788665 | Z11: -5404160 | AA11: =SUM(W11:Z11) -> -19168285 | AB11: -4803625 | AC11: -4673470 | AD11: -4930788 | AE11: -5307485 | AF11: =SUM(AB11:AE11) -> -19715368 | AG11: =Operating!AG62*$C$9 -> -5457841.8 | AH11: =Operating!AH62*$C$9 -> -5468641.3 | AI11: =Operating!AI62*$C$9 -> -5581365.1 | AJ11: =Operating!AJ62*$C$9 -> -5768530.6 | AK11: =Operating!AK62*$C$9 -> -22276379 | AL11: =Operating!AL62*$C$9 -> -6190160.3 | AM11: =Operating!AM62*$C$9 -> -6311335.8 | AN11: =Operating!AN62*$C$9 -> -6521826.6 | ... BA11: =Operating!BA62*$C$9 -> -33700392 | BC11: =IFERROR((Q11/#REF!)^(1/(_xlfn.NUMBERVALUE(LEFT(Q$6,4))-_xlfn.NUMBERVALUE(LEFT(#REF!,4))))-1,"NA") -> NA | BD11: =IFERROR((AZ11/AK11)^(1/(_xlfn.NUMBERVALUE(LEFT(AZ$6,4))-_xlfn.NUMBERVALUE(LEFT(AK$6,4))))-1,"NA") -> 0.11640728 | BE11: =IFERROR((#REF!/BA11)^(1/(_xlfn.NUMBERVALUE(LEFT(#REF!,4))-_xlfn.NUMBERVALUE(LEFT(BA$6,4))))-1,"NA") -> NA | BF11: =IFERROR((#REF!/AK11)^(1/(_xlfn.NUMBERVALUE(LEFT(#REF!,4))-_xlfn.NUMBERVALUE(LEFT(AK$6,4))))-1,"NA") -> NA
C12: Gross Profit | G12: USD'k | H12: =SUM(H10:H11) -> 1650378 | I12: =SUM(I10:I11) -> 1917459 | J12: =SUM(J10:J11) -> 2146986 | K12: =SUM(K10:K11) -> 2001411 | L12: =SUM(L10:L11) -> 7716234 | M12: =SUM(M10:M11) -> 2167990 | N12: =SUM(N10:N11) -> 2504579 | O12: =SUM(O10:O11) -> 2567886 | ... BA12: =SUM(BA10:BA11) -> 37496142 | BC12: =IFERROR((Q12/#REF!)^(1/(_xlfn.NUMBERVALUE(LEFT(Q$6,4))-_xlfn.NUMBERVALUE(LEFT(#REF!,4))))-1,"NA") -> NA | BD12: =IFERROR((AZ12/AK12)^(1/(_xlfn.NUMBERVALUE(LEFT(AZ$6,4))-_xlfn.NUMBERVALUE(LEFT(AK$6,4))))-1,"NA") -> 0.25165791 | BE12: =IFERROR((#REF!/BA12)^(1/(_xlfn.NUMBERVALUE(LEFT(#REF!,4))-_xlfn.NUMBERVALUE(LEFT(BA$6,4))))-1,"NA") -> NA | BF12: =IFERROR((#REF!/AK12)^(1/(_xlfn.NUMBERVALUE(LEFT(#REF!,4))-_xlfn.NUMBERVALUE(LEFT(AK$6,4))))-1,"NA") -> NA
AK13: =AK12/AK10 -> 0.43133469 | AL13: =AL12/AL10 -> 0.43211806 | AM13: =AM12/AM10 -> 0.43511806 | AN13: =AN12/AN10 -> 0.44211806 | AO13: =AO12/AO10 -> 0.45111806 | AP13: =AP12/AP10 -> 0.44048844 | AQ13: =AQ12/AQ10 -> 0.46111806 | AR13: =AR12/AR10 -> 0.47111806 | ... BA13: =BA12/BA10 -> 0.52665685
C14: Marketing | G14: USD'k | H14: -616578 | I14: -603150 | J14: -553797 | K14: -878937 | L14: =SUM(H14:K14) -> -2652462 | M14: -503830 | N14: -434370 | O14: -527597 | P14: -762565 | Q14: =SUM(M14:P14) -> -2228362 | R14: -512512 | S14: -603973 | T14: -635948 | U14: -792713 | V14: =SUM(R14:U14) -> -2545146 | W14: -555978 | X14: -574960 | Y14: -567954 | Z14: -831610 | AA14: =SUM(W14:Z14) -> -2530502 | AB14: -555362 | AC14: -627168 | AD14: -558736 | AE14: -916617 | AF14: =SUM(AB14:AE14) -> -2657883 | AG14: =Operating!AG95*$C$9 -> -713278.54 | AH14: =Operating!AH95*$C$9 -> -715337.05 | AI14: =Operating!AI95*$C$9 -> -723451.49 | AJ14: =Operating!AJ95*$C$9 -> -740509.13 | AK14: =Operating!AK95*$C$9 -> -2892576.2 | AL14: =Operating!AL95*$C$9 -> -795298.44 | AM14: =Operating!AM95*$C$9 -> -843105.29 | AN14: =Operating!AN95*$C$9 -> -876310.38 | ... BA14: =Operating!BA95*$C$9 -> -3877380.8 | BC14: =IFERROR((Q14/#REF!)^(1/(_xlfn.NUMBERVALUE(LEFT(Q$6,4))-_xlfn.NUMBERVALUE(LEFT(#REF!,4))))-1,"NA") -> NA | BD14: =IFERROR((AZ14/AK14)^(1/(_xlfn.NUMBERVALUE(LEFT(AZ$6,4))-_xlfn.NUMBERVALUE(LEFT(AK$6,4))))-1,"NA") -> 0.095814504 | BE14: =IFERROR((#REF!/BA14)^(1/(_xlfn.NUMBERVALUE(LEFT(#REF!,4))-_xlfn.NUMBERVALUE(LEFT(BA$6,4))))-1,"NA") -> NA | BF14: =IFERROR((#REF!/AK14)^(1/(_xlfn.NUMBERVALUE(LEFT(#REF!,4))-_xlfn.NUMBERVALUE(LEFT(AK$6,4))))-1,"NA") -> NA
C15: Technology and development | G15: USD'k | H15: -372764 | I15: -383233 | J15: -379776 | K15: -409376 | L15: =SUM(H15:K15) -> -1545149 | M15: -453817 | N15: -435045 | O15: -453802 | P15: -486936 | Q15: =SUM(M15:P15) -> -1829600 | R15: -525207 | S15: -537321 | T15: -563887 | U15: -647470 | V15: =SUM(R15:U15) -> -2273885 | W15: -657530 | X15: -716846 | Y15: -662739 | Z15: -673926 | AA15: =SUM(W15:Z15) -> -2711041 | AB15: -687275 | AC15: -657983 | AD15: -657159 | AE15: -673341 | AF15: =SUM(AB15:AE15) -> -2675758 | AG15: =Operating!AG96*$C$9 -> -722334.13 | AH15: =Operating!AH96*$C$9 -> -724599.3 | AI15: =Operating!AI96*$C$9 -> -733139.78 | AJ15: =Operating!AJ96*$C$9 -> -750777.71 | AK15: =Operating!AK96*$C$9 -> -2930850.9 | AL15: =Operating!AL96*$C$9 -> -805948.9 | AM15: =Operating!AM96*$C$9 -> -854021.9 | AN15: =Operating!AN96*$C$9 -> -887732.61 | ... BA15: =Operating!BA96*$C$9 -> -3946944.5 | BC15: =IFERROR((Q15/#REF!)^(1/(_xlfn.NUMBERVALUE(LEFT(Q$6,4))-_xlfn.NUMBERVALUE(LEFT(#REF!,4))))-1,"NA") -> NA | BD15: =IFERROR((AZ15/AK15)^(1/(_xlfn.NUMBERVALUE(LEFT(AZ$6,4))-_xlfn.NUMBERVALUE(LEFT(AK$6,4))))-1,"NA") -> 0.096977705 | BE15: =IFERROR((#REF!/BA15)^(1/(_xlfn.NUMBERVALUE(LEFT(#REF!,4))-_xlfn.NUMBERVALUE(LEFT(BA$6,4))))-1,"NA") -> NA | BF15: =IFERROR((#REF!/AK15)^(1/(_xlfn.NUMBERVALUE(LEFT(#REF!,4))-_xlfn.NUMBERVALUE(LEFT(AK$6,4))))-1,"NA") -> NA
C16: General and administrative | G16: USD'k | H16: -201952 | I16: -224657 | J16: -233174 | K16: -254586 | L16: =SUM(H16:K16) -> -914369 | M16: -252087 | N16: -277236 | O16: -271624 | P16: -275539 | Q16: =SUM(M16:P16) -> -1076486 | R16: -297196 | S16: -334845 | T16: -321790 | U16: -397790 | V16: =SUM(R16:U16) -> -1351621 | W16: -397928 | X16: -409297 | Y16: -373213 | Z16: -392453 | AA16: =SUM(W16:Z16) -> -1572891 | AB16: -400924 | AC16: -401497 | AD16: -478591 | AE16: -439273 | AF16: =SUM(AB16:AE16) -> -1720285 | AG16: =Operating!AG97*$C$9 -> -458592.29 | AH16: =Operating!AH97*$C$9 -> -454838.51 | AI16: =Operating!AI97*$C$9 -> -450970.68 | AJ16: =Operating!AJ97*$C$9 -> -451707.89 | AK16: =Operating!AK97*$C$9 -> -1816109.4 | AL16: =Operating!AL97*$C$9 -> -495757.2 | AM16: =Operating!AM97*$C$9 -> -536078.42 | AN16: =Operating!AN97*$C$9 -> -555062.89 | ... BA16: =Operating!BA97*$C$9 -> -1920917.7
C17: Operating Expenses | G17: USD'k | H17: =SUM(H14:H16) -> -1191294 | I17: =SUM(I14:I16) -> -1211040 | J17: =SUM(J14:J16) -> -1166747 | K17: =SUM(K14:K16) -> -1542899 | L17: =SUM(L14:L16) -> -5111980 | M17: =SUM(M14:M16) -> -1209734 | N17: =SUM(N14:N16) -> -1146651 | O17: =SUM(O14:O16) -> -1253023 | ... BA17: =SUM(BA14:BA16) -> -9745243
C19: EBIT | G19: USD'k | H19: =SUM(H12,H17) -> 459084 | I19: =SUM(I12,I17) -> 706419 | J19: =SUM(J12,J17) -> 980239 | K19: =SUM(K12,K17) -> 458512 | L19: =SUM(L12,L17) -> 2604254 | M19: =SUM(M12,M17) -> 958256 | N19: =SUM(N12,N17) -> 1357928 | O19: =SUM(O12,O17) -> 1314863 | ... BA19: =SUM(BA12,BA17) -> 27750899
C21: Interest expense | G21: % | H21: -135529 | I21: -152033 | J21: -160660 | K21: -177801 | L21: =SUM(H21:K21) -> -626023 | M21: -184083 | N21: -189151 | O21: -197079 | P21: -197186 | Q21: =SUM(M21:P21) -> -767499 | R21: -194440 | S21: -191322 | T21: -190429 | U21: -189429 | V21: =SUM(R21:U21) -> -765620 | W21: -187579 | X21: -175455 | Y21: -172575 | Z21: -170603 | AA21: =SUM(W21:Z21) -> -706212 | AB21: -174239 | AC21: -174812 | AD21: -175563 | AE21: -175212 | AF21: =SUM(AB21:AE21) -> -699826
C22: Interest and other income (expense) | G22: % | H22: 76104 | I22: -53470 | J22: 192744 | K22: -131378 | L22: =SUM(H22:K22) -> 84000 | M22: 21697 | N22: -133175 | O22: -256324 | P22: -250639 | Q22: =SUM(M22:P22) -> -618441 | R22: 269086 | S22: -62519 | T22: 96135 | U22: 108512 | V22: =SUM(R22:U22) -> 411214 | W22: 195645 | X22: 220226 | Y22: 261404 | Z22: -339965 | AA22: =SUM(W22:Z22) -> 337310 | AB22: -71204 | AC22: 26961 | AD22: 168218 | AE22: -172747 | AF22: =SUM(AB22:AE22) -> -48772
C23: EBT | G23: USD'k | H23: =SUM(H21:H22,H19) -> 399659 | I23: =SUM(I21:I22,I19) -> 500916 | J23: =SUM(J21:J22,J19) -> 1012323 | K23: =SUM(K21:K22,K19) -> 149333 | L23: =SUM(L21:L22,L19) -> 2062231 | M23: =SUM(M21:M22,M19) -> 795870 | N23: =SUM(N21:N22,N19) -> 1035602 | O23: =SUM(O21:O22,O19) -> 861460 | ... AF23: =SUM(AF21:AF22,AF19) -> 6205405
C25: Benefit from (provision for) income taxes | G25: USD'k | H25: -55607 | I25: -230266 | J25: -347079 | K25: 437637 | L25: =SUM(H25:K25) -> -195315 | M25: -86803 | N25: -315406 | O25: -71484 | P25: 35739 | Q25: =SUM(M25:P25) -> -437954 | R25: -327787 | S25: -240776 | T25: -211888 | U25: 56576 | V25: =SUM(R25:U25) -> -723875 | W25: -382245 | X25: -182103 | Y25: -223605 | Z25: 15948 | AA25: =SUM(W25:Z25) -> -772005 | AB25: -163754 | AC25: -191722 | AD25: -231627 | AE25: -210312 | AF25: =SUM(AB25:AE25) -> -797415
C27: Net Income (loss) | G27: USD'k | H27: =SUM(H23,H25) -> 344052 | I27: =SUM(I23,I25) -> 270650 | J27: =SUM(J23,J25) -> 665244 | K27: =SUM(K23,K25) -> 586970 | L27: =SUM(L23,L25) -> 1866916 | M27: =SUM(M23,M25) -> 709067 | N27: =SUM(N23,N25) -> 720196 | O27: =SUM(O23,O25) -> 789976 | ... AF27: =SUM(AF23,AF25) -> 5407990 | BC27: =IFERROR((Q27/#REF!)^(1/(_xlfn.NUMBERVALUE(LEFT(Q$6,4))-_xlfn.NUMBERVALUE(LEFT(#REF!,4))))-1,"NA") -> NA | BD27: =IFERROR((AZ27/AK27)^(1/(_xlfn.NUMBERVALUE(LEFT(AZ$6,4))-_xlfn.NUMBERVALUE(LEFT(AK$6,4))))-1,"NA") -> NA | BE27: =IFERROR((#REF!/BA27)^(1/(_xlfn.NUMBERVALUE(LEFT(#REF!,4))-_xlfn.NUMBERVALUE(LEFT(BA$6,4))))-1,"NA") -> NA | BF27: =IFERROR((#REF!/AK27)^(1/(_xlfn.NUMBERVALUE(LEFT(#REF!,4))-_xlfn.NUMBERVALUE(LEFT(AK$6,4))))-1,"NA") -> NA
AB28: =AB27/AB10 -> 0.15951122 | AC28: =AC27/AC10 -> 0.18156109 | AD28: =AD27/AD10 -> 0.1968748 | AE28: =AE27/AE10 -> 0.10617645 | AF28: =AF27/AF10 -> 0.16036362
C29: Basic EPS | G29: USD | H29: 0.79 | I29: 0.62 | J29: 1.52 | K29: 1.34 | L29: =ROUND(L$27/L32,2) -> 4.26 | M29: 1.61 | N29: 1.63 | O29: 1.79 | P29: 1.23 | Q29: =ROUND(Q$27/Q32,2) -> 6.26 | R29: 3.85 | S29: 3.05 | T29: 3.27 | U29: 1.37 | V29: =ROUND(V$27/V32,2) -> 11.55 | W29: 3.6 | X29: 3.24 | Y29: 3.14 | Z29: 0.12 | AA29: =ROUND(AA$27/AA32,2) -> 10.1 | AB29: 2.93 | AC29: 3.35 | AD29: 3.8 | AE29: 2.15 | AF29: =ROUND(AF$27/AF32,2) -> 12.25
C30: Diluted EPS | G30: USD | H30: 0.76 | I30: 0.6 | J30: 1.47 | K30: 1.3 | L30: =ROUND(L$27/L33,2) -> 4.13 | M30: 1.57 | N30: 1.59 | O30: 1.74 | P30: 1.19 | Q30: =ROUND(Q$27/Q33,2) -> 6.08 | R30: 3.75 | S30: 2.97 | T30: 3.19 | U30: 1.33 | V30: =ROUND(V$27/V33,2) -> 11.24 | W30: 3.53 | X30: 3.2 | Y30: 3.1 | Z30: 0.12 | AA30: =ROUND(AA$27/AA33,2) -> 9.95 | AB30: 2.88 | AC30: 3.29 | AD30: 3.73 | AE30: 2.11 | AF30: =ROUND(AF$27/AF33,2) -> 12.03
C32: Basic weighted-average shares of common stock outstanding | G32: # | H32: 436947 | I32: 437587 | J32: 438090 | K32: 438547 | L32: 437799 | M32: 439352 | N32: 440569 | O32: 441526 | P32: 442220 | Q32: 440922 | R32: 443224 | S32: 443159 | T32: 442778 | U32: 443462 | V32: 443155 | W32: 444146 | X32: 444557 | Y32: 444878 | Z32: 445200 | AA32: 444698 | AB32: 445244 | AC32: 443881 | AD32: 441537 | AE32: 435923 | AF32: 441571
C33: Diluted weighted-average shares of common stock outstanding | G33: # | H33: 451922 | I33: 452195 | J33: 451552 | K33: 451367 | L33: 451765 | M33: 452494 | N33: 453945 | O33: 455088 | P33: 455283 | Q33: 454208 | R33: 455641 | S33: 455129 | T33: 454925 | U33: 455795 | V33: 455372 | W33: 452984 | X33: 450169 | Y33: 450344 | Z33: 451649 | AA33: 451290 | AB33: 452417 | AC33: 451572 | AD33: 450011 | AE33: 444292 | AF33: 449498
C35: EBITDA | G35: USD'k | H35: =SUM(H19,H81) -> 482645 | I35: =SUM(I19,I81) -> 731915 | J35: =SUM(J19,J81) -> 1006943 | K35: =SUM(K19,K81) -> 486330 | L35: =SUM(L19,L81) -> 2707833 | M35: =SUM(M19,M81) -> 986773 | N35: =SUM(N19,N81) -> 1384589 | O35: =SUM(O19,O81) -> 1343452 | ... AF35: =SUM(AF19,AF81) -> 7310950 | AK35: =AK19+Operating!AK242 -> 9141530 | AP35: =AP19+Operating!AP242 -> 11104331 | AU35: =AU19+Operating!AU242 -> 16118464 | AZ35: =AZ19+Operating!AZ242 -> 23198378 | BA35: =BA19+Operating!BA242 -> 27230790
A37: B | C37: Balance Sheet
C38: Check | H38: =ROUND(H50-H72,0) -> 0 | I38: =ROUND(I50-I72,0) -> 0 | J38: =ROUND(J50-J72,0) -> 0 | K38: =ROUND(K50-K72,0) -> 0 | L38: =ROUND(L50-L72,0) -> 0 | M38: =ROUND(M50-M72,0) -> 0 | N38: =ROUND(N50-N72,0) -> 0 | O38: =ROUND(O50-O72,0) -> 0 | ... AF38: =ROUND(AF50-AF72,0) -> 0
C40: Cash and cash equivalents | G40: USD'k | H40: 3348557 | I40: 5004247 | J40: 4435018 | K40: 5018437 | L40: =K40 -> 5018437 | M40: 5151884 | N40: 7153248 | O40: 8392391 | P40: 8205550 | Q40: =P40 -> 8205550 | R40: 8403705 | S40: 7777530 | T40: 7526681 | U40: 6027804 | V40: =U40 -> 6027804 | W40: 6008946 | X40: 5819449 | Y40: 6113733 | Z40: 5147176 | AA40: =Z40 -> 5147176 | AB40: 6714594 | AC40: 7662788 | AD40: 7353245 | AE40: 7116913 | AF40: =AE40 -> 7116913
C41: Current content assets, net | G41: USD'k | H41: 0 | I41: 0 | J41: 0 | K41: 0 | L41: =K41 -> 0 | M41: 0 | N41: 0 | O41: 0 | P41: 0 | Q41: =P41 -> 0 | R41: 0 | S41: 0 | T41: 0 | U41: 0 | V41: =U41 -> 0 | W41: 0 | X41: 0 | Y41: 0 | Z41: 911276 | AA41: =Z41 -> 911276 | AB41: 1112910 | AC41: 914201 | AD41: 514201 | AE41: 20973 | AF41: =AE41 -> 20973
C42: Other current assets | G42: USD'k | H42: 820350 | I42: 872910 | J42: 892740 | K42: 1160067 | L42: =K42 -> 1160067 | M42: 1295897 | N42: 1410891 | O42: 1434089 | P42: 1556030 | Q42: =P42 -> 1556030 | R42: 1703803 | S42: 1826746 | T42: 1889106 | U42: 2042021 | V42: =U42 -> 2042021 | W42: 2089069 | X42: 2021329 | Y42: 2703170 | Z42: 3208021 | AA42: =Z42 -> 3208021 | AB42: 2655119 | AC42: 2929347 | AD42: 2912028 | AE42: 2780247 | AF42: =AE42 -> 2780247
C43: Total current assets | G43: USD'k | H43: =SUM(H40:H42) -> 4168907 | I43: =SUM(I40:I42) -> 5877157 | J43: =SUM(J40:J42) -> 5327758 | K43: =SUM(K40:K42) -> 6178504 | L43: =SUM(L40:L42) -> 6178504 | M43: =SUM(M40:M42) -> 6447781 | N43: =SUM(N40:N42) -> 8564139 | O43: =SUM(O40:O42) -> 9826480 | ... AF43: =SUM(AF40:AF42) -> 9918133
C45: Non-current content assets, net | G45: USD'k | H45: 20878317 | I45: 21937845 | J45: 23227772 | K45: 24504567 | L45: =K45 -> 24504567 | M45: 25266889 | N45: 25155117 | O45: 25067633 | P45: 25383950 | Q45: =P45 -> 25383950 | R45: 26043991 | S45: 27291640 | T45: 28974045 | U45: 30919539 | V45: =U45 -> 30919539 | W45: 31191920 | X45: 32533199 | Y45: 32777340 | Z45: 32736713 | AA45: =Z45 -> 32736713 | AB45: 32349184 | AC45: 32520774 | AD45: 31749861 | AE45: 31658056 | AF45: =AE45 -> 31658056
C46: Property and equipment, net | G46: USD'k | H46: 434372 | I46: 452399 | J46: 481992 | K46: 565221 | L46: =K46 -> 565221 | M46: 650455 | N46: 751941 | O46: 828118 | P46: 960183 | Q46: =P46 -> 960183 | R46: 1015419 | S46: 1107437 | T46: 1220114 | U46: 1323453 | V46: =U46 -> 1323453 | W46: 1383763 | X46: 1361920 | Y46: 1372754 | Z46: 1398257 | AA46: =Z46 -> 1398257 | AB46: 1413094 | AC46: 1471968 | AD46: 1498391 | AE46: 1491444 | AF46: =AE46 -> 1491444
C47: Other non-current assets | G47: USD'k | H47: 1737036 | I47: 1903938 | J47: 1904189 | K47: 2727420 | L47: =K47 -> 2727420 | M47: 2694785 | N47: 2704084 | O47: 2900312 | P47: 3174646 | Q47: =P47 -> 3174646 | R47: 2956096 | S47: 2967616 | T47: 3129911 | U47: 4271846 | V47: =U47 -> 4271846 | W47: 4657206 | X47: 4615038 | Y47: 4595190 | Z47: 5193325 | AA47: =Z47 -> 5193325 | AB47: 5245444 | AC47: 5318395 | AD47: 5474060 | AE47: 5664359 | AF47: =AE47 -> 5664359
C48: Total non-current assets | G48: USD'k | H48: =SUM(H45:H47) -> 23049725 | I48: =SUM(I45:I47) -> 24294182 | J48: =SUM(J45:J47) -> 25613953 | K48: =SUM(K45:K47) -> 27797208 | L48: =SUM(L45:L47) -> 27797208 | M48: =SUM(M45:M47) -> 28612129 | N48: =SUM(N45:N47) -> 28611142 | O48: =SUM(O45:O47) -> 28796063 | ... AF48: =SUM(AF45:AF47) -> 38813859
C50: Total assets | G50: USD'k | H50: =H48+H43 -> 27218632 | I50: =I48+I43 -> 30171339 | J50: =J48+J43 -> 30941711 | K50: =K48+K43 -> 33975712 | L50: =L48+L43 -> 33975712 | M50: =M48+M43 -> 35059910 | N50: =N48+N43 -> 37175281 | O50: =O48+O43 -> 38622543 | ... AF50: =AF48+AF43 -> 48731992
C52: Current content liabilities | G52: USD'k | H52: 4858899 | I52: 4846525 | J52: 4857520 | K52: 4413561 | L52: =K52 -> 4413561 | M52: 4761585 | N52: 4664733 | O52: 4599654 | P52: 4429536 | Q52: =P52 -> 4429536 | R52: 4297957 | S52: 4197874 | T52: 4110962 | U52: 4292967 | V52: =U52 -> 4292967 | W52: 4066289 | X52: 4174966 | Y52: 4225890 | Z52: 4480150 | AA52: =Z52 -> 4480150 | AB52: 4344580 | AC52: 4440412 | AD52: 4259582 | AE52: 4466470 | AF52: =AE52 -> 4466470
C53: Accounts payable | G53: USD'k | H53: 439496 | I53: 442194 | J53: 444129 | K53: 674347 | L53: =K53 -> 674347 | M53: 545488 | N53: 446668 | O53: 541298 | P53: 656183 | Q53: =P53 -> 656183 | R53: 532942 | S53: 622931 | T53: 643059 | U53: 837483 | V53: =U53 -> 837483 | W53: 617202 | X53: 504278 | Y53: 560156 | Z53: 671513 | AA53: =Z53 -> 671513 | AB53: 591987 | AC53: 615374 | AD53: 534429 | AE53: 747412 | AF53: =AE53 -> 747412
C54: Accrued expenses and other liabilities | G54: USD'k | H54: 750720 | I54: 752488 | J54: 1040745 | K54: 843043 | L54: =K54 -> 843043 | M54: 1061090 | N54: 986595 | O54: 1259124 | P54: 1102196 | Q54: =P54 -> 1102196 | R54: 1291812 | S54: 1125591 | T54: 1413120 | U54: 1449351 | V54: =U54 -> 1449351 | W54: 1817117 | X54: 1596035 | Y54: 1803555 | Z54: 1514650 | AA54: =Z54 -> 1514650 | AB54: 1718069 | AC54: 1908714 | AD54: 1838908 | AE54: 1803960 | AF54: =AE54 -> 1803960
C55: Deferred revenue | G55: USD'k | H55: 808692 | I55: 892777 | J55: 915506 | K55: 924745 | L55: =K55 -> 924745 | M55: 986753 | N55: 1029261 | O55: 1040202 | P55: 1117992 | Q55: =P55 -> 1117992 | R55: 1140271 | S55: 1187364 | T55: 1182632 | U55: 1209342 | V55: =U55 -> 1209342 | W55: 1239048 | X55: 1224743 | Y55: 1176323 | Z55: 1264661 | AA55: =Z55 -> 1264661 | AB55: 1262271 | AC55: 1311918 | AD55: 1306185 | AE55: 1442969 | AF55: =AE55 -> 1442969
C56: Short-term debt | G56: USD'k | H56: 0 | I56: 0 | J56: 0 | K56: 0 | L56: =K56 -> 0 | M56: 498809 | N56: 499161 | O56: 499517 | P56: 499878 | Q56: =P56 -> 499878 | R56: 698788 | S56: 699128 | T56: 699473 | U56: 699823 | V56: =U56 -> 699823 | W56: 0 | X56: 0 | Y56: 0 | Z56: 0 | AA56: =Z56 -> 0 | AB56: 399163 | AC56: 399387 | AD56: 399614 | AE56: 399844 | AF56: =AE56 -> 399844
...

Sheet Operating
C5: Operating Schedules | L5: Historicals | AK5: Forecasts | BC5: CAGR
G6: Units | H6: 19Q1 | I6: 19Q2 | J6: 19Q3 | K6: 19Q4 | L6: 2019A | M6: 20Q1 | N6: 20Q2 | O6: 20Q3 | P6: 20Q4 | Q6: 2020A | R6: 21Q1 | S6: 21Q2 | T6: 21Q3 | U6: 21Q4 | V6: 2021A | W6: 22Q1 | X6: 22Q2 | Y6: 22Q3 | Z6: 22Q4 | AA6: 2022A | AB6: 23Q1 | AC6: 23Q2 | AD6: 23Q3 | AE6: 23Q4 | AF6: 2023A | AG6: 24Q1 | AH6: 24Q2 | AI6: 24Q3 | AJ6: 24Q4 | AK6: 2024E | AL6: 25Q1 | AM6: 25Q2 | AN6: 25Q3 | AO6: 25Q4 | AP6: 2025E | AQ6: 26Q1 | AR6: 26Q2 | AS6: 26Q3 | AT6: 26Q4 | AU6: 2026E | AV6: 27Q1 | AW6: 27Q2 | AX6: 27Q3 | AY6: 27Q4 | AZ6: 2027E | BA6: ='Financial Statements'!BA6 -> 2028E | BC6: 2019A - 2020A | BD6: 2020A - 2021A | BE6: 2021A - 2022A | BF6: 2022A - 2023A
A8: R | C8: Revenue Schedule
C10: Summary
C11: Total streaming revenue | G11: USD'k | H11: =H54 -> 4440304 | I11: =I54 -> 4846916 | J11: =J54 -> 5173028 | K11: =K54 -> 5398982 | L11: =L54 -> 19859230 | M11: =M54 -> 5703363 | N11: =N54 -> 6086715 | O11: =O54 -> 6376803 | ... BA11: =BA54 -> 71196534 | BC11: =IFERROR((Q11/L11)^(1/(_xlfn.NUMBERVALUE(LEFT(Q$6,4))-_xlfn.NUMBERVALUE(LEFT(L$6,4))))-1,"NA") -> 0.246608 | BD11: =IFERROR((V11/Q11)^(1/(_xlfn.NUMBERVALUE(LEFT(V$6,4))-_xlfn.NUMBERVALUE(LEFT(Q$6,4))))-1,"NA") -> 0.19222375 | BE11: =IFERROR((AA11/V11)^(1/(_xlfn.NUMBERVALUE(LEFT(AA$6,4))-_xlfn.NUMBERVALUE(LEFT(V$6,4))))-1,"NA") -> 0.066214574 | BF11: =IFERROR((AF11/AA11)^(1/(_xlfn.NUMBERVALUE(LEFT(AF$6,4))-_xlfn.NUMBERVALUE(LEFT(AA$6,4))))-1,"NA") -> 0.068974141
C12: Domestic DVD revenue | G12: USD'k | H12: =H57 -> 80688 | I12: =I57 -> 76200 | J12: =J57 -> 71877 | K12: =K57 -> 68452 | L12: =SUM(H12:K12) -> 297217 | M12: =SUM(M50) -> 64328 | N12: =SUM(N50) -> 61571 | O12: =SUM(O50) -> 58834 | P12: =SUM(P50) -> 54648 | Q12: =SUM(M12:P12) -> 239381 | R12: =SUM(R50) -> 49575 | S12: =SUM(S50) -> 46292 | T12: =SUM(T50) -> 44232 | U12: =SUM(U50) -> 42249 | V12: =SUM(R12:U12) -> 182348 | W12: =SUM(W50) -> 39810 | X12: =SUM(X50) -> 37090 | Y12: =SUM(Y50) -> 35228 | Z12: =SUM(Z50) -> 33569 | AA12: =SUM(W12:Z12) -> 145697 | AB12: =SUM(AB50) -> 27613 | AC12: =SUM(AC50) -> 27613 | AD12: =SUM(AD50) -> 27613 | AF12: =SUM(AB12:AE12) -> 82839 | BC12: =IFERROR((Q12/L12)^(1/(_xlfn.NUMBERVALUE(LEFT(Q$6,4))-_xlfn.NUMBERVALUE(LEFT(L$6,4))))-1,"NA") -> -0.19459183 | BD12: =IFERROR((V12/Q12)^(1/(_xlfn.NUMBERVALUE(LEFT(V$6,4))-_xlfn.NUMBERVALUE(LEFT(Q$6,4))))-1,"NA") -> -0.23825199 | BE12: =IFERROR((AA12/V12)^(1/(_xlfn.NUMBERVALUE(LEFT(AA$6,4))-_xlfn.NUMBERVALUE(LEFT(V$6,4))))-1,"NA") -> -0.2009948 | BF12: =IFERROR((AF12/AA12)^(1/(_xlfn.NUMBERVALUE(LEFT(AF$6,4))-_xlfn.NUMBERVALUE(LEFT(AA$6,4))))-1,"NA") -> -0.43142961
C13: Total revenue | G13: USD'k | H13: =SUM(H11:H12) -> 4520992 | I13: =SUM(I11:I12) -> 4923116 | J13: =SUM(J11:J12) -> 5244905 | K13: =SUM(K11:K12) -> 5467434 | L13: =SUM(L11:L12) -> 20156447 | M13: =SUM(M11:M12) -> 5767691 | N13: =SUM(N11:N12) -> 6148286 | O13: =SUM(O11:O12) -> 6435637 | ... BA13: =SUM(BA11:BA12) -> 71196534 | BC13: =IFERROR((Q13/L13)^(1/(_xlfn.NUMBERVALUE(LEFT(Q$6,4))-_xlfn.NUMBERVALUE(LEFT(L$6,4))))-1,"NA") -> 0.24010229 | BD13: =IFERROR((V13/Q13)^(1/(_xlfn.NUMBERVALUE(LEFT(V$6,4))-_xlfn.NUMBERVALUE(LEFT(Q$6,4))))-1,"NA") -> 0.18810119 | BE13: =IFERROR((AA13/V13)^(1/(_xlfn.NUMBERVALUE(LEFT(AA$6,4))-_xlfn.NUMBERVALUE(LEFT(V$6,4))))-1,"NA") -> 0.06457388 | BF13: =IFERROR((AF13/AA13)^(1/(_xlfn.NUMBERVALUE(LEFT(AF$6,4))-_xlfn.NUMBERVALUE(LEFT(AA$6,4))))-1,"NA") -> 0.066668082
C14: YoY growth rate | G14: % | M14: =M13/H13-1 -> 0.27575784 | N14: =N13/I13-1 -> 0.24886068 | O14: =O13/J13-1 -> 0.22702642 | P14: =P13/K13-1 -> 0.21527612 | Q14: =Q13/L13-1 -> 0.24010229 | R14: =R13/M13-1 -> 0.24196702 | S14: =S13/N13-1 -> 0.19411768 | T14: =T13/O13-1 -> 0.16281683 | ... AZ14: =AZ13/AU13-1 -> 0.17617793
C16: Streaming as a % of total revenue | G16: % | H16: =H11/H$13 -> 0.98215259 | I16: =I11/I$13 -> 0.984522 | J16: =J11/J$13 -> 0.98629584 | K16: =K11/K$13 -> 0.98748005 | L16: =L11/L$13 -> 0.98525449 | M16: =M11/M$13 -> 0.98884684 | N16: =N11/N$13 -> 0.98998566 | O16: =O11/O$13 -> 0.99085809 | ... BA16: =BA11/BA$13 -> 1
C17: Domestic DVD as a % of total revenue | G17: % | H17: =H12/H$13 -> 0.01784741 | I17: =I12/I$13 -> 0.015478002 | J17: =J12/J$13 -> 0.013704157 | K17: =K12/K$13 -> 0.01251995 | L17: =L12/L$13 -> 0.014745505 | M17: =M12/M$13 -> 0.011153163 | N17: =N12/N$13 -> 0.010014336 | O17: =O12/O$13 -> 0.0091419078 | ... BA17: =BA12/BA$13 -> 0
C19: Streaming revenue breakdown
C20: Europe, Middle East, and Africa (EMEA)
C21: Revenues | G21: USD'k | H21: 1233379 | I21: 1319087 | J21: 1428040 | K21: 1562561 | L21: =SUM(H21:K21) -> 5543067 | M21: 1723474 | N21: 1892537 | O21: 2019083 | P21: 2137158 | Q21: =SUM(M21:P21) -> 7772252 | R21: 2343674 | S21: 2400480 | T21: 2432239 | U21: 2523426 | V21: =SUM(R21:U21) -> 9699819 | W21: 2561831 | X21: 2457235 | Y21: 2375814 | Z21: 2350135 | AA21: =SUM(W21:Z21) -> 9745015 | AB21: 2517641 | AC21: 2562170 | AD21: 2693146 | AE21: 2783530 | AF21: =SUM(AB21:AE21) -> 10556487 | AG21: =AG25*AG24*3 -> 2931364.9 | AH21: =AH25*AH24*3 -> 3019324.8 | AI21: =AI25*AI24*3 -> 3197240.7 | AJ21: =AJ25*AJ24*3 -> 3419632.9 | AK21: =SUM(AG21:AJ21) -> 12567563 | AL21: =AL25*AL24*3 -> 3543626.9 | AM21: =AM25*AM24*3 -> 3653048.8 | AN21: =AN25*AN24*3 -> 3873990.5 | AO21: =AO25*AO24*3 -> 4161759.6 | AP21: =SUM(AL21:AO21) -> 15232426 | AQ21: =AQ25*AQ24*3 -> 4295722.9 | AR21: =AR25*AR24*3 -> 4425555.7 | AS21: =AS25*AS24*3 -> 4688650.5 | AT21: =AT25*AT24*3 -> 5036755.7 | AU21: =SUM(AQ21:AT21) -> 18446685 | AV21: =AV25*AV24*3 -> 5187849.2 | AW21: =AW25*AW24*3 -> 5336066.5 | AX21: =AX25*AX24*3 -> 5639880.8 | AY21: =AY25*AY24*3 -> 6045278.6 | AZ21: =SUM(AV21:AY21) -> 22209075 | BA21: =BA25*BA24*3 -> 6228019.5 | BC21: =IFERROR((Q21/L21)^(1/(_xlfn.NUMBERVALUE(LEFT(Q$6,4))-_xlfn.NUMBERVALUE(LEFT(L$6,4))))-1,"NA") -> 0.40215733 | BD21: =IFERROR((V21/Q21)^(1/(_xlfn.NUMBERVALUE(LEFT(V$6,4))-_xlfn.NUMBERVALUE(LEFT(Q$6,4))))-1,"NA") -> 0.24800624 | BE21: =IFERROR((AA21/V21)^(1/(_xlfn.NUMBERVALUE(LEFT(AA$6,4))-_xlfn.NUMBERVALUE(LEFT(V$6,4))))-1,"NA") -> 0.0046594684 | BF21: =IFERROR((AF21/AA21)^(1/(_xlfn.NUMBERVALUE(LEFT(AF$6,4))-_xlfn.NUMBERVALUE(LEFT(AA$6,4))))-1,"NA") -> 0.083270472
C22: Paid net membership additions | G22: #'k | H22: 4724 | I22: 1687 | J22: 3126 | K22: 4423 | L22: =SUM(H22:K22) -> 13960 | M22: 6956 | N22: 2749 | O22: 759 | P22: 4456 | Q22: =SUM(M22:P22) -> 14920 | R22: 1810 | S22: 188 | T22: 1804 | U22: 3536 | V22: =SUM(R22:U22) -> 7338 | W22: -303 | X22: -767 | Y22: 568 | Z22: 3195 | AA22: =SUM(W22:Z22) -> 2693 | AB22: 644 | AC22: 2434 | AD22: 3953 | AE22: 5053 | AF22: =SUM(AB22:AE22) -> 12084 | AG22: =Drivers!H13 -> 798.56 | AH22: =Drivers!I13 -> 2726.08 | AI22: =Drivers!J13 -> 4617.104 | AJ22: =Drivers!K13 -> 6144.448 | AK22: =SUM(AG22:AJ22) -> 14286.192 | AL22: =Drivers!M13 -> 977.43744 | AM22: =Drivers!N13 -> 3069.5661 | AN22: =Drivers!O13 -> 5328.138 | AO22: =Drivers!P13 -> 7348.7598 | AP22: =SUM(AL22:AO22) -> 16723.901 | AQ22: =Drivers!R13 -> 1135.7823 | AR22: =Drivers!S13 -> 3401.0792 | AS22: =Drivers!T13 -> 6047.4366 | AT22: =Drivers!U13 -> 8539.2589 | AU22: =SUM(AQ22:AT22) -> 19123.557 | AV22: =Drivers!W13 -> 1274.9156 | AW22: =Drivers!X13 -> 3692.7218 | AX22: =Drivers!Y13 -> 6714.1665 | AY22: =Drivers!Z13 -> 9585.3181 | AZ22: =SUM(AV22:AY22) -> 21267.122 | BA22: =Drivers!AB13 -> 1415.4751 | BC22: =IFERROR((Q22/L22)^(1/(_xlfn.NUMBERVALUE(LEFT(Q$6,4))-_xlfn.NUMBERVALUE(LEFT(L$6,4))))-1,"NA") -> 0.068767908 | BD22: =IFERROR((V22/Q22)^(1/(_xlfn.NUMBERVALUE(LEFT(V$6,4))-_xlfn.NUMBERVALUE(LEFT(Q$6,4))))-1,"NA") -> -0.50817694 | BE22: =IFERROR((AA22/V22)^(1/(_xlfn.NUMBERVALUE(LEFT(AA$6,4))-_xlfn.NUMBERVALUE(LEFT(V$6,4))))-1,"NA") -> -0.63300627 | BF22: =IFERROR((AF22/AA22)^(1/(_xlfn.NUMBERVALUE(LEFT(AF$6,4))-_xlfn.NUMBERVALUE(LEFT(AA$6,4))))-1,"NA") -> 3.487189
C23: Paid memberships at end of period | G23: #'k | H23: 42542 | I23: 44229 | J23: 47355 | K23: 51778 | L23: =K23 -> 51778 | M23: 58734 | N23: 61483 | O23: 62242 | P23: 66698 | Q23: =P23 -> 66698 | R23: 68508 | S23: 68696 | T23: 70500 | U23: 74036 | V23: =U23 -> 74036 | W23: 73733 | X23: 72966 | Y23: 73534 | Z23: 76729 | AA23: =Z23 -> 76729 | AB23: 77373 | AC23: 79807 | AD23: 83760 | AE23: 88813 | AF23: =AE23 -> 88813 | AG23: =AF23+AG22 -> 89611.56 | AH23: =AG23+AH22 -> 92337.64 | AI23: =AH23+AI22 -> 96954.744 | AJ23: =AI23+AJ22 -> 103099.19 | AK23: =AJ23 -> 103099.19 | AL23: =AK23+AL22 -> 104076.63 | AM23: =AL23+AM22 -> 107146.2 | AN23: =AM23+AN22 -> 112474.33 | AO23: =AN23+AO22 -> 119823.09 | AP23: =AO23 -> 119823.09 | AQ23: =AP23+AQ22 -> 120958.88 | AR23: =AQ23+AR22 -> 124359.95 | AS23: =AR23+AS22 -> 130407.39 | AT23: =AS23+AT22 -> 138946.65 | AU23: =AT23 -> 138946.65 | AV23: =AU23+AV22 -> 140221.57 | AW23: =AV23+AW22 -> 143914.29 | AX23: =AW23+AX22 -> 150628.45 | AY23: =AX23+AY22 -> 160213.77 | AZ23: =AY23 -> 160213.77 | BA23: =AZ23+BA22 -> 161629.25 | BC23: =IFERROR((Q23/L23)^(1/(_xlfn.NUMBERVALUE(LEFT(Q$6,4))-_xlfn.NUMBERVALUE(LEFT(L$6,4))))-1,"NA") -> 0.28815327 | BD23: =IFERROR((V23/Q23)^(1/(_xlfn.NUMBERVALUE(LEFT(V$6,4))-_xlfn.NUMBERVALUE(LEFT(Q$6,4))))-1,"NA") -> 0.11001829 | BE23: =IFERROR((AA23/V23)^(1/(_xlfn.NUMBERVALUE(LEFT(AA$6,4))-_xlfn.NUMBERVALUE(LEFT(V$6,4))))-1,"NA") -> 0.036374196 | BF23: =IFERROR((AF23/AA23)^(1/(_xlfn.NUMBERVALUE(LEFT(AF$6,4))-_xlfn.NUMBERVALUE(LEFT(AA$6,4))))-1,"NA") -> 0.15748935
C24: Average paying memberships | G24: #'k | H24: 40180 | I24: 43386 | J24: 45792 | K24: 49567 | L24: =AVERAGE(H24:K24) -> 44731.25 | M24: 55256 | N24: 60109 | O24: 61863 | P24: 64470 | Q24: =AVERAGE(M24:P24) -> 60424.5 | R24: 67603 | S24: 68602 | T24: 69598 | U24: 72268 | V24: =AVERAGE(R24:U24) -> 69517.75 | W24: 73885 | X24: 73350 | Y24: 73250 | Z24: 75132 | AA24: =AVERAGE(W24:Z24) -> 73904.25 | AB24: 77051 | AC24: 78590 | AD24: 81784 | AE24: 86287 | AF24: =AVERAGE(AB24:AE24) -> 80928 | AG24: =Drivers!$I$62*Operating!AG23 -> 86936.809 | AH24: =Drivers!$I$62*Operating!AH23 -> 89581.52 | AI24: =Drivers!$I$62*Operating!AI23 -> 94060.812 | AJ24: =Drivers!$I$62*Operating!AJ23 -> 100021.86 | AK24: =AVERAGE(AG24:AJ24) -> 92650.25 | AL24: =Drivers!$I$62*Operating!AL23 -> 100970.12 | AM24: =Drivers!$I$62*Operating!AM23 -> 103948.07 | AN24: =Drivers!$I$62*Operating!AN23 -> 109117.17 | AO24: =Drivers!$I$62*Operating!AO23 -> 116246.58 | AP24: =AVERAGE(AL24:AO24) -> 107570.48 | AQ24: =Drivers!$I$62*Operating!AQ23 -> 117348.46 | AR24: =Drivers!$I$62*Operating!AR23 -> 120648.02 | AS24: =Drivers!$I$62*Operating!AS23 -> 126514.96 | AT24: =Drivers!$I$62*Operating!AT23 -> 134799.33 | AU24: =AVERAGE(AQ24:AT24) -> 124827.69 | AV24: =Drivers!$I$62*Operating!AV23 -> 136036.19 | AW24: =Drivers!$I$62*Operating!AW23 -> 139618.69 | AX24: =Drivers!$I$62*Operating!AX23 -> 146132.45 | AY24: =Drivers!$I$62*Operating!AY23 -> 155431.67 | AZ24: =AVERAGE(AV24:AY24) -> 144304.75 | BA24: =Drivers!$I$62*Operating!BA23 -> 156804.89 | BC24: =IFERROR((Q24/L24)^(1/(_xlfn.NUMBERVALUE(LEFT(Q$6,4))-_xlfn.NUMBERVALUE(LEFT(L$6,4))))-1,"NA") -> 0.35083415 | BD24: =IFERROR((V24/Q24)^(1/(_xlfn.NUMBERVALUE(LEFT(V$6,4))-_xlfn.NUMBERVALUE(LEFT(Q$6,4))))-1,"NA") -> 0.15048945 | BE24: =IFERROR((AA24/V24)^(1/(_xlfn.NUMBERVALUE(LEFT(AA$6,4))-_xlfn.NUMBERVALUE(LEFT(V$6,4))))-1,"NA") -> 0.063098993 | BF24: =IFERROR((AF24/AA24)^(1/(_xlfn.NUMBERVALUE(LEFT(AF$6,4))-_xlfn.NUMBERVALUE(LEFT(AA$6,4))))-1,"NA") -> 0.095038513
C25: Average monthly revenue per paying membership (ARPU) | G25: USD | H25: 10.23 | I25: 10.13 | J25: 10.4 | K25: 10.51 | L25: =AVERAGE(H25:K25) -> 10.3175 | M25: 10.4 | N25: 10.5 | O25: 10.88 | P25: 11.05 | Q25: =AVERAGE(M25:P25) -> 10.7075 | R25: 11.56 | S25: 11.66 | T25: 11.65 | U25: 11.64 | V25: =AVERAGE(R25:U25) -> 11.6275 | W25: 11.56 | X25: 11.17 | Y25: 10.81 | Z25: 10.43 | AA25: =AVERAGE(W25:Z25) -> 10.9925 | AB25: 10.89 | AC25: 10.87 | AD25: 10.98 | AE25: 10.75 | AF25: =AVERAGE(AB25:AE25) -> 10.8725 | AG25: =Drivers!H40 -> 11.239447 | AH25: =Drivers!I40 -> 11.234924 | AI25: =Drivers!J40 -> 11.330403 | AJ25: =Drivers!K40 -> 11.396285 | AK25: =AVERAGE(AG25:AJ25) -> 11.300265 | AL25: =Drivers!M40 -> 11.698599 | AM25: =Drivers!N40 -> 11.71434 | AN25: =Drivers!O40 -> 11.834345 | AO25: =Drivers!P40 -> 11.933712 | AP25: =AVERAGE(AL25:AO25) -> 11.795249 | AQ25: =Drivers!R40 -> 12.202185 | AR25: =Drivers!S40 -> 12.227181 | AS25: =Drivers!T40 -> 12.35335 | AT25: =Drivers!U40 -> 12.454947 | AU25: =AVERAGE(AQ25:AT25) -> 12.309416 | AV25: =Drivers!W40 -> 12.711934 | AW25: =Drivers!X40 -> 12.739618 | AX25: =Drivers!Y40 -> 12.864769 | AY25: =Drivers!Z40 -> 12.964494 | AZ25: =AVERAGE(AV25:AY25) -> 12.820204 | BA25: =Drivers!AB40 -> 13.239424 | BC25: =IFERROR((Q25/L25)^(1/(_xlfn.NUMBERVALUE(LEFT(Q$6,4))-_xlfn.NUMBERVALUE(LEFT(L$6,4))))-1,"NA") -> 0.037799855 | BD25: =IFERROR((V25/Q25)^(1/(_xlfn.NUMBERVALUE(LEFT(V$6,4))-_xlfn.NUMBERVALUE(LEFT(Q$6,4))))-1,"NA") -> 0.085921083 | BE25: =IFERROR((AA25/V25)^(1/(_xlfn.NUMBERVALUE(LEFT(AA$6,4))-_xlfn.NUMBERVALUE(LEFT(V$6,4))))-1,"NA") -> -0.054611911 | BF25: =IFERROR((AF25/AA25)^(1/(_xlfn.NUMBERVALUE(LEFT(AF$6,4))-_xlfn.NUMBERVALUE(LEFT(AA$6,4))))-1,"NA") -> -0.010916534
Q26: =Q24/L24-1 -> 0.35083415 | V26: =V24/Q24-1 -> 0.15048945 | AA26: =AA24/V24-1 -> 0.063098993 | AF26: =AF24/AA24-1 -> 0.095038513 | AK26: =AK24/AF24-1 -> 0.14484789 | AP26: =AP24/AK24-1 -> 0.16103825 | AU26: =AU24/AP24-1 -> 0.16042699 | AZ26: =AZ24/AU24-1 -> 0.15603155 | BA26: =BA24/AV24-1 -> 0.15267039 | BC26: =(BA24/AF24)^(1/5)-1 -> 0.14143756
C27: United States and Canada (UCAN) | Q27: =Q25/L25-1 -> 0.037799855 | V27: =V25/Q25-1 -> 0.085921083 | AA27: =AA25/V25-1 -> -0.054611911 | AF27: =AF25/AA25-1 -> -0.010916534 | AK27: =AK25/AF25-1 -> 0.039343743 | AP27: =AP25/AK25-1 -> 0.043802867 | AU27: =AU25/AP25-1 -> 0.04359102 | AZ27: =AZ25/AU25-1 -> 0.041495701 | BA27: =BA25/AV25-1 -> 0.041495701
C28: Revenues | G28: USD'k | H28: 2256851 | I28: 2501199 | J28: 2621250 | K28: 2671908 | L28: =SUM(H28:K28) -> 10051208 | M28: 2702776 | N28: 2839670 | O28: 2933445 | P28: 2979505 | Q28: =SUM(M28:P28) -> 11455396 | R28: 3170972 | S28: 3234643 | T28: 3257697 | U28: 3308788 | V28: =SUM(R28:U28) -> 12972100 | W28: 3350424 | X28: 3537863 | Y28: 3601565 | Z28: 3594791 | AA28: =SUM(W28:Z28) -> 14084643 | AB28: 3608645 | AC28: 3599448 | AD28: 3735133 | AE28: 3930557 | AF28: =SUM(AB28:AE28) -> 14873783 | AG28: =AG32*AG31*3 -> 4039647.5 | AH28: =AH32*AH31*3 -> 4111214.9 | AI28: =AI32*AI31*3 -> 4266096.3 | AJ28: =AJ32*AJ31*3 -> 4477534.2 | AK28: =SUM(AG28:AJ28) -> 16894493 | AL28: =AL32*AL31*3 -> 4605516.7 | AM28: =AM32*AM31*3 -> 4694782 | AN28: =AN32*AN31*3 -> 4870025.6 | AO28: =AO32*AO31*3 -> 5127072.2 | AP28: =SUM(AL28:AO28) -> 19297396 | AQ28: =AQ32*AQ31*3 -> 5271862 | AR28: =AR32*AR31*3 -> 5375112.5 | AS28: =AS32*AS31*3 -> 5574463.2 | AT28: =AT32*AT31*3 -> 5879467.1 | AU28: =SUM(AQ28:AT28) -> 22100905 | AV28: =AV32*AV31*3 -> 6034203.3 | AW28: =AW32*AW31*3 -> 6151954.5 | AX28: =AX32*AX31*3 -> 6375997.2 | AY28: =AY32*AY31*3 -> 6724480 | AZ28: =SUM(AV28:AY28) -> 25286635 | BA28: =BA32*BA31*3 -> 6906421.5 | BC28: =IFERROR((Q28/L28)^(1/(_xlfn.NUMBERVALUE(LEFT(Q$6,4))-_xlfn.NUMBERVALUE(LEFT(L$6,4))))-1,"NA") -> 0.13970341 | BD28: =IFERROR((V28/Q28)^(1/(_xlfn.NUMBERVALUE(LEFT(V$6,4))-_xlfn.NUMBERVALUE(LEFT(Q$6,4))))-1,"NA") -> 0.13240084 | BE28: =IFERROR((AA28/V28)^(1/(_xlfn.NUMBERVALUE(LEFT(AA$6,4))-_xlfn.NUMBERVALUE(LEFT(V$6,4))))-1,"NA") -> 0.085764294 | BF28: =IFERROR((AF28/AA28)^(1/(_xlfn.NUMBERVALUE(LEFT(AF$6,4))-_xlfn.NUMBERVALUE(LEFT(AA$6,4))))-1,"NA") -> 0.056028399
C29: Paid net membership additions | G29: #'k | H29: 1876 | I29: -132 | J29: 613 | K29: 548 | L29: =SUM(H29:K29) -> 2905 | M29: 2307 | N29: 2935 | O29: 177 | P29: 855 | Q29: =SUM(M29:P29) -> 6274 | R29: 448 | S29: -433 | T29: 73 | U29: 1191 | V29: =SUM(R29:U29) -> 1279 | W29: -636 | X29: -1296 | Y29: 104 | Z29: 909 | AA29: =SUM(W29:Z29) -> -919 | AB29: 102 | AC29: 1173 | AD29: 1750 | AE29: 2807 | AF29: =SUM(AB29:AE29) -> 5832 | AG29: =Drivers!H14 -> 126.48 | AH29: =Drivers!I14 -> 1299.684 | AI29: =Drivers!J14 -> 1897 | AJ29: =Drivers!K14 -> 3278.576 | AK29: =SUM(AG29:AJ29) -> 6601.74 | AL29: =Drivers!M14 -> 150.32148 | AM29: =Drivers!N14 -> 1450.4473 | AN29: =Drivers!O14 -> 2144.5585 | AO29: =Drivers!P14 -> 3849.0482 | AP29: =SUM(AL29:AO29) -> 7594.3755 | AQ29: =Drivers!R14 -> 171.36649 | AR29: =Drivers!S14 -> 1592.5912 | AS29: =Drivers!T14 -> 2354.7252 | AT29: =Drivers!U14 -> 4387.915 | AU29: =SUM(AQ29:AT29) -> 8506.5979 | AV29: =Drivers!W14 -> 188.84587 | AW29: =Drivers!X14 -> 1734.7299 | AX29: =Drivers!Y14 -> 2564.8845 | AY29: =Drivers!Z14 -> 4835.4823 | AZ29: =SUM(AV29:AY29) -> 9323.9426 | BA29: =Drivers!AB14 -> 206.90426 | BC29: =IFERROR((Q29/L29)^(1/(_xlfn.NUMBERVALUE(LEFT(Q$6,4))-_xlfn.NUMBERVALUE(LEFT(L$6,4))))-1,"NA") -> 1.1597246 | BD29: =IFERROR((V29/Q29)^(1/(_xlfn.NUMBERVALUE(LEFT(V$6,4))-_xlfn.NUMBERVALUE(LEFT(Q$6,4))))-1,"NA") -> -0.79614281 | BE29: =IFERROR((AA29/V29)^(1/(_xlfn.NUMBERVALUE(LEFT(AA$6,4))-_xlfn.NUMBERVALUE(LEFT(V$6,4))))-1,"NA") -> -1.7185301 | BF29: =IFERROR((AF29/AA29)^(1/(_xlfn.NUMBERVALUE(LEFT(AF$6,4))-_xlfn.NUMBERVALUE(LEFT(AA$6,4))))-1,"NA") -> -7.3460283
C30: Paid memberships at end of period | G30: #'k | H30: 66633 | I30: 66501 | J30: 67114 | K30: 67662 | L30: =K30 -> 67662 | M30: 69969 | N30: 72904 | O30: 73081 | P30: 73936 | Q30: =P30 -> 73936 | R30: 74384 | S30: 73951 | T30: 74024 | U30: 75215 | V30: =U30 -> 75215 | W30: 74579 | X30: 73283 | Y30: 73387 | Z30: 74296 | AA30: =Z30 -> 74296 | AB30: 74398 | AC30: 75571 | AD30: 77321 | AE30: 80128 | AF30: =AE30 -> 80128 | AG30: =AF30+AG29 -> 80254.48 | AH30: =AG30+AH29 -> 81554.164 | AI30: =AH30+AI29 -> 83451.164 | AJ30: =AI30+AJ29 -> 86729.74 | AK30: =AJ30 -> 86729.74 | AL30: =AK30+AL29 -> 86880.061 | AM30: =AL30+AM29 -> 88330.509 | AN30: =AM30+AN29 -> 90475.067 | AO30: =AN30+AO29 -> 94324.116 | AP30: =AO30 -> 94324.116 | AQ30: =AP30+AQ29 -> 94495.482 | AR30: =AQ30+AR29 -> 96088.073 | AS30: =AR30+AS29 -> 98442.798 | AT30: =AS30+AT29 -> 102830.71 | AU30: =AT30 -> 102830.71 | AV30: =AU30+AV29 -> 103019.56 | AW30: =AV30+AW29 -> 104754.29 | AX30: =AW30+AX29 -> 107319.17 | AY30: =AX30+AY29 -> 112154.66 | AZ30: =AY30 -> 112154.66 | BA30: =AZ30+BA29 -> 112361.56 | BC30: =IFERROR((Q30/L30)^(1/(_xlfn.NUMBERVALUE(LEFT(Q$6,4))-_xlfn.NUMBERVALUE(LEFT(L$6,4))))-1,"NA") -> 0.092725607 | BD30: =IFERROR((V30/Q30)^(1/(_xlfn.NUMBERVALUE(LEFT(V$6,4))-_xlfn.NUMBERVALUE(LEFT(Q$6,4))))-1,"NA") -> 0.017298745 | BE30: =IFERROR((AA30/V30)^(1/(_xlfn.NUMBERVALUE(LEFT(AA$6,4))-_xlfn.NUMBERVALUE(LEFT(V$6,4))))-1,"NA") -> -0.012218308 | BF30: =IFERROR((AF30/AA30)^(1/(_xlfn.NUMBERVALUE(LEFT(AF$6,4))-_xlfn.NUMBERVALUE(LEFT(AA$6,4))))-1,"NA") -> 0.078496824
C31: Average paying memberships | G31: #'k | H31: 65695 | I31: 66567 | J31: 66808 | K31: 67388 | L31: =AVERAGE(H31:K31) -> 66614.5 | M31: 68816 | N31: 71437 | O31: 72993 | P31: 73509 | Q31: =AVERAGE(M31:P31) -> 71688.75 | R31: 74160 | S31: 74168 | T31: 73988 | U31: 74620 | V31: =AVERAGE(R31:U31) -> 74234 | W31: 74897 | X31: 73931 | Y31: 73335 | Z31: 73842 | AA31: =AVERAGE(W31:Z31) -> 74001.25 | AB31: 74347 | AC31: 74985 | AD31: 76446 | AE31: 78725 | AF31: =AVERAGE(AB31:AE31) -> 76125.75 | AG31: =Drivers!$I$63*Operating!AG30 -> 79590.685 | AH31: =Drivers!$I$63*Operating!AH30 -> 80879.619 | AI31: =Drivers!$I$63*Operating!AI30 -> 82760.929 | AJ31: =Drivers!$I$63*Operating!AJ30 -> 86012.387 | AK31: =AVERAGE(AG31:AJ31) -> 82310.905 | AL31: =Drivers!$I$63*Operating!AL30 -> 86161.465 | AM31: =Drivers!$I$63*Operating!AM30 -> 87599.916 | AN31: =Drivers!$I$63*Operating!AN30 -> 89726.736 | AO31: =Drivers!$I$63*Operating!AO30 -> 93543.949 | AP31: =AVERAGE(AL31:AO31) -> 89258.017 | AQ31: =Drivers!$I$63*Operating!AQ30 -> 93713.898 | AR31: =Drivers!$I$63*Operating!AR30 -> 95293.316 | AS31: =Drivers!$I$63*Operating!AS30 -> 97628.565 | AT31: =Drivers!$I$63*Operating!AT30 -> 101980.19 | AU31: =AVERAGE(AQ31:AT31) -> 97153.992 | AV31: =Drivers!$I$63*Operating!AV30 -> 102167.47 | AW31: =Drivers!$I$63*Operating!AW30 -> 103887.85 | AX31: =Drivers!$I$63*Operating!AX30 -> 106431.52 | AY31: =Drivers!$I$63*Operating!AY30 -> 111227.01 | AZ31: =AVERAGE(AV31:AY31) -> 105928.46 | BA31: =Drivers!$I$63*Operating!BA30 -> 111432.2 | BC31: =IFERROR((Q31/L31)^(1/(_xlfn.NUMBERVALUE(LEFT(Q$6,4))-_xlfn.NUMBERVALUE(LEFT(L$6,4))))-1,"NA") -> 0.076173356 | BD31: =IFERROR((V31/Q31)^(1/(_xlfn.NUMBERVALUE(LEFT(V$6,4))-_xlfn.NUMBERVALUE(LEFT(Q$6,4))))-1,"NA") -> 0.035504176 | BE31: =IFERROR((AA31/V31)^(1/(_xlfn.NUMBERVALUE(LEFT(AA$6,4))-_xlfn.NUMBERVALUE(LEFT(V$6,4))))-1,"NA") -> -0.0031353558 | BF31: =IFERROR((AF31/AA31)^(1/(_xlfn.NUMBERVALUE(LEFT(AF$6,4))-_xlfn.NUMBERVALUE(LEFT(AA$6,4))))-1,"NA") -> 0.028708975
C32: Average monthly revenue per paying membership (ARPU) | G32: USD | H32: 11.45 | I32: 12.52 | J32: 13.08 | K32: 13.22 | L32: =AVERAGE(H32:K32) -> 12.5675 | M32: 13.09 | N32: 13.25 | O32: 13.4 | P32: 13.51 | Q32: =AVERAGE(M32:P32) -> 13.3125 | R32: 14.25 | S32: 14.54 | T32: 14.68 | U32: 14.78 | V32: =AVERAGE(R32:U32) -> 14.5625 | W32: 14.91 | X32: 15.95 | Y32: 16.37 | Z32: 16.23 | AA32: =AVERAGE(W32:Z32) -> 15.865 | AB32: 16.18 | AC32: 16 | AD32: 16.29 | AE32: 16.64 | AF32: =AVERAGE(AB32:AE32) -> 16.2775 | AG32: =Drivers!H41 -> 16.918427 | AH32: =Drivers!I41 -> 16.943761 | AI32: =Drivers!J41 -> 17.182409 | AJ32: =Drivers!K41 -> 17.352285 | AK32: =AVERAGE(AG32:AJ32) -> 17.09922 | AL32: =Drivers!M41 -> 17.817388 | AM32: =Drivers!N41 -> 17.864484 | AN32: =Drivers!O41 -> 18.092064 | AO32: =Drivers!P41 -> 18.269745 | AP32: =AVERAGE(AL32:AO32) -> 18.01092 | AQ32: =Drivers!R41 -> 18.751619 | AR32: =Drivers!S41 -> 18.801992 | AS32: =Drivers!T41 -> 19.032897 | AT32: =Drivers!U41 -> 19.217678 | AU32: =AVERAGE(AQ32:AT32) -> 18.951046 | AV32: =Drivers!W41 -> 19.687295 | AW32: =Drivers!X41 -> 19.739088 | AX32: =Drivers!Y41 -> 19.969012 | AY32: =Drivers!Z41 -> 20.152419 | AZ32: =AVERAGE(AV32:AY32) -> 19.886954 | BA32: =Drivers!AB41 -> 20.659562 | BC32: =IFERROR((Q32/L32)^(1/(_xlfn.NUMBERVALUE(LEFT(Q$6,4))-_xlfn.NUMBERVALUE(LEFT(L$6,4))))-1,"NA") -> 0.059279889 | BD32: =IFERROR((V32/Q32)^(1/(_xlfn.NUMBERVALUE(LEFT(V$6,4))-_xlfn.NUMBERVALUE(LEFT(Q$6,4))))-1,"NA") -> 0.093896714 | BE32: =IFERROR((AA32/V32)^(1/(_xlfn.NUMBERVALUE(LEFT(AA$6,4))-_xlfn.NUMBERVALUE(LEFT(V$6,4))))-1,"NA") -> 0.08944206 | BF32: =IFERROR((AF32/AA32)^(1/(_xlfn.NUMBERVALUE(LEFT(AF$6,4))-_xlfn.NUMBERVALUE(LEFT(AA$6,4))))-1,"NA") -> 0.02600063
Q33: =Q31/L31-1 -> 0.076173356 | V33: =V31/Q31-1 -> 0.035504176 | AA33: =AA31/V31-1 -> -0.0031353558 | AF33: =AF31/AA31-1 -> 0.028708975 | AK33: =AK31/AF31-1 -> 0.081249183 | AP33: =AP31/AK31-1 -> 0.084400865 | AU33: =AU31/AP31-1 -> 0.088462364 | AZ33: =AZ31/AU31-1 -> 0.090315102 | BA33: =BA31/AV31-1 -> 0.090681818 | BC33: =(BA31/AF31)^(1/5)-1 -> 0.079184817
C34: Latin America (LATAM) | Q34: =Q32/L32-1 -> 0.059279889 | V34: =V32/Q32-1 -> 0.093896714 | AA34: =AA32/V32-1 -> 0.08944206 | AF34: =AF32/AA32-1 -> 0.02600063 | AK34: =AK32/AF32-1 -> 0.050481971 | AP34: =AP32/AK32-1 -> 0.05331821 | AU34: =AU32/AP32-1 -> 0.052197572 | AZ34: =AZ32/AU32-1 -> 0.049385516 | BA34: =BA32/AV32-1 -> 0.049385516
C35: Revenues | G35: USD'k | H35: 630472 | I35: 677136 | J35: 741434 | K35: 746392 | L35: =SUM(H35:K35) -> 2795434 | M35: 793453 | N35: 785368 | O35: 789384 | P35: 788522 | Q35: =SUM(M35:P35) -> 3156727 | R35: 836647 | S35: 860882 | T35: 915297 | U35: 964150 | V35: =SUM(R35:U35) -> 3576976 | W35: 998948 | X35: 1030234 | Y35: 1023945 | Z35: 1016846 | AA35: =SUM(W35:Z35) -> 4069973 | AB35: 1070192 | AC35: 1077435 | AD35: 1142811 | AE35: 1156023 | AF35: =SUM(AB35:AE35) -> 4446461 | AG35: =AG39*AG38*3 -> 1226574.3 | AH35: =AH39*AH38*3 -> 1264263.7 | AI35: =AI39*AI38*3 -> 1309499.3 | AJ35: =AJ39*AJ38*3 -> 1383646.1 | AK35: =SUM(AG35:AJ35) -> 5183983.4 | AL35: =AL39*AL38*3 -> 1443079.2 | AM35: =AM39*AM38*3 -> 1486651.5 | AN35: =AN39*AN38*3 -> 1536201.7 | AO35: =AO39*AO38*3 -> 1629174.1 | AP35: =SUM(AL35:AO35) -> 6095106.5 | AQ35: =AQ39*AQ38*3 -> 1693218.4 | AR35: =AR39*AR38*3 -> 1743247.4 | AS35: =AS39*AS38*3 -> 1798935.1 | AT35: =AT39*AT38*3 -> 1906238.2 | AU35: =SUM(AQ35:AT35) -> 7141639.1 | AV35: =AV39*AV38*3 -> 1978218.2 | AW35: =AW39*AW38*3 -> 2034511.1 | AX35: =AX39*AX38*3 -> 2097116.3 | AY35: =AY39*AY38*3 -> 2216702.6 | AZ35: =SUM(AV35:AY35) -> 8326548.2 | BA35: =BA39*BA38*3 -> 2298326.8 | BC35: =IFERROR((Q35/L35)^(1/(_xlfn.NUMBERVALUE(LEFT(Q$6,4))-_xlfn.NUMBERVALUE(LEFT(L$6,4))))-1,"NA") -> 0.12924397 | BD35: =IFERROR((V35/Q35)^(1/(_xlfn.NUMBERVALUE(LEFT(V$6,4))-_xlfn.NUMBERVALUE(LEFT(Q$6,4))))-1,"NA") -> 0.13312808 | BE35: =IFERROR((AA35/V35)^(1/(_xlfn.NUMBERVALUE(LEFT(AA$6,4))-_xlfn.NUMBERVALUE(LEFT(V$6,4))))-1,"NA") -> 0.13782508 | BF35: =IFERROR((AF35/AA35)^(1/(_xlfn.NUMBERVALUE(LEFT(AF$6,4))-_xlfn.NUMBERVALUE(LEFT(AA$6,4))))-1,"NA") -> 0.092503808
C36: Paid net membership additions | G36: #'k | H36: 1470 | I36: 343 | J36: 1490 | K36: 2037 | L36: =SUM(H36:K36) -> 5340 | M36: 2901 | N36: 1750 | O36: 256 | P36: 1213 | Q36: =SUM(M36:P36) -> 6120 | R36: 357 | S36: 764 | T36: 330 | U36: 973 | V36: =SUM(R36:U36) -> 2424 | W36: -351 | X36: 14 | Y36: 312 | Z36: 1763 | AA36: =SUM(W36:Z36) -> 1738 | AB36: -450 | AC36: 1217 | AD36: 1179 | AE36: 2352 | AF36: =SUM(AB36:AE36) -> 4298 | AG36: =Drivers!H15 -> 973.896 | AH36: =Drivers!I15 -> 1363.04 | AI36: =Drivers!J15 -> 1278.036 | AJ36: =Drivers!K15 -> 2718.912 | AK36: =SUM(AG36:AJ36) -> 6333.884 | AL36: =Drivers!M15 -> 1118.5196 | AM36: =Drivers!N15 -> 1528.6494 | AN36: =Drivers!O15 -> 1381.5569 | AO36: =Drivers!P15 -> 3049.2598 | AP36: =SUM(AL36:AO36) -> 7077.9856 | AQ36: =Drivers!R15 -> 1220.3048 | AR36: =Drivers!S15 -> 1687.6289 | AS36: =Drivers!T15 -> 1471.3581 | AT36: =Drivers!U15 -> 3366.3828 | AU36: =SUM(AQ36:AT36) -> 7745.6747 | AV36: =Drivers!W15 -> 1306.3363 | AW36: =Drivers!X15 -> 1826.4364 | AX36: =Drivers!Y15 -> 1575.0889 | AY36: =Drivers!Z15 -> 3603.7128 | AZ36: =SUM(AV36:AY36) -> 8311.5744 | BA36: =Drivers!AB15 -> 1402.2704 | BC36: =IFERROR((Q36/L36)^(1/(_xlfn.NUMBERVALUE(LEFT(Q$6,4))-_xlfn.NUMBERVALUE(LEFT(L$6,4))))-1,"NA") -> 0.14606742 | BD36: =IFERROR((V36/Q36)^(1/(_xlfn.NUMBERVALUE(LEFT(V$6,4))-_xlfn.NUMBERVALUE(LEFT(Q$6,4))))-1,"NA") -> -0.60392157 | BE36: =IFERROR((AA36/V36)^(1/(_xlfn.NUMBERVALUE(LEFT(AA$6,4))-_xlfn.NUMBERVALUE(LEFT(V$6,4))))-1,"NA") -> -0.2830033 | BF36: =IFERROR((AF36/AA36)^(1/(_xlfn.NUMBERVALUE(LEFT(AF$6,4))-_xlfn.NUMBERVALUE(LEFT(AA$6,4))))-1,"NA") -> 1.4729574
C37: Paid memberships at end of period | G37: #'k | H37: 27547 | I37: 27890 | J37: 29380 | K37: 31417 | L37: =K37 -> 31417 | M37: 34318 | N37: 36068 | O37: 36324 | P37: 37537 | Q37: =P37 -> 37537 | R37: 37894 | S37: 38658 | T37: 38988 | U37: 39961 | V37: =U37 -> 39961 | W37: 39610 | X37: 39624 | Y37: 39936 | Z37: 41699 | AA37: =Z37 -> 41699 | AB37: 41249 | AC37: 42466 | AD37: 43645 | AE37: 45997 | AF37: =AE37 -> 45997 | AG37: =AF37+AG36 -> 46970.896 | AH37: =AG37+AH36 -> 48333.936 | AI37: =AH37+AI36 -> 49611.972 | AJ37: =AI37+AJ36 -> 52330.884 | AK37: =AJ37 -> 52330.884 | AL37: =AK37+AL36 -> 53449.404 | AM37: =AL37+AM36 -> 54978.053 | AN37: =AM37+AN36 -> 56359.61 | AO37: =AN37+AO36 -> 59408.87 | AP37: =AO37 -> 59408.87 | AQ37: =AP37+AQ36 -> 60629.174 | AR37: =AQ37+AR36 -> 62316.803 | AS37: =AR37+AS36 -> 63788.161 | AT37: =AS37+AT36 -> 67154.544 | AU37: =AT37 -> 67154.544 | AV37: =AU37+AV36 -> 68460.881 | AW37: =AV37+AW36 -> 70287.317 | AX37: =AW37+AX36 -> 71862.406 | AY37: =AX37+AY36 -> 75466.119 | AZ37: =AY37 -> 75466.119 | BA37: =AZ37+BA36 -> 76868.389 | BC37: =IFERROR((Q37/L37)^(1/(_xlfn.NUMBERVALUE(LEFT(Q$6,4))-_xlfn.NUMBERVALUE(LEFT(L$6,4))))-1,"NA") -> 0.19479899 | BD37: =IFERROR((V37/Q37)^(1/(_xlfn.NUMBERVALUE(LEFT(V$6,4))-_xlfn.NUMBERVALUE(LEFT(Q$6,4))))-1,"NA") -> 0.064576285 | BE37: =IFERROR((AA37/V37)^(1/(_xlfn.NUMBERVALUE(LEFT(AA$6,4))-_xlfn.NUMBERVALUE(LEFT(V$6,4))))-1,"NA") -> 0.043492405 | BF37: =IFERROR((AF37/AA37)^(1/(_xlfn.NUMBERVALUE(LEFT(AF$6,4))-_xlfn.NUMBERVALUE(LEFT(AA$6,4))))-1,"NA") -> 0.10307202
C38: Average paying memberships | G38: #'k | H38: 26812 | I38: 27719 | J38: 28635 | K38: 30399 | L38: =AVERAGE(H38:K38) -> 28391.25 | M38: 32868 | N38: 35193 | O38: 36196 | P38: 36931 | Q38: =AVERAGE(M38:P38) -> 35297 | R38: 37716 | S38: 38276 | T38: 38823 | U38: 39475 | V38: =AVERAGE(R38:U38) -> 38572.5 | W38: 39786 | X38: 39617 | Y38: 39780 | Z38: 40818 | AA38: =AVERAGE(W38:Z38) -> 40000.25 | AB38: 41474 | AC38: 41858 | AD38: 43056 | AE38: 44821 | AF38: =AVERAGE(AB38:AE38) -> 42802.25 | AG38: =Drivers!$I$64*Operating!AG37 -> 45961.931 | AH38: =Drivers!$I$64*Operating!AH37 -> 47295.692 | AI38: =Drivers!$I$64*Operating!AI37 -> 48546.275 | AJ38: =Drivers!$I$64*Operating!AJ37 -> 51206.783 | AK38: =AVERAGE(AG38:AJ38) -> 48252.67 | AL38: =Drivers!$I$64*Operating!AL37 -> 52301.276 | AM38: =Drivers!$I$64*Operating!AM37 -> 53797.089 | AN38: =Drivers!$I$64*Operating!AN37 -> 55148.969 | AO38: =Drivers!$I$64*Operating!AO37 -> 58132.728 | AP38: =AVERAGE(AL38:AO38) -> 54845.015 | AQ38: =Drivers!$I$64*Operating!AQ37 -> 59326.82 | AR38: =Drivers!$I$64*Operating!AR37 -> 60978.198 | AS38: =Drivers!$I$64*Operating!AS37 -> 62417.95 | AT38: =Drivers!$I$64*Operating!AT37 -> 65712.021 | AU38: =AVERAGE(AQ38:AT38) -> 62108.747 | AV38: =Drivers!$I$64*Operating!AV37 -> 66990.296 | AW38: =Drivers!$I$64*Operating!AW37 -> 68777.5 | AX38: =Drivers!$I$64*Operating!AX37 -> 70318.755 | AY38: =Drivers!$I$64*Operating!AY37 -> 73845.057 | AZ38: =AVERAGE(AV38:AY38) -> 69982.902 | BA38: =Drivers!$I$64*Operating!BA37 -> 75217.206 | BC38: =IFERROR((Q38/L38)^(1/(_xlfn.NUMBERVALUE(LEFT(Q$6,4))-_xlfn.NUMBERVALUE(LEFT(L$6,4))))-1,"NA") -> 0.24323515 | BD38: =IFERROR((V38/Q38)^(1/(_xlfn.NUMBERVALUE(LEFT(V$6,4))-_xlfn.NUMBERVALUE(LEFT(Q$6,4))))-1,"NA") -> 0.092798255 | BE38: =IFERROR((AA38/V38)^(1/(_xlfn.NUMBERVALUE(LEFT(AA$6,4))-_xlfn.NUMBERVALUE(LEFT(V$6,4))))-1,"NA") -> 0.037014713 | BF38: =IFERROR((AF38/AA38)^(1/(_xlfn.NUMBERVALUE(LEFT(AF$6,4))-_xlfn.NUMBERVALUE(LEFT(AA$6,4))))-1,"NA") -> 0.070049562
C39: Average monthly revenue per paying membership (ARPU) | G39: USD | H39: 7.84 | I39: 8.14 | J39: 8.63 | K39: 8.18 | L39: =AVERAGE(H39:K39) -> 8.1975 | M39: 8.05 | N39: 7.44 | O39: 7.27 | P39: 7.12 | Q39: =AVERAGE(M39:P39) -> 7.47 | R39: 7.39 | S39: 7.5 | T39: 7.86 | U39: 8.14 | V39: =AVERAGE(R39:U39) -> 7.7225 | W39: 8.37 | X39: 8.67 | Y39: 8.58 | Z39: 8.3 | AA39: =AVERAGE(W39:Z39) -> 8.48 | AB39: 8.6 | AC39: 8.58 | AD39: 8.85 | AE39: 8.6 | AF39: =AVERAGE(AB39:AE39) -> 8.6575 | AG39: =Drivers!H42 -> 8.8955813 | AH39: =Drivers!I42 -> 8.9103516 | AI39: =Drivers!J42 -> 8.9914165 | AJ39: =Drivers!K42 -> 9.0069193 | AK39: =AVERAGE(AG39:AJ39) -> 8.9510672 | AL39: =Drivers!M42 -> 9.1972215 | AM39: =Drivers!N42 -> 9.2114744 | AN39: =Drivers!O42 -> 9.2851642 | AO39: =Drivers!P42 -> 9.3416915 | AP39: =AVERAGE(AL39:AO39) -> 9.2588879 | AQ39: =Drivers!R42 -> 9.5135073 | AR39: =Drivers!S42 -> 9.5293479 | AS39: =Drivers!T42 -> 9.6069326 | AT39: =Drivers!U42 -> 9.6696573 | AU39: =AVERAGE(AQ39:AT39) -> 9.5798613 | AV39: =Drivers!W42 -> 9.8433075 | AW39: =Drivers!X42 -> 9.8603521 | AX39: =Drivers!Y42 -> 9.9410005 | AY39: =Drivers!Z42 -> 10.006098 | AZ39: =AVERAGE(AV39:AY39) -> 9.9126894 | BA39: =Drivers!AB42 -> 10.185288 | BC39: =IFERROR((Q39/L39)^(1/(_xlfn.NUMBERVALUE(LEFT(Q$6,4))-_xlfn.NUMBERVALUE(LEFT(L$6,4))))-1,"NA") -> -0.088746569 | BD39: =IFERROR((V39/Q39)^(1/(_xlfn.NUMBERVALUE(LEFT(V$6,4))-_xlfn.NUMBERVALUE(LEFT(Q$6,4))))-1,"NA") -> 0.033801874 | BE39: =IFERROR((AA39/V39)^(1/(_xlfn.NUMBERVALUE(LEFT(AA$6,4))-_xlfn.NUMBERVALUE(LEFT(V$6,4))))-1,"NA") -> 0.098089997 | BF39: =IFERROR((AF39/AA39)^(1/(_xlfn.NUMBERVALUE(LEFT(AF$6,4))-_xlfn.NUMBERVALUE(LEFT(AA$6,4))))-1,"NA") -> 0.020931604
Q40: =Q38/L38-1 -> 0.24323515 | V40: =V38/Q38-1 -> 0.092798255 | AA40: =AA38/V38-1 -> 0.037014713 | AF40: =AF38/AA38-1 -> 0.070049562 | AK40: =AK38/AF38-1 -> 0.12733956 | AP40: =AP38/AK38-1 -> 0.13662136 | AU40: =AU38/AP38-1 -> 0.13244106 | AZ40: =AZ38/AU38-1 -> 0.12678012 | BA40: =BA38/AV38-1 -> 0.12280748 | BC40: =(BA38/AF38)^(1/5)-1 -> 0.11936087
C41: Asia Pacific (APAC) | Q41: =Q39/L39-1 -> -0.088746569 | V41: =V39/Q39-1 -> 0.033801874 | AA41: =AA39/V39-1 -> 0.098089997 | AF41: =AF39/AA39-1 -> 0.020931604 | AK41: =AK39/AF39-1 -> 0.033908998 | AP41: =AP39/AK39-1 -> 0.03438928 | AU41: =AU39/AP39-1 -> 0.034666513 | AZ41: =AZ39/AU39-1 -> 0.034742482 | BA41: =BA39/AV39-1 -> 0.034742482
