Workbook
Name IQ_CH: 110000
Name IQ_CQ: 5000
Name IQ_CY: 10000
Name IQ_DAILY: 500000
Name IQ_FH: 100000
Name IQ_FQ: 500
Name IQ_FY: 1000
Name IQ_LTM: 2000
Name IQ_MONTH: 15000
Name IQ_NTM: 6000
Name IQ_WEEK: 50000
Name IQ_YTD: 3000

Sheet Master
B4: Nanyang Capital Stock Pitch Competition 2026
B5: Valuation Model
B7: NISSIN TSE: 2879

Sheet Drivers
B2: Nissin Foods Holdings Co Ltd
B3: (2897 JT)
G5: Period Start | H5: 44105 | I5: =H6+1 -> 44197 | J5: =I6+1 -> 44287 | K5: =J6+1 -> 44378 | L5: =K6+1 -> 44470 | M5: =L6+1 -> 44562 | N5: =M6+1 -> 44652 | O5: =N6+1 -> 44743 | P5: =O6+1 -> 44835 | ... AB5: =AA6+1 -> 45931
G6: Period End | H6: =EOMONTH(H5,2) -> 44196 | I6: =EOMONTH(I5,2) -> 44286 | J6: =EOMONTH(J5,2) -> 44377 | K6: =EOMONTH(K5,2) -> 44469 | L6: =EOMONTH(L5,2) -> 44561 | M6: =EOMONTH(M5,2) -> 44651 | N6: =EOMONTH(N5,2) -> 44742 | O6: =EOMONTH(O5,2) -> 44834 | ... AB6: =EOMONTH(AB5,2) -> 46022
G7: FY | H7: =IF(MONTH(H6)>3,YEAR(H6)+1,YEAR(H6)) -> 2021 | I7: =IF(MONTH(I6)>3,YEAR(I6)+1,YEAR(I6)) -> 2021 | J7: =IF(MONTH(J6)>3,YEAR(J6)+1,YEAR(J6)) -> 2022 | K7: =IF(MONTH(K6)>3,YEAR(K6)+1,YEAR(K6)) -> 2022 | L7: =IF(MONTH(L6)>3,YEAR(L6)+1,YEAR(L6)) -> 2022 | M7: =IF(MONTH(M6)>3,YEAR(M6)+1,YEAR(M6)) -> 2022 | N7: =IF(MONTH(N6)>3,YEAR(N6)+1,YEAR(N6)) -> 2023 | O7: =IF(MONTH(O6)>3,YEAR(O6)+1,YEAR(O6)) -> 2023 | ... AB7: =IF(MONTH(AB6)>3,YEAR(AB6)+1,YEAR(AB6)) -> 2026
B8: In Thousands of JPY | G8: Quarter | H8: =IF(MONTH(H5)=4,"Q1",IF(MONTH(H5)=7,"Q2",IF(MONTH(H5)=10,"Q3","Q4"))) -> Q3 | I8: =IF(MONTH(I5)=4,"Q1",IF(MONTH(I5)=7,"Q2",IF(MONTH(I5)=10,"Q3","Q4"))) -> Q4 | J8: =IF(MONTH(J5)=4,"Q1",IF(MONTH(J5)=7,"Q2",IF(MONTH(J5)=10,"Q3","Q4"))) -> Q1 | K8: =IF(MONTH(K5)=4,"Q1",IF(MONTH(K5)=7,"Q2",IF(MONTH(K5)=10,"Q3","Q4"))) -> Q2 | L8: =IF(MONTH(L5)=4,"Q1",IF(MONTH(L5)=7,"Q2",IF(MONTH(L5)=10,"Q3","Q4"))) -> Q3 | M8: =IF(MONTH(M5)=4,"Q1",IF(MONTH(M5)=7,"Q2",IF(MONTH(M5)=10,"Q3","Q4"))) -> Q4 | N8: =IF(MONTH(N5)=4,"Q1",IF(MONTH(N5)=7,"Q2",IF(MONTH(N5)=10,"Q3","Q4"))) -> Q1 | O8: =IF(MONTH(O5)=4,"Q1",IF(MONTH(O5)=7,"Q2",IF(MONTH(O5)=10,"Q3","Q4"))) -> Q2 | ... AB8: =IF(MONTH(AB5)=4,"Q1",IF(MONTH(AB5)=7,"Q2",IF(MONTH(AB5)=10,"Q3","Q4"))) -> Q3
G9: Days | H9: =_xlfn.DAYS(H6,H5)+1 -> 92 | I9: =_xlfn.DAYS(I6,I5)+1 -> 90 | J9: =_xlfn.DAYS(J6,J5)+1 -> 91 | K9: =_xlfn.DAYS(K6,K5)+1 -> 92 | L9: =_xlfn.DAYS(L6,L5)+1 -> 92 | M9: =_xlfn.DAYS(M6,M5)+1 -> 90 | N9: =_xlfn.DAYS(N6,N5)+1 -> 91 | O9: =_xlfn.DAYS(O6,O5)+1 -> 92 | ... AB9: =_xlfn.DAYS(AB6,AB5)+1 -> 92
A10: # | B10: Historical Quarterly Results
B12: Revenue | E12: Latest % of Revenue
B13: Instant Noodles | H13: =SUM(H14:H17) -> 96613 | I13: =SUM(I14:I17) -> 90658 | J13: =SUM(J14:J17) -> 88456 | K13: =SUM(K14:K17) -> 97060 | L13: =SUM(L14:L17) -> 104735 | M13: =SUM(M14:M17) -> 101254 | N13: =SUM(N14:N17) -> 102667 | O13: =SUM(O14:O17) -> 118232 | ... AB13: =SUM(AB14:AB17) -> 145992 | AN13: $
B14: Nissin Food Products | E14: =AB14/$AB$24 -> 0.33112536 | H14: 57884 | I14: 50707 | J14: 46577 | K14: 51948 | L14: 59620 | M14: 52637 | N14: 47791 | O14: 54071 | P14: 65104 | Q14: 53237 | R14: 51448 | S14: 56355 | T14: 69302 | U14: 55116 | V14: 53363 | W14: 57768 | X14: 69008 | Y14: 58642 | Z14: 52940 | AA14: 60064 | AB14: 70635
B15: Myojo Foods | E15: =AB15/$AB$24 -> 0.06135441 | H15: 9912 | I15: 9516 | J15: 9411 | K15: 9283 | L15: 9562 | M15: 9663 | N15: 9257 | O15: 10014 | P15: 10737 | Q15: 10502 | R15: 9963 | S15: 10388 | T15: 11582 | U15: 11516 | V15: 10751 | W15: 11498 | X15: 11862 | Y15: 11263 | Z15: 11635 | AA15: 11543 | AB15: 13088
B16: The Americas | E16: =AB16/$AB$24 -> 0.20909628 | H16: 17767 | I16: 17590 | J16: 20221 | K16: 22196 | L16: 21412 | M16: 23497 | N16: 29899 | O16: 36119 | P16: 38719 | Q16: 35304 | R16: 34433 | S16: 42276 | T16: 42470 | U16: 41154 | V16: 41981 | W16: 42476 | X16: 41151 | Y16: 42955 | Z16: 33380 | AA16: 41043 | AB16: 44604
B17: China | E17: =AB17/$AB$24 -> 0.08281064 | H17: 11050 | I17: 12845 | J17: 12247 | K17: 13633 | L17: 14141 | M17: 15457 | N17: 15720 | O17: 18028 | P17: 16389 | Q17: 16834 | R17: 14859 | S17: 18076 | T17: 15910 | U17: 17606 | V17: 16458 | W17: 18999 | X17: 18071 | Y17: 19945 | Z17: 16689 | AA17: 19190 | AB17: 17665
B18: Chilled / Frozen Foods & Beverages | E18: =AB18/$AB$24 -> 0.12651534 | H18: 19265 | I18: 19107 | J18: 20216 | K18: 20773 | L18: 20232 | M18: 19645 | N18: 20354 | O18: 21235 | P18: 22939 | Q18: 22309 | R18: 23213 | S18: 23559 | T18: 24769 | U18: 23679 | V18: 25462 | W18: 25474 | X18: 25828 | Y18: 24584 | Z18: 26154 | AA18: 26096 | AB18: 26988
B19: Confectionery / Snack | E19: =AB19/$AB$24 -> 0.11684902 | H19: 10433 | I19: 15931 | J19: 17063 | K19: 17740 | L19: 17222 | M19: 17006 | N19: 17561 | O19: 17647 | P19: 19754 | Q19: 19093 | R19: 20750 | S19: 20129 | T19: 22377 | U19: 21893 | V19: 23072 | W19: 22388 | X19: 24325 | Y19: 22658 | Z19: 23743 | AA19: 23460 | AB19: 24926
B20: Others | H20: 6412 | I20: 6552 | J20: =SUM(J21:J23) -> 6719 | K20: =SUM(K21:K23) -> 7003 | L20: =SUM(L21:L23) -> 7565 | M20: =SUM(M21:M23) -> 7023 | N20: =SUM(N21:N23) -> 8677 | O20: =SUM(O21:O23) -> 10573 | P20: =SUM(P21:P23) -> 10867 | Q20: =SUM(Q21:Q23) -> 10500 | ... AB20: =SUM(AB21:AB23) -> 15412
B21: Domestic | E21: =AB21/$AB$24 -> 0.01092266 | J21: 498 | K21: 564 | L21: 589 | M21: 520 | N21: 701 | O21: 1526 | P21: 1169 | Q21: 1282 | R21: 1442 | S21: 1678 | T21: 1393 | U21: 1569 | V21: 1761 | W21: 2100 | X21: 1721 | Y21: 2210 | Z21: 1907 | AA21: 2383 | AB21: 2330
B22: Asia | E22: =AB22/$AB$24 -> 0.027897318 | J22: 3391 | K22: 3879 | L22: 3905 | M22: 3602 | N22: 4557 | O22: 4867 | P22: 4966 | Q22: 4205 | R22: 5201 | S22: 5244 | T22: 5196 | U22: 5081 | V22: 6005 | W22: 5891 | X22: 5682 | Y22: 5691 | Z22: 5064 | AA22: 5656 | AB22: 5951
B23: EMEA | E23: =AB23/$AB$24 -> 0.033428965 | J23: 2830 | K23: 2560 | L23: 3071 | M23: 2901 | N23: 3419 | O23: 4180 | P23: 4732 | Q23: 5013 | R23: 5156 | S23: 6191 | T23: 5549 | U23: 6397 | V23: 6180 | W23: 6455 | X23: 6535 | Y23: 6368 | Z23: 5515 | AA23: 6772 | AB23: 7131
B24: Total Revenue | H24: =SUM(H13,H18:H20) -> 132723 | I24: =SUM(I13,I18:I20) -> 132248 | J24: =SUM(J13,J18:J20) -> 132454 | K24: =SUM(K13,K18:K20) -> 142576 | L24: =SUM(L13,L18:L20) -> 149754 | M24: =SUM(M13,M18:M20) -> 144928 | N24: =SUM(N13,N18:N20) -> 149259 | O24: =SUM(O13,O18:O20) -> 167687 | ... AB24: =SUM(AB13,AB18:AB20) -> 213318
B26: COGS | H26: -84730 | I26: -87484 | J26: -85725 | K26: -93381 | L26: -96905 | M26: -99207 | N26: -100150 | O26: -112100 | P26: -121274 | Q26: -114646 | R26: -108485 | S26: -117321 | T26: -125522 | U26: -122975 | V26: -117980 | W26: -124434 | X26: -132337 | Y26: -128891 | Z26: -116570 | AA26: -128399 | AB26: -138740
B27: Gross Profit | H27: 47993 | I27: 44764 | J27: 46729 | K27: 49195 | L27: 52849 | M27: 45721 | N27: 49109 | O27: 55587 | P27: 63235 | Q27: 53133 | R27: 57980 | S27: 66575 | T27: 73026 | U27: 61036 | V27: 67053 | W27: 68615 | X27: 71846 | Y27: 65425 | Z27: 60457 | AA27: 67808 | AB27: 74578
E28: Mean
B29: COGS Margin % | E29: =AVERAGE(H29:AB29) -> 0.65527909 | H29: =-H26/H$24 -> 0.63839726 | I29: =-I26/I$24 -> 0.66151473 | J29: =-J26/J$24 -> 0.64720582 | K29: =-K26/K$24 -> 0.65495595 | L29: =-L26/L$24 -> 0.64709457 | M29: =-M26/M$24 -> 0.68452611 | N29: =-N26/N$24 -> 0.67098131 | O29: =-O26/O$24 -> 0.6685074 | ... AB29: =-AB26/AB$24 -> 0.6503905
B30: Gross Profit Margin % | E30: =AVERAGE(H30:AB30) -> 0.34472091 | H30: =H27/H$24 -> 0.36160274 | I30: =I27/I$24 -> 0.33848527 | J30: =J27/J$24 -> 0.35279418 | K30: =K27/K$24 -> 0.34504405 | L30: =L27/L$24 -> 0.35290543 | M30: =M27/M$24 -> 0.31547389 | N30: =N27/N$24 -> 0.32901869 | O30: =O27/O$24 -> 0.3314926 | ... AB30: =AB27/AB$24 -> 0.3496095
B32: Accounts Receivable And Other Receivables | H32: 91511 | I32: 84837 | J32: 76286 | K32: 83738 | L32: 93222 | M32: 89600 | N32: 82290 | O32: 99864 | P32: 113040 | Q32: 101483 | R32: 94722 | S32: 109021 | T32: 120651 | U32: 116407 | V32: 107252 | W32: 105775 | X32: 125298 | Y32: 115072 | Z32: 103765 | AA32: 118174 | AB32: 135291
B33: Inventories | H33: 38262 | I33: 40901 | J33: 44193 | K33: 43723 | L33: 45965 | M33: 47638 | N33: 57773 | O33: 59626 | P33: 57292 | Q33: 57187 | R33: 66079 | S33: 69344 | T33: 67438 | U33: 64060 | V33: 71625 | W33: 71173 | X33: 75789 | Y33: 70536 | Z33: 74010 | AA33: 73824 | AB33: 76205
B34: Trade Payable And Other Payables | H34: 120225 | I34: 119275 | J34: 112877 | K34: 110398 | L34: 124017 | M34: 123251 | N34: 121933 | O34: 126624 | P34: 139750 | Q34: 140346 | R34: 127672 | S34: 144655 | T34: 150766 | U34: 161453 | V34: 144432 | W34: 131800 | X34: 156566 | Y34: 144703 | Z34: 132757 | AA34: 147672 | AB34: 155466
E35: Average
C36: Q1 | D36: Q2 | E36: Q3 | F36: Q4
B37: DSO | C37: =AVERAGEIF($I8:$AB8,C36,$I37:$AB37) -> 54.524052 | D37: =AVERAGEIF($I8:$AB8,D36,$I37:$AB37) -> 51.071129 | E37: =AVERAGEIF($I8:$AB8,E36,$I37:$AB37) -> 53.472447 | F37: =AVERAGEIF($I8:$AB8,F36,$I37:$AB37) -> 57.718245 | I37: =ABS(AVERAGE(H32:I32)/I$24*I$9) -> 60.005898 | J37: =ABS(AVERAGE(I32:J32)/J$24*J$9) -> 55.348245 | K37: =ABS(AVERAGE(J32:K32)/K$24*K$9) -> 51.629335 | L37: =ABS(AVERAGE(K32:L32)/L$24*L$9) -> 54.356879 | M37: =ABS(AVERAGE(L32:M32)/M$24*M$9) -> 56.766049 | N37: =ABS(AVERAGE(M32:N32)/N$24*N$9) -> 52.398817 | O37: =ABS(AVERAGE(N32:O32)/O$24*O$9) -> 49.968596 | P37: =ABS(AVERAGE(O32:P32)/P$24*P$9) -> 53.079167 | ... AB37: =ABS(AVERAGE(AA32:AB32)/AB$24*AB$9) -> 54.657319
B38: DIO | C38: =AVERAGEIF($I8:$AB8,C36,$I38:$AB38) -> 50.700474 | D38: =AVERAGEIF($I8:$AB8,D36,$I38:$AB38) -> 50.066267 | E38: =AVERAGEIF($I8:$AB8,E36,$I38:$AB38) -> 47.574976 | F38: =AVERAGEIF($I8:$AB8,F36,$I38:$AB38) -> 45.570514 | I38: =ABS(AVERAGE(H33:I33)/I$26*I$9) -> 40.719846 | J38: =ABS(AVERAGE(I33:J33)/J$26*J$9) -> 45.165086 | K38: =ABS(AVERAGE(J33:K33)/K$26*K$9) -> 43.307911 | L38: =ABS(AVERAGE(K33:L33)/L$26*L$9) -> 42.57415 | M38: =ABS(AVERAGE(L33:M33)/M$26*M$9) -> 42.458042 | N38: =ABS(AVERAGE(M33:N33)/N$26*N$9) -> 47.89017 | O38: =ABS(AVERAGE(N33:O33)/O$26*O$9) -> 48.174434 | P38: =ABS(AVERAGE(O33:P33)/P$26*P$9) -> 44.347741 | ... AB38: =ABS(AVERAGE(AA33:AB33)/AB$26*AB$9) -> 49.742929
B39: DPO | C39: =AVERAGEIF($I8:$AB8,C36,$I39:$AB39) -> 114.65735 | D39: =AVERAGEIF($I8:$AB8,D36,$I39:$AB39) -> 104.26778 | E39: =AVERAGEIF($I8:$AB8,E36,$I39:$AB39) -> 104.26347 | F39: =AVERAGEIF($I8:$AB8,F36,$I39:$AB39) -> 113.19941 | I39: =ABS(AVERAGE(H34:I34)/I$26*I$9) -> 123.19396 | J39: =ABS(AVERAGE(I34:J34)/J$26*J$9) -> 123.21862 | K39: =ABS(AVERAGE(J34:K34)/K$26*K$9) -> 109.98651 | L39: =ABS(AVERAGE(K34:L34)/L$26*L$9) -> 111.27486 | M39: =ABS(AVERAGE(L34:M34)/M$26*M$9) -> 112.16003 | N39: =ABS(AVERAGE(M34:N34)/N$26*N$9) -> 111.39163 | O39: =ABS(AVERAGE(N34:O34)/O$26*O$9) -> 101.99484 | P39: =ABS(AVERAGE(O34:P34)/P$26*P$9) -> 101.03735 | ... AB39: =ABS(AVERAGE(AA34:AB34)/AB$26*AB$9) -> 100.50705
A41: # | B41: YoY Quarterly Growth Rate (in %)
B43: Revenue | AE43: Arethmetic Mean | AF43: Geometric Mean
B44: Instant Noodles | L44: =L13/H13-1 -> 0.084067362 | M44: =M13/I13-1 -> 0.11687882 | N44: =N13/J13-1 -> 0.16065615 | O44: =O13/K13-1 -> 0.21813311 | P44: =P13/L13-1 -> 0.25028882 | Q44: =Q13/M13-1 -> 0.14441899 | R44: =R13/N13-1 -> 0.078272473 | S44: =S13/O13-1 -> 0.074962785 | ... AB44: =AB13/X13-1 -> 0.042115181 | AE44: =AVERAGE(L44:AB44) -> 0.085886455 | AF44: =(AB13/H13)^(1/((($AB$7-$H$7))))-1 -> 0.086072202
B45: Nissin Food Products | L45: =L14/H14-1 -> 0.029991017 | M45: =M14/I14-1 -> 0.038061806 | N45: =N14/J14-1 -> 0.026064367 | O45: =O14/K14-1 -> 0.040867791 | P45: =P14/L14-1 -> 0.091982556 | Q45: =Q14/M14-1 -> 0.011398826 | R45: =R14/N14-1 -> 0.076520684 | S45: =S14/O14-1 -> 0.042240758 | ... AB45: =AB14/X14-1 -> 0.023576977 | AE45: =AVERAGE(L45:AB45) -> 0.037313334 | AF45: =(AB14/H14)^(1/((($AB$7-$H$7))))-1 -> 0.040620274
B46: Myojo Foods | L46: =L15/H15-1 -> -0.035310734 | M46: =M15/I15-1 -> 0.015447667 | N46: =N15/J15-1 -> -0.01636383 | O46: =O15/K15-1 -> 0.078746095 | P46: =P15/L15-1 -> 0.12288224 | Q46: =Q15/M15-1 -> 0.086826037 | R46: =R15/N15-1 -> 0.076266609 | S46: =S15/O15-1 -> 0.037347713 | ... AB46: =AB15/X15-1 -> 0.10335525 | AE46: =AVERAGE(L46:AB46) -> 0.054043604 | AF46: =(AB15/H15)^(1/((($AB$7-$H$7))))-1 -> 0.057164081
B47: The Americas | L47: =L16/H16-1 -> 0.20515563 | M47: =M16/I16-1 -> 0.3358158 | N47: =N16/J16-1 -> 0.47861134 | O47: =O16/K16-1 -> 0.62727518 | P47: =P16/L16-1 -> 0.80828507 | Q47: =Q16/M16-1 -> 0.50248968 | R47: =R16/N16-1 -> 0.15164387 | S47: =S16/O16-1 -> 0.1704643 | ... AB47: =AB16/X16-1 -> 0.083910476 | AE47: =AVERAGE(L47:AB47) -> 0.21319187 | AF47: =(AB16/H16)^(1/((($AB$7-$H$7))))-1 -> 0.2021314
...

Sheet Operating Model
B2: Nissin Foods Holdings Co Ltd
B3: (2897 JT)
F4: Actual or Forecast | G4: Actual | H4: Actual | I4: Actual | J4: Actual | K4: Actual | L4: Actual | M4: Actual | N4: Actual | O4: Actual | P4: Actual | Q4: Actual | R4: Actual | S4: Actual | T4: Actual | U4: Actual | V4: Actual | W4: Actual | X4: Actual | Y4: Actual | Z4: Actual | AA4: Actual | AB4: Forecast | AC4: Forecast | AD4: Forecast | AE4: Forecast | AF4: Forecast | AG4: Forecast | AH4: Forecast | AI4: Forecast | AJ4: Forecast | AK4: Forecast | AL4: Forecast | AM4: Forecast | AN4: Forecast | AO4: Forecast | AP4: Forecast | AQ4: Forecast | AR4: Forecast | AS4: Forecast | AT4: Forecast | AU4: Forecast | AV4: Forecast
F5: Period Start | G5: 44105 | H5: =G6+1 -> 44197 | I5: =H6+1 -> 44287 | J5: =I6+1 -> 44378 | K5: =J6+1 -> 44470 | L5: =K6+1 -> 44562 | M5: =L6+1 -> 44652 | N5: =M6+1 -> 44743 | O5: =N6+1 -> 44835 | ... AV5: =AU6+1 -> 47849
F6: Period End | G6: =EOMONTH(G5,2) -> 44196 | H6: =EOMONTH(H5,2) -> 44286 | I6: =EOMONTH(I5,2) -> 44377 | J6: =EOMONTH(J5,2) -> 44469 | K6: =EOMONTH(K5,2) -> 44561 | L6: =EOMONTH(L5,2) -> 44651 | M6: =EOMONTH(M5,2) -> 44742 | N6: =EOMONTH(N5,2) -> 44834 | ... AV6: =EOMONTH(AV5,2) -> 47938
F7: FY | G7: =IF(MONTH(G6)>3,YEAR(G6)+1,YEAR(G6)) -> 2021 | H7: =IF(MONTH(H6)>3,YEAR(H6)+1,YEAR(H6)) -> 2021 | I7: =IF(MONTH(I6)>3,YEAR(I6)+1,YEAR(I6)) -> 2022 | J7: =IF(MONTH(J6)>3,YEAR(J6)+1,YEAR(J6)) -> 2022 | K7: =IF(MONTH(K6)>3,YEAR(K6)+1,YEAR(K6)) -> 2022 | L7: =IF(MONTH(L6)>3,YEAR(L6)+1,YEAR(L6)) -> 2022 | M7: =IF(MONTH(M6)>3,YEAR(M6)+1,YEAR(M6)) -> 2023 | N7: =IF(MONTH(N6)>3,YEAR(N6)+1,YEAR(N6)) -> 2023 | ... AV7: =IF(MONTH(AV6)>3,YEAR(AV6)+1,YEAR(AV6)) -> 2031
B8: In Thousands of JPY | C8: Note | F8: Quarter | G8: =IF(MONTH(G5)=4,"Q1",IF(MONTH(G5)=7,"Q2",IF(MONTH(G5)=10,"Q3","Q4"))) -> Q3 | H8: =IF(MONTH(H5)=4,"Q1",IF(MONTH(H5)=7,"Q2",IF(MONTH(H5)=10,"Q3","Q4"))) -> Q4 | I8: =IF(MONTH(I5)=4,"Q1",IF(MONTH(I5)=7,"Q2",IF(MONTH(I5)=10,"Q3","Q4"))) -> Q1 | J8: =IF(MONTH(J5)=4,"Q1",IF(MONTH(J5)=7,"Q2",IF(MONTH(J5)=10,"Q3","Q4"))) -> Q2 | K8: =IF(MONTH(K5)=4,"Q1",IF(MONTH(K5)=7,"Q2",IF(MONTH(K5)=10,"Q3","Q4"))) -> Q3 | L8: =IF(MONTH(L5)=4,"Q1",IF(MONTH(L5)=7,"Q2",IF(MONTH(L5)=10,"Q3","Q4"))) -> Q4 | M8: =IF(MONTH(M5)=4,"Q1",IF(MONTH(M5)=7,"Q2",IF(MONTH(M5)=10,"Q3","Q4"))) -> Q1 | N8: =IF(MONTH(N5)=4,"Q1",IF(MONTH(N5)=7,"Q2",IF(MONTH(N5)=10,"Q3","Q4"))) -> Q2 | ... AV8: =IF(MONTH(AV5)=4,"Q1",IF(MONTH(AV5)=7,"Q2",IF(MONTH(AV5)=10,"Q3","Q4"))) -> Q4
F9: Days | G9: =_xlfn.DAYS(G6,G5)+1 -> 92 | H9: =_xlfn.DAYS(H6,H5)+1 -> 90 | I9: =_xlfn.DAYS(I6,I5)+1 -> 91 | J9: =_xlfn.DAYS(J6,J5)+1 -> 92 | K9: =_xlfn.DAYS(K6,K5)+1 -> 92 | L9: =_xlfn.DAYS(L6,L5)+1 -> 90 | M9: =_xlfn.DAYS(M6,M5)+1 -> 91 | N9: =_xlfn.DAYS(N6,N5)+1 -> 92 | ... AV9: =_xlfn.DAYS(AV6,AV5)+1 -> 90
A10: # | B10: Income Statement
B12: Revenue
B13: Instant Noodles | G13: =SUM(G14:G17) -> 96613 | H13: =SUM(H14:H17) -> 90658 | I13: =SUM(I14:I17) -> 88456 | J13: =SUM(J14:J17) -> 97060 | K13: =SUM(K14:K17) -> 104735 | L13: =SUM(L14:L17) -> 101254 | M13: =SUM(M14:M17) -> 102667 | N13: =SUM(N14:N17) -> 118232 | ... AV13: =SUM(AV14:AV17) -> 232432.67
B14: Nissin Food Products | C14: Revenue Schedule | G14: 57884 | H14: 50707 | I14: 46577 | J14: 51948 | K14: 59620 | L14: 52637 | M14: 47791 | N14: 54071 | O14: 65104 | P14: 53237 | Q14: 51448 | R14: 56355 | S14: 69302 | T14: 55116 | U14: 53363 | V14: 57768 | W14: 69008 | X14: 58642 | Y14: 52940 | Z14: 60064 | AA14: 70635 | AB14: =Drivers!O121 -> 63509.286 | AC14: =Drivers!P121 -> 57334.02 | AD14: =Drivers!Q121 -> 65049.312 | AE14: =Drivers!R121 -> 76497.705 | AF14: =Drivers!S121 -> 68780.557 | AG14: =Drivers!T121 -> 62092.744 | AH14: =Drivers!U121 -> 70448.405 | AI14: =Drivers!V121 -> 82847.015 | ... AV14: =Drivers!AI121 -> 94619.253
B15: Myojo Foods | C15: Revenue Schedule | G15: 9912 | H15: 9516 | I15: 9411 | J15: 9283 | K15: 9562 | L15: 9663 | M15: 9257 | N15: 10014 | O15: 10737 | P15: 10502 | Q15: 9963 | R15: 10388 | S15: 11582 | T15: 11516 | U15: 10751 | V15: 11498 | W15: 11862 | X15: 11263 | Y15: 11635 | Z15: 11543 | AA15: 13088 | AB15: =Drivers!O122 -> 12197.829 | AC15: =Drivers!P122 -> 12600.705 | AD15: =Drivers!Q122 -> 12501.069 | AE15: =Drivers!R122 -> 14174.304 | AF15: =Drivers!S122 -> 13210.249 | AG15: =Drivers!T122 -> 13646.564 | AH15: =Drivers!U122 -> 13538.658 | AI15: =Drivers!V122 -> 15350.771 | ... AV15: =Drivers!AI122 -> 18172.925
B16: The Americas | C16: Revenue Schedule | G16: 17767 | H16: 17590 | I16: 20221 | J16: 22196 | K16: 21412 | L16: 23497 | M16: 29899 | N16: 36119 | O16: 38719 | P16: 35304 | Q16: 34433 | R16: 42276 | S16: 42470 | T16: 41154 | U16: 41981 | V16: 42476 | W16: 41151 | X16: 42955 | Y16: 33380 | Z16: 41043 | AA16: 44604 | AB16: =Drivers!O123 -> 48668.015 | AC16: =Drivers!P123 -> 37819.54 | AD16: =Drivers!Q123 -> 46501.719 | AE16: =Drivers!R123 -> 50536.332 | AF16: =Drivers!S123 -> 55140.861 | AG16: =Drivers!T123 -> 42849.539 | AH16: =Drivers!U123 -> 52686.448 | AI16: =Drivers!V123 -> 57257.664 | ... AV16: =Drivers!AI123 -> 90864.279
B17: China | C17: Revenue Schedule | G17: 11050 | H17: 12845 | I17: 12247 | J17: 13633 | K17: 14141 | L17: 15457 | M17: 15720 | N17: 18028 | O17: 16389 | P17: 16834 | Q17: 14859 | R17: 18076 | S17: 15910 | T17: 17606 | U17: 16458 | V17: 18999 | W17: 18071 | X17: 19945 | Y17: 16689 | Z17: 19190 | AA17: 17665 | AB17: =Drivers!O124 -> 21201.535 | AC17: =Drivers!P124 -> 17740.407 | AD17: =Drivers!Q124 -> 20398.97 | AE17: =Drivers!R124 -> 18777.895 | AF17: =Drivers!S124 -> 22537.232 | AG17: =Drivers!T124 -> 18858.053 | AH17: =Drivers!U124 -> 21684.105 | AI17: =Drivers!V124 -> 19960.902 | ... AV17: =Drivers!AI124 -> 28776.212
B18: Chilled / Frozen Foods & Beverages | C18: Historical | G18: 19265 | H18: 19107 | I18: 20216 | J18: 20773 | K18: 20232 | L18: 19645 | M18: 20354 | N18: 21235 | O18: 22939 | P18: 22309 | Q18: 23213 | R18: 23559 | S18: 24769 | T18: 23679 | U18: 25462 | V18: 25474 | W18: 25828 | X18: 24584 | Y18: 26154 | Z18: 26096 | AA18: 26988 | AB18: =Drivers!O125 -> 26298.615 | AC18: =Drivers!P125 -> 27978.115 | AD18: =Drivers!Q125 -> 27916.07 | AE18: =Drivers!R125 -> 28870.283 | AF18: =Drivers!S125 -> 28132.817 | AG18: =Drivers!T125 -> 29929.454 | AH18: =Drivers!U125 -> 29863.081 | AI18: =Drivers!V125 -> 30883.846 | ... AV18: =Drivers!AI125 -> 36841.268
B19: Confectionery / Snack | C19: Historical | G19: 10433 | H19: 15931 | I19: 17063 | J19: 17740 | K19: 17222 | L19: 17006 | M19: 17561 | N19: 17647 | O19: 19754 | P19: 19093 | Q19: 20750 | R19: 20129 | S19: 22377 | T19: 21893 | U19: 23072 | V19: 22388 | W19: 24325 | X19: 22658 | Y19: 23743 | Z19: 23460 | AA19: 24926 | AB19: =Drivers!O126 -> 26969.336 | AC19: =Drivers!P126 -> 28260.788 | AD19: =Drivers!Q126 -> 27923.939 | AE19: =Drivers!R126 -> 29668.888 | AF19: =Drivers!S126 -> 32101.027 | AG19: =Drivers!T126 -> 33638.215 | AH19: =Drivers!U126 -> 33237.271 | AI19: =Drivers!V126 -> 35314.246 | ... AV19: =Drivers!AI126 -> 64433.783
B20: Others | G20: =SUM(G21:G23) -> 6412 | H20: =SUM(H21:H23) -> 6552 | I20: =SUM(I21:I23) -> 6719 | J20: =SUM(J21:J23) -> 7003 | K20: =SUM(K21:K23) -> 7565 | L20: =SUM(L21:L23) -> 7023 | M20: =SUM(M21:M23) -> 8677 | N20: =SUM(N21:N23) -> 10573 | ... AV20: =SUM(AV21:AV23) -> 51963.208
B21: Domestic | C21: Historical | G21: 6412 | H21: 6552 | I21: 498 | J21: 564 | K21: 589 | L21: 520 | M21: 701 | N21: 1526 | O21: 1169 | P21: 1282 | Q21: 1442 | R21: 1678 | S21: 1393 | T21: 1569 | U21: 1761 | V21: 2100 | W21: 1721 | X21: 2210 | Y21: 1907 | Z21: 2383 | AA21: 2330 | AB21: =Drivers!O127 -> 3294.5035 | AC21: =Drivers!P127 -> 2842.8137 | AD21: =Drivers!Q127 -> 3552.399 | AE21: =Drivers!R127 -> 3473.3906 | AF21: =Drivers!S127 -> 4911.2007 | AG21: =Drivers!T127 -> 4237.855 | AH21: =Drivers!U127 -> 5295.6521 | AI21: =Drivers!V127 -> 5177.8722 | ... AV21: =Drivers!AI127 -> 24253.727
B22: Asia | C22: Historical | I22: 3391 | J22: 3879 | K22: 3905 | L22: 3602 | M22: 4557 | N22: 4867 | O22: 4966 | P22: 4205 | Q22: 5201 | R22: 5244 | S22: 5196 | T22: 5081 | U22: 6005 | V22: 5891 | W22: 5682 | X22: 5691 | Y22: 5064 | Z22: 5656 | AA22: 5951 | AB22: =Drivers!O128 -> 6291.1503 | AC22: =Drivers!P128 -> 5598.0294 | AD22: =Drivers!Q128 -> 6252.4594 | AE22: =Drivers!R128 -> 6578.5689 | AF22: =Drivers!S128 -> 6954.5901 | AG22: =Drivers!T128 -> 6188.3754 | AH22: =Drivers!U128 -> 6911.819 | AI22: =Drivers!V128 -> 7272.3187 | ... AV22: =Drivers!AI128 -> 10385.74
B23: EMEA | C23: Historical | I23: 2830 | J23: 2560 | K23: 3071 | L23: 2901 | M23: 3419 | N23: 4180 | O23: 4732 | P23: 5013 | Q23: 5156 | R23: 6191 | S23: 5549 | T23: 6397 | U23: 6180 | V23: 6455 | W23: 6535 | X23: 6368 | Y23: 5515 | Z23: 6772 | AA23: 7131 | AB23: =Drivers!O129 -> 7523.8967 | AC23: =Drivers!P129 -> 6516.0632 | AD23: =Drivers!Q129 -> 8001.2294 | AE23: =Drivers!R129 -> 8425.3938 | AF23: =Drivers!S129 -> 8889.6077 | AG23: =Drivers!T129 -> 7698.8358 | AH23: =Drivers!U129 -> 9453.5841 | AI23: =Drivers!V129 -> 9954.7413 | ... AV23: =Drivers!AI129 -> 17323.741
B24: Total Revenue | G24: =SUM(G13,G18:G20) -> 132723 | H24: =SUM(H13,H18:H20) -> 132248 | I24: =SUM(I13,I18:I20) -> 132454 | J24: =SUM(J13,J18:J20) -> 142576 | K24: =SUM(K13,K18:K20) -> 149754 | L24: =SUM(L13,L18:L20) -> 144928 | M24: =SUM(M13,M18:M20) -> 149259 | N24: =SUM(N13,N18:N20) -> 167687 | ... AV24: =SUM(AV13,AV18:AV20) -> 385670.93
D25: Growth % | E25: Margin %
B26: Cost of Sales | C26: Cost Schedule | D26: =Drivers!D108 -> 0.023 | E26: =Drivers!D109 -> 0.65527909 | G26: -84730 | H26: -87484 | I26: -85725 | J26: -93381 | K26: -96905 | L26: -99207 | M26: -100150 | N26: -112100 | O26: -121274 | P26: -114646 | Q26: -108485 | R26: -117321 | S26: -125522 | T26: -122975 | U26: -117980 | V26: -124434 | W26: -132337 | X26: -128891 | Y26: -116570 | Z26: -128399 | AA26: -138740 | AB26: =Drivers!O132 -> -135001.89 | AC26: =Drivers!P132 -> -122739.06 | AD26: =Drivers!Q132 -> -135256.5 | AE26: =Drivers!R132 -> -146276.37 | AF26: =Drivers!S132 -> -144700.04 | AG26: =Drivers!T132 -> -132285.51 | AH26: =Drivers!U132 -> -145669.14 | AI26: =Drivers!V132 -> -157482.07 | ... AV26: =Drivers!AI132 -> -220936.52
B27: Gross Profit | G27: =SUM(G24:G24,G26) -> 47993 | H27: =SUM(H24:H24,H26) -> 44764 | I27: =SUM(I24:I24,I26) -> 46729 | J27: =SUM(J24:J24,J26) -> 49195 | K27: =SUM(K24:K24,K26) -> 52849 | L27: =SUM(L24:L24,L26) -> 45721 | M27: =SUM(M24:M24,M26) -> 49109 | N27: =SUM(N24:N24,N26) -> 55587 | ... AV27: =SUM(AV24:AV24,AV26) -> 164734.41
B30: Operating Expenses
B31: SG&A Expense | C31: SG&A Schedule | G31: -36072 | H31: -40102 | I31: -34857 | J31: -36324 | K31: -38115 | L31: -42221 | M31: -37081 | N31: -42732 | O31: -44378 | P31: -49632 | Q31: -40223 | R31: -46180 | S31: -51890 | T31: -58959 | U31: -48178 | V31: -51575 | W31: -53561 | X31: -55956 | Y31: -47460 | Z31: -54053 | AA31: -56125 | AB31: =Drivers!H195 -> -57345.895 | AC31: =Drivers!I195 -> -52230.489 | AD31: =Drivers!J195 -> -60146.918 | AE31: =Drivers!K195 -> -65360.71 | AF31: =Drivers!L195 -> -66368.792 | AG31: =Drivers!M195 -> -60434.41 | AH31: =Drivers!N195 -> -67047.455 | AI31: =Drivers!O195 -> -72811.362 | ... AV31: =Drivers!AB195 -> -106360.47
B32: Other Income | C32: Normalised | G32: 5104 | H32: 868 | I32: =0.46*(1000) -> 460 | J32: =0.452*(1000) -> 452 | K32: =0.283*(1000) -> 283 | L32: =0.791*(1000) -> 791 | M32: =0.55*(1000) -> 550 | N32: =0.307*(1000) -> 307 | O32: =0.425*(1000) -> 425 | P32: =0.839*(1000) -> 839 | Q32: =0.39*(1000) -> 390 | R32: =0.397*(1000) -> 397 | S32: =0.342*(1000) -> 342 | T32: =1.203*(1000) -> 1203 | U32: =0.252*(1000) -> 252 | V32: =0.275*(1000) -> 275 | W32: =0.467*(1000) -> 467 | X32: =0.836*(1000) -> 836 | Y32: 254 | Z32: 298 | AA32: 279 | AB32: =AVERAGE(H32,L32,P32,T32,X32) -> 907.4 | AC32: =AVERAGE(I32,M32,Q32,U32,Y32) -> 381.2 | AD32: =AVERAGE(J32,N32,R32,V32,Z32) -> 345.8 | AE32: =AVERAGE(K32,O32,S32,W32,AA32) -> 359.2 | AF32: =AVERAGE(L32,P32,T32,X32,AB32) -> 915.28 | AG32: =AVERAGE(M32,Q32,U32,Y32,AC32) -> 365.44 | AH32: =AVERAGE(N32,R32,V32,Z32,AD32) -> 324.56 | AI32: =AVERAGE(O32,S32,W32,AA32,AE32) -> 374.44 | ... AV32: =AVERAGE(AB32,AF32,AJ32,AN32,AR32) -> 927.00301
B33: Other Expense | C33: Normalised | G33: -436 | H33: -867 | I33: -198 | J33: -318 | K33: -352 | L33: -1145 | M33: -156 | N33: -507 | O33: -492 | P33: -582 | Q33: -409 | R33: -349 | S33: -701 | T33: -1928 | U33: -459 | V33: -231 | W33: -3035 | X33: -635 | Y33: -427 | Z33: -321 | AA33: -584 | AB33: =AVERAGE(H33,L33,P33,T33,X33) -> -1031.4 | AC33: =AVERAGE(I33,M33,Q33,U33,Y33) -> -329.8 | AD33: =AVERAGE(J33,N33,R33,V33,Z33) -> -345.2 | AE33: =AVERAGE(K33,O33,S33,W33,AA33) -> -1032.8 | AF33: =AVERAGE(L33,P33,T33,X33,AB33) -> -1064.28 | AG33: =AVERAGE(M33,Q33,U33,Y33,AC33) -> -356.16 | AH33: =AVERAGE(N33,R33,V33,Z33,AD33) -> -350.64 | AI33: =AVERAGE(O33,S33,W33,AA33,AE33) -> -1168.96 | ... AV33: =AVERAGE(AB33,AF33,AJ33,AN33,AR33) -> -1053.843
B34: Gain on investments accounted for using the equity method | C34: Historical | D34: =AVERAGE(X34/T34-1,Y34/U34-1,Z34/V34-1,AA34/W34-1) -> 0.022821813 | G34: 1533 | H34: 903 | I34: 1112 | J34: 579 | K34: 1083 | L34: 880 | M34: 832 | N34: 1116 | O34: 2880 | P34: 3170 | Q34: 3136 | R34: 3576 | S34: 2876 | T34: 3449 | U34: 3186 | V34: 2723 | W34: 3111 | X34: 4197 | Y34: 3017 | Z34: 2241 | AA34: 3436 | AB34: =X34*(1+$D$34) -> 4292.7832 | AC34: =Y34*(1+$D$34) -> 3085.8534 | AD34: =Z34*(1+$D$34) -> 2292.1437 | AE34: =AA34*(1+$D$34) -> 3514.4158 | AF34: =AB34*(1+$D$34) -> 4390.7522 | AG34: =AC34*(1+$D$34) -> 3156.2782 | AH34: =AD34*(1+$D$34) -> 2344.4546 | AI34: =AE34*(1+$D$34) -> 3594.6211 | ... AV34: =AR34*(1+$D$34) -> 4805.5031
B35: Total Operating Income | G35: =SUM(G27,G31:G34) -> 18122 | H35: =SUM(H27,H31:H34) -> 5566 | I35: =SUM(I27,I31:I34) -> 13246 | J35: =SUM(J27,J31:J34) -> 13584 | K35: =SUM(K27,K31:K34) -> 15748 | L35: =SUM(L27,L31:L34) -> 4026 | M35: =SUM(M27,M31:M34) -> 13254 | N35: =SUM(N27,N31:N34) -> 13771 | ... AV35: =SUM(AV27,AV31:AV34) -> 63052.603
B37: Finance Income | C37: Normalised | G37: 607 | H37: 262 | I37: =-0.895*(-1000) -> 895 | J37: =-0.403*(-1000) -> 403 | K37: =-1.131*(-1000) -> 1131 | L37: =-0.641*(-1000) -> 641 | M37: =-1.035*(-1000) -> 1035 | N37: =-0.616*(-1000) -> 616 | O37: =-1.023*(-1000) -> 1023 | P37: =-0.582*(-1000) -> 582 | Q37: =-1.213*(-1000) -> 1213 | R37: =-0.756*(-1000) -> 756 | S37: =-1.155*(-1000) -> 1155 | T37: =-1.212*(-1000) -> 1212 | U37: =1.383*(1000) -> 1383 | V37: =-0.518*(-1000) -> 518 | W37: =-1.477*(-1000) -> 1477 | X37: 873 | Y37: 1512 | Z37: 969 | AA37: 1763 | AB37: =AVERAGE(H37,L37,P37,T37,X37) -> 714 | AC37: =AVERAGE(I37,M37,Q37,U37,Y37) -> 1207.6 | AD37: =AVERAGE(J37,N37,R37,V37,Z37) -> 652.4 | AE37: =AVERAGE(K37,O37,S37,W37,AA37) -> 1309.8 | AF37: =AVERAGE(L37,P37,T37,X37,AB37) -> 804.4 | AG37: =AVERAGE(M37,Q37,U37,Y37,AC37) -> 1270.12 | AH37: =AVERAGE(N37,R37,V37,Z37,AD37) -> 702.28 | AI37: =AVERAGE(O37,S37,W37,AA37,AE37) -> 1345.56 | ... AV37: =AVERAGE(AB37,AF37,AJ37,AN37,AR37) -> 813.37824
B38: Finance Costs | C38: Normalised | G38: -201 | H38: -273 | I38: =0.141*(-1000) -> -141 | J38: =0.125*(-1000) -> -125 | K38: =0.129*(-1000) -> -129 | L38: =0.107*(-1000) -> -107 | M38: =0.301*(-1000) -> -301 | N38: =0.322*(-1000) -> -322 | O38: =0.175*(-1000) -> -175 | P38: =0.145*(-1000) -> -145 | Q38: =0.132*(-1000) -> -132 | R38: =0.264*(-1000) -> -264 | S38: =0.386*(-1000) -> -386 | T38: 0 | U38: -315 | V38: -1091 | W38: -415 | X38: 0 | Y38: -747 | Z38: -252 | AA38: -648 | AB38: =AVERAGE(H38,L38,P38,T38,X38) -> -105 | AC38: =AVERAGE(I38,M38,Q38,U38,Y38) -> -327.2 | AD38: =AVERAGE(J38,N38,R38,V38,Z38) -> -410.8 | AE38: =AVERAGE(K38,O38,S38,W38,AA38) -> -350.6 | AF38: =AVERAGE(L38,P38,T38,X38,AB38) -> -71.4 | AG38: =AVERAGE(M38,Q38,U38,Y38,AC38) -> -364.44 | AH38: =AVERAGE(N38,R38,V38,Z38,AD38) -> -467.96 | AI38: =AVERAGE(O38,S38,W38,AA38,AE38) -> -394.92 | ... AV38: =AVERAGE(AB38,AF38,AJ38,AN38,AR38) -> -69.31584
B39: Profit before Tax | G39: =SUM(G35,G37:G38) -> 18528 | H39: =SUM(H35,H37:H38) -> 5555 | I39: =SUM(I35,I37:I38) -> 14000 | J39: =SUM(J35,J37:J38) -> 13862 | K39: =SUM(K35,K37:K38) -> 16750 | L39: =SUM(L35,L37:L38) -> 4560 | M39: =SUM(M35,M37:M38) -> 13988 | N39: =SUM(N35,N37:N38) -> 14065 | ... AV39: =SUM(AV35,AV37:AV38) -> 63796.665
B41: Income Tax Expense | C41: Eff Tax Rate | D41: =SUM(G41:AA41)/SUM(G39:AA39) -> -0.22016411 | G41: -3719 | H41: -429 | I41: -5438 | J41: -3890 | K41: -2269 | L41: 669 | M41: -5770 | N41: -3472 | O41: -3849 | P41: 3521 | Q41: -6819 | R41: -5392 | S41: -6101 | T41: 115 | U41: -5958 | V41: -4981 | W41: -4771 | X41: -2195 | Y41: -4792 | Z41: -4420 | AA41: -5088 | AB41: =AB39*$D$41 -> -6249.1743 | AC41: =AC39*$D$41 -> -5666.7132 | AD41: =AD39*$D$41 -> -5554.3214 | AE41: =AE39*$D$41 -> -6421.2396 | AF41: =AF39*$D$41 -> -7609.7648 | AG41: =AG39*$D$41 -> -6713.0138 | AH41: =AH39*$D$41 -> -7255.5348 | AI41: =AI39*$D$41 -> -8251.0206 | ... AV41: =AV39*$D$41 -> -14045.736
B42: Profit after Tax | G42: =SUM(G39,G41) -> 14809 | H42: =SUM(H39,H41) -> 5126 | I42: =SUM(I39,I41) -> 8562 | J42: =SUM(J39,J41) -> 9972 | K42: =SUM(K39,K41) -> 14481 | L42: =SUM(L39,L41) -> 5229 | M42: =SUM(M39,M41) -> 8218 | N42: =SUM(N39,N41) -> 10593 | ... AV42: =SUM(AV39,AV41) -> 49750.929
B44: NCI claim of Profit | C44: Historical Proportion | D44: =SUM(G44:AA44)/SUM(G42:AA42) -> 0.070072416 | G44: 505 | H44: =2511-1934 -> 577 | I44: 671 | J44: 746 | K44: 860 | L44: 564 | M44: 691 | N44: 744 | O44: 1134 | P44: 1051 | Q44: 1110 | R44: 1144 | S44: 1284 | T44: 1009 | U44: 1093 | V44: 1083 | W44: 593 | X44: 1105 | Y44: 598 | Z44: 893 | AA44: 1172 | AB44: =$D$44*AB42 -> 1551.0523 | AC44: =$D$44*AC42 -> 1406.4847 | AD44: =$D$44*AD42 -> 1378.589 | AE44: =$D$44*AE42 -> 1593.7591 | AF44: =$D$44*AF42 -> 1888.7524 | AG44: =$D$44*AG42 -> 1666.1778 | AH44: =$D$44*AH42 -> 1800.8321 | AI44: =$D$44*AI42 -> 2047.9128 | ... AV44: =$D$44*AV42 -> 3486.1678
B45: Profit to owners of parent | G45: =G42-G44 -> 14304 | H45: =H42-H44 -> 4549 | I45: =I42-I44 -> 7891 | J45: =J42-J44 -> 9226 | K45: =K42-K44 -> 13621 | L45: =L42-L44 -> 4665 | M45: =M42-M44 -> 7527 | N45: =N42-N44 -> 9849 | ... AV45: =AV42-AV44 -> 46264.761
B47: Total OCI | C47: Normalised | G47: 270 | H47: =27347-16346 -> 11001 | I47: 1987 | J47: 1078 | K47: 565 | L47: 16426 | M47: 13858 | N47: 11983 | O47: -10314 | P47: -7599 | Q47: 18841 | R47: 10866 | S47: -12421 | T47: 8680 | U47: 8489 | V47: -13232 | W47: 6704 | X47: -7402 | Y47: -292 | Z47: 14852 | AA47: 9633 | AB47: =AVERAGE(H47,L47,P47,T47,X47) -> 4221.2 | AC47: =AVERAGE(I47,M47,Q47,U47,Y47) -> 8576.6 | AD47: =AVERAGE(J47,N47,R47,V47,Z47) -> 5109.4 | AE47: =AVERAGE(K47,O47,S47,W47,AA47) -> -1166.6 | AF47: =AVERAGE(L47,P47,T47,X47,AB47) -> 2865.24 | AG47: =AVERAGE(M47,Q47,U47,Y47,AC47) -> 9894.52 | AH47: =AVERAGE(N47,R47,V47,Z47,AD47) -> 5915.68 | AI47: =AVERAGE(O47,S47,W47,AA47,AE47) -> -1512.92 | ... AV47: =AVERAGE(AB47,AF47,AJ47,AN47,AR47) -> 1850.2481
B48: Total Comprehensive Income | G48: =SUM(G42,G47) -> 15079 | H48: =SUM(H42,H47) -> 16127 | I48: =SUM(I42,I47) -> 10549 | J48: =SUM(J42,J47) -> 11050 | K48: =SUM(K42,K47) -> 15046 | L48: =SUM(L42,L47) -> 21655 | M48: =SUM(M42,M47) -> 22076 | N48: =SUM(N42,N47) -> 22576 | ... AA48: =SUM(AA42,AA47) -> 27244 | AB48: =SUM(AB45,AB47) -> 24805.138 | AC48: =SUM(AC45,AC47) -> 27241.99 | AD48: =SUM(AD45,AD47) -> 23404.586 | AE48: =SUM(AE45,AE47) -> 19984.098 | AF48: =SUM(AF45,AF47) -> 27930.78 | AG48: =SUM(AG45,AG47) -> 32006.283 | AH48: =SUM(AH45,AH47) -> 29814.434 | AI48: =SUM(AI45,AI47) -> 25664.83 | ... AV48: =SUM(AV45,AV47) -> 48115.01
...

Sheet Valuation
B2: Nissin Foods Holdings Co Ltd
B3: (2897 JT)
B5: DCF Model
B7: Discounted Cash Flow | L7: Terminal Value
D8: Period Start | E8: 45931 | F8: 46023 | G8: =F9+1 -> 46113 | H8: =G9+1 -> 46478 | I8: =H9+1 -> 46844 | J8: =I9+1 -> 47209 | K8: =J9+1 -> 47574 | L8: 47574
D9: Period End | E9: ='Operating Model'!AA6 -> 46022 | F9: 46112 | G9: =EOMONTH(G8,11) -> 46477 | H9: =EOMONTH(H8,11) -> 46843 | I9: =EOMONTH(I8,11) -> 47208 | J9: =EOMONTH(J8,11) -> 47573 | K9: =EOMONTH(K8,11) -> 47938 | L9: 47938
D10: FY | E10: ='Operating Model'!AA7 -> 2026 | F10: 2026 | G10: =F10+1 -> 2027 | H10: =G10+1 -> 2028 | I10: =H10+1 -> 2029 | J10: =I10+1 -> 2030 | K10: =J10+1 -> 2031 | L10: 2031
D11: Year Frac. | F11: =YEARFRAC(F9,E9) -> 0.25 | G11: =YEARFRAC(G9,F9) -> 1 | H11: =YEARFRAC(H9,G9) -> 1 | I11: =YEARFRAC(I9,H9) -> 1 | J11: =YEARFRAC(J9,I9) -> 1 | K11: =YEARFRAC(K9,J9) -> 1 | L11: =K11 -> 1
B13: EBIT | F13: ='Operating Model'!AB35 -> 27775.165 | G13: =SUM('Operating Model'!AC35:AF35) -> 111882.24 | H13: =SUM('Operating Model'!AG35:AJ35) -> 140175.92 | I13: =SUM('Operating Model'!AK35:AN35) -> 170862.69 | J13: =SUM('Operating Model'!AO35:AR35) -> 197556.3 | K13: =SUM('Operating Model'!AS35:AV35) -> 222646.77
B14: Less: Tax paid in Cash | F14: =SUM('Operating Model'!AB72) -> -6249.1743 | G14: =SUM('Operating Model'!AC72:AF72) -> -25252.039 | H14: =SUM('Operating Model'!AG72:AJ72) -> -31492.133 | I14: =SUM('Operating Model'!AK72:AN72) -> -38272.495 | J14: =SUM('Operating Model'!AO72:AR72) -> -44123.91 | K14: =SUM('Operating Model'!AS72:AV72) -> -49666.753
B15: NOPAT | F15: =SUM(F13:F14) -> 21525.99 | G15: =SUM(G13:G14) -> 86630.199 | H15: =SUM(H13:H14) -> 108683.79 | I15: =SUM(I13:I14) -> 132590.19 | J15: =SUM(J13:J14) -> 153432.39 | K15: =SUM(K13:K14) -> 172980.02
B16: Add: D&A | F16: ='Operating Model'!AB59 -> 9531.8664 | G16: =SUM('Operating Model'!AC59:AF59) -> 46511.462 | H16: =SUM('Operating Model'!AG59:AJ59) -> 54117.816 | I16: =SUM('Operating Model'!AK59:AN59) -> 57469.346 | J16: =SUM('Operating Model'!AO59:AR59) -> 65224.509 | K16: =SUM('Operating Model'!AS59:AV59) -> 76800.275
B17: Less: CapEx | F17: ='Operating Model'!AB78 -> -26847.665 | G17: =SUM('Operating Model'!AC78:AF78) -> -65049.583 | H17: =SUM('Operating Model'!AG78:AJ78) -> -58076.082 | I17: =SUM('Operating Model'!AK78:AN78) -> -84906.214 | J17: =SUM('Operating Model'!AO78:AR78) -> -91140.901 | K17: =SUM('Operating Model'!AS78:AV78) -> -82417.574
B18: Add: Cash from sale of PPE | F18: ='Operating Model'!AB79 -> 45.6 | G18: =SUM('Operating Model'!AC79:AF79) -> 262.52 | H18: =SUM('Operating Model'!AG79:AJ79) -> 184.624 | I18: =SUM('Operating Model'!AK79:AN79) -> 179.3488 | J18: =SUM('Operating Model'!AO79:AR79) -> 197.81856 | K18: =SUM('Operating Model'!AS79:AV79) -> 189.78227
B19: Less: Change in NCWC | F19: =SUM('Operating Model'!AB64:AB66) -> 18980.365 | G19: =SUM('Operating Model'!AC64:AF66) -> -8555.4961 | H19: =SUM('Operating Model'!AG64:AJ66) -> -7703.5271 | I19: =SUM('Operating Model'!AK64:AN66) -> -9044.3213 | J19: =SUM('Operating Model'!AO64:AR66) -> -9003.0248 | K19: =SUM('Operating Model'!AS64:AV66) -> -9961.2984
B20: Unlevered FCFF | F20: =SUM(F15:F19) -> 23236.157 | G20: =SUM(G15:G19) -> 59799.101 | H20: =SUM(H15:H19) -> 97206.618 | I20: =SUM(I15:I19) -> 96288.35 | J20: =SUM(J15:J19) -> 118710.79 | K20: =SUM(K15:K19) -> 157591.2 | L20: =K20*(1+0.035)/(D55-0.035) -> 24819281
B22: Intrinsic Value
B23: Enterprise Value | D23: =XNPV(D55,F20:L20,F9:L9) -> 20728760
B24: Add: Cash | D24: ='Operating Model'!AA112 -> 93710
B25: Less: Debt | D25: =-D43*1000 -> -135500
B26: Equity Value | D26: =SUM(D23:D25) -> 20686970
B27: Shares Outstanding (thousands) | D27: =10527344/1000 -> 10527.344
B28: Equity Value / Share | D28: =D26/D27 -> 1965.0702
B30: Bottom up Beta
B31: Company name | D31: 2Y Equity Beta | G31: Mkt cap | H31: D/E | I31: Marginal Tax Rate | K31: Asset Beta
B32: Ajinomoto | D32: 0.867 | G32: 3534.5 | H32: ='Relative Valuation'!AO11 -> 43.95 | I32: 0.22 | K32: =D32/(1+(1-I32)*H32) -> 0.024574133
B33: Kikkoman | D33: 0.776 | G33: 1467.7 | H33: ='Relative Valuation'!AO13 -> -10.47 | I33: 0.22 | K33: =D33/(1+(1-I33)*H33) -> -0.10828008
B34: Calbee | D34: 0.548 | G34: 405.8 | H34: ='Relative Valuation'!AO15 -> 7.94 | I34: 0.22 | K34: =D34/(1+(1-I34)*H34) -> 0.076183062
B35: Nisshin Seifun Group | D35: 0.582 | G35: 611.7 | H35: ='Relative Valuation'!AO17 -> -4.99 | I35: 0.22 | K35: =D35/(1+(1-I35)*H35) -> -0.2012309
B36: Ezaki Glico | D36: 0.516 | G36: 394 | H36: ='Relative Valuation'!AO19 -> -19.15 | I36: 0.22 | K36: =D36/(1+(1-I36)*H36) -> -0.03702375
B37: House Foods Group | D37: 0.487 | G37: 305.4 | H37: ='Relative Valuation'!AO21 -> -20.1 | I37: 0.22 | K37: =D37/(1+(1-I37)*H37) -> -0.033178907
B38: Average Beta | K38: =AVERAGE(K32:K37) -> -0.046492739
B40: WACC
G41: Source
B42: Marginal Tax rate | D42: 0.22 | G42: Bloomberg
B43: Total Debt | D43: =42.5+93 -> 135.5
B44: Mkt Cap | D44: ='Relative Valuation'!G5 -> 951.7
B45: Mkt D/E Ratio | D45: ='Relative Valuation'!AO5 -> 15.22
B46: Equity Beta | D46: ='Relative Valuation'!AE5 -> 0.579
B48: Market Risk Prem | D48: 0.04959
...

Sheet Relative Valuation
G2: Market Valuation | J2: LTM Financial Statistics | O2: LTM Profitability Margins | T2: Growth Rates | AE2: General | AG2: Return On Investment | AL2: LTM Leverage Ratios | AQ2: LTM Coverage Ratios | AU2: Enterprise Value | BJ2: Price / | BQ2: EV/EBITDA | CA2: P/E | CG2: PEG | CJ2: FCF Yield
E3: In Billions | T3: Sales | V3: EBITDA | Y3: EPS | BQ3: EV/EBITDA | CA3: P/E | CG3: PEG | CJ3: FCF Yield
B4: Company | E4: Ticker | F4: Currency | G4: Market Cap | H4: Enterprise Value | J4: Sales | K4: Gross Profit | L4: EBITDA (adj.) | M4: Net Income | O4: Gross Profit (%) | P4: EBITDA (%) | Q4: EBIT(%) | R4: Net Income (%) | T4: Hist. 1 year | U4: Est 1-year | V4: Hist 1. Year | W4: Est 1-year | Y4: Current | Z4: Hist 1-year. | AA4: Est. 1-year | AB4: Est. LT | AE4: 2 yr Regressional Beta | AG4: ROIC | AH4: ROE | AI4: ROA | AJ4: Implied Div. Yield | AL4: Debt/Total Assets | AM4: Debt/EBITDA | AN4: Net Debt / EBITDA | AO4: Net Debt/Equity | AQ4: EBITDA/Int. Exp. | AV4: LTM Sales | AW4: 2026E Sales | AX4: 2027E Sales | AZ4: LTM EBITDA | BA4: 2026E EBITDA | BB4: 2027E EBITDA | BD4: LTM EBIT | BE4: 2026E EBIT | BF4: 2027E EBIT | BH4: LTM EBITDA MARGIN | BJ4: LTM EPS | BK4: 2026E EPS | BL4: 2027E EPS | BN4: LT EPS GROWTH | BQ4: Current | BR4: 2026E | BS4: 2027E | BU4: 2026E EBITDA Margin | BV4: LTM Debt/ EBITDA | BW4: LTM Int Exp / EBITDA | BX4: EV/Sales | BY4: EV/EBIT | CA4: Current | CB4: 2026E | CC4: 2027E | CE4: LT EPS Growth | CG4: 2-Year Forward PEG | CH4: Dividend Yield | CJ4: 2026E
B5: NISSIN | E5: 2897 JT | F5: JPY | G5: 951.7 | H5: 1072 | J5: 780.9 | K5: 268.3 | L5: 89.5 | M5: 51 | O5: =K5/J5 -> 0.34357792 | P5: =L5/J5 -> 0.11461135 | Q5: =BD5/J5 -> 0.070431553 | R5: =M5/J5 -> 0.065309259 | T5: 732.9 | U5: 790.5 | V5: 92.4 | W5: 100.5 | Y5: 174.92 | Z5: 178.99 | AA5: 159.76 | AB5: 177.71 | AE5: 0.579 | AG5: 0.0611 | AH5: 0.1046 | AI5: 0.0555 | AJ5: =CH5 -> 0.0219 | AL5: 0.1596 | AM5: 2.11 | AN5: 0.91 | AO5: 15.22 | AQ5: 75.49 | AV5: 780.9 | AW5: 790.5 | AX5: 826.6 | AZ5: 89.5 | BA5: 100.5 | BB5: 110.3 | BD5: 55 | BE5: 64.8 | BF5: 70.9 | BH5: =AZ5/AV5 -> 0.11461135 | BJ5: =Y5 -> 174.92 | BK5: =AA5 -> 159.76 | BL5: =AB5 -> 177.71 | BN5: =(BL5/BJ5)-1 -> 0.015950149 | BQ5: 11.98 | BR5: 10.67 | BS5: 9.72 | BU5: =BA5/AW5 -> 0.12713472 | BV5: =AM5 -> 2.11 | BW5: =1/AQ5 -> 0.013246788 | BX5: =H5/AV5 -> 1.372775 | BY5: =H5/BD5 -> 19.490909 | CA5: 18.36 | CB5: 20.02 | CC5: 18 | CE5: =BN5 -> 0.015950149 | CG5: =CC5/1.6 -> 11.25 | CH5: 0.0219 | CJ5: -1.35
B6: Values | Y6: -0.0087 | Z6: -1.17857 | AA6: -0.45 | AB6: -0.26833 | AN6: =AN5*L5 -> 81.445
Z7: -1.17857 | AA7: -0.45 | AB7: -0.26833
B8: Tier 1: Core Japan Packaged Food Peers | AE8: Tier 1: Core Japan Packaged Food Peers | AU8: Tier 1: Core Japan Packaged Food Peers | BP8: Tier 1: Core Japan Packaged Food Peers
B11: Ajinomoto | E11: 2802 JT | F11: JPY | G11: 3534.5 | H11: 3970.4 | J11: 1543.7 | K11: 574.1 | L11: 241.1 | M11: 110.9 | O11: =K11/$J$11 -> 0.37189868 | P11: =L11/$J$11 -> 0.1561832 | Q11: =BD11/J11 -> 0.099501198 | R11: =M11/J11 -> 0.071840383 | T11: 1439.2 | U11: 1567.6 | V11: 214.3 | W11: 269.5 | Y11: 113.12 | Z11: 79.76 | AA11: 122.6 | AB11: 138.98 | AE11: 0.867 | AG11: 0.061 | AH11: 0.1047 | AI11: 0.044 | AJ11: 0.0122 | AL11: 0.2882 | AM11: 2.33 | AN11: 1.49 | AO11: 43.95 | AQ11: 27.17 | AV11: 1543.7 | AW11: 1567.6 | AX11: 1655.9 | AZ11: 241.1 | BA11: 269.5 | BB11: 294.4 | BD11: 153.6 | BE11: 181.5 | BF11: 202.3 | BH11: =AZ11/AV11 -> 0.1561832 | BJ11: 79.66 | BK11: 121.69 | BL11: 138.47 | BN11: =(BL11/BJ11)-1 -> 0.73826262 | BQ11: =H11/AZ11 -> 16.467856 | BR11: 14.73 | BS11: 13.49 | BU11: =BA11/AW11 -> 0.17191886 | BV11: =AN11 -> 1.49 | BW11: =1/AQ11 -> 0.0368053 | BX11: =H11/J11 -> 2.5720023 | BY11: =H11/BD11 -> 25.848958 | CA11: 45.38 | CB11: 29.49 | CC11: 26.01 | CE11: =BN11 -> 0.73826262 | CG11: =CC11/78.83 -> 0.32995053 | CH11: 0.0122 | CJ11: 3.37
B13: Kikkoman | E13: 2801 JT | F13: JPY | G13: 1467.7 | H13: 1417.3 | J13: 726.3 | K13: 244.4 | L13: 102.2 | M13: 60.8 | O13: =K13/J13 -> 0.33650007 | P13: =L13/J13 -> 0.1407132 | Q13: =BD13/J13 -> 0.10395154 | R13: =M13/J13 -> 0.083711965 | T13: 660.8 | U13: 732.9 | V13: 94.1 | W13: 104.4 | Y13: 64.92 | Z13: 60.5 | AA13: 65.01 | AB13: 68.27 | AE13: 0.776 | AG13: 0.0792 | AH13: 0.1092 | AI13: 0.0539 | AJ13: 0.0165 | AL13: 0.0869 | AM13: 0.59 | AN13: -0.57 | AO13: -10.47 | AQ13: 60.27 | AV13: =J11 -> 1543.7 | AW13: =U13 -> 732.9 | AX13: 773.5 | AZ13: =L13 -> 102.2 | BA13: =W13 -> 104.4 | BB13: 112.2 | BD13: 75.5 | BE13: 75.9 | BF13: 80 | BH13: =AZ13/AV13 -> 0.066204573 | BJ13: =Y13 -> 64.92 | BK13: =AA13 -> 65.01 | BL13: =AB13 -> 68.27 | BN13: =(BL13/BJ13)-1 -> 0.051601972 | BQ13: =H13/AZ13 -> 13.867906 | BR13: 13.57 | BS13: 12.64 | BU13: =BA13/AW13 -> 0.14244781 | BV13: =AN13 -> -0.57 | BW13: =1/AQ13 -> 0.016592003 | BX13: =H13/J13 -> 1.9513975 | BY13: =H13/BD13 -> 18.772185 | CA13: 23.86 | CB13: 23.29 | CC13: 22.18 | CE13: =BN13 -> 0.051601972 | CG13: =CC13/5.16 -> 4.2984496 | CH13: 0.0165 | CJ13: - | CS13: EV/EBITDA
CS14: FY | CU14: EBITDA | CW14: Range | CY14: 25th | CZ14: Diff | DA14: 75th | DB14: Enterprise Value | DE14: Debt | DF14: Equity Value | DI14: Shares outstanding | DK14: Low | DL14: Diff | DM14: High | DN14: Mean
B15: Calbee | E15: 2229 JT | F15: JPY | G15: 405.8 | H15: 434.2 | J15: 335.5 | K15: 108.4 | L15: 40.7 | M15: 16.8 | O15: =K15/J15 -> 0.32309985 | P15: =L15/J15 -> 0.12131148 | Q15: =BD15/J15 -> 0.070938897 | R15: =M15/J15 -> 0.050074516 | T15: 303 | U15: 337.3 | V15: 40 | W15: 42.5 | Y15: 135.35 | Z15: 163.75 | AA15: 141.86 | AB15: 160.08 | AE15: 0.548 | AG15: 0.0654 | AH15: 0.082 | AI15: 0.0522 | AJ15: =CH15 -> 0.0191 | AL15: 0.1145 | AM15: 1.28 | AN15: 0.42 | AO15: 7.94 | AQ15: 121.46 | AV15: =J15 -> 335.5 | AW15: =U15 -> 337.3 | AX15: 352.3 | AZ15: =L15 -> 40.7 | BA15: =W15 -> 42.5 | BB15: 45.9 | BD15: 23.8 | BE15: 26 | BF15: 29 | BH15: =AZ15/AV15 -> 0.12131148 | BJ15: =Y15 -> 135.35 | BK15: =AA15 -> 141.86 | BL15: =AB15 -> 160.08 | BN15: =(BL15/BJ15)-1 -> 0.18271149 | BQ15: =H15/AZ15 -> 10.668305 | BR15: 10.21 | BS15: 9.46 | BU15: =BA15/AW15 -> 0.12600059 | BV15: =AN15 -> 0.42 | BW15: =1/AQ15 -> 0.0082331632 | BX15: =H15/J15 -> 1.2941878 | BY15: =H15/BD15 -> 18.243697 | CA15: 23.35 | CB15: 21.36 | CC15: 18.93 | CE15: =BN15 -> 0.18271149 | CG15: =CC15/18.27 -> 1.0361248 | CH15: 0.0191 | CJ15: 2.65 | CS15: LTM Tier 1 | CU15: =AZ5 -> 89.5 | CW15: 9.18x-13.61x | CY15: 9.18 | CZ15: =DA15-CY15 -> 4.43 | DA15: 13.61 | DB15: =CU15*CY15 -> 821.61 | DC15: =CU15*CZ15 -> 396.485 | DD15: =CU15*DA15 -> 1218.095 | DE15: =AN6 -> 81.445 | DF15: =DB15-DE15 -> 740.165 | DG15: =DC15-DE15 -> 315.04 | DH15: =DD15-DE15 -> 1136.65 | DI15: 0.303 | DK15: =DF15/DI15 -> 2442.7888 | DL15: =DG15/DI15 -> 1039.736 | DM15: =DH15/DI15 -> 3751.3201 | DN15: =(DK15+DM15)/2 -> 3097.0545
CS16: 2026E Tier 1 | CU16: =BA5 -> 100.5 | CW16: 8.56x-13.15x | CY16: 8.56 | CZ16: =DA16-CY16 -> 4.59 | DA16: 13.15 | DB16: =CU16*CY16 -> 860.28 | DC16: =CU16*CZ16 -> 461.295 | DD16: =CU16*DA16 -> 1321.575 | DE16: 81.445 | DF16: =DB16-DE16 -> 778.835 | DG16: =DC16-DE16 -> 379.85 | DH16: =DD16-DE16 -> 1240.13 | DI16: 0.303 | DK16: =DF16/DI16 -> 2570.4125 | DL16: =DG16/DI16 -> 1253.6304 | DM16: =DH16/DI16 -> 4092.8383 | DN16: =(DK16+DM16)/2 -> 3331.6254
B17: Nisshin Seifun Group | E17: 2002 JT | F17: JPY | G17: 611.7 | H17: 604.7 | J17: 858 | K17: 191 | L17: 71.4 | M17: 29.1 | O17: =K17/J17 -> 0.22261072 | P17: =L17/J17 -> 0.083216783 | Q17: =BD17/J17 -> 0.051748252 | R17: =M17/J17 -> 0.033916084 | T17: 858.2 | U17: 862.7 | V17: 72.1 | W17: 75.8 | Y17: 100.54 | Z17: 109.4 | AA17: 110.51 | AB17: 138.88 | AE17: 0.582 | AG17: 0.0418 | AH17: 0.057 | AI17: 0.0346 | AJ17: =CH17 -> 0.0285 | AL17: 0.1085 | AM17: 1.24 | AN17: -0.37 | AO17: -4.99 | AQ17: 18.9 | AV17: =J17 -> 858 | AW17: =U17 -> 862.7 | AX17: 885.2 | AZ17: =L17 -> 71.4 | BA17: =W17 -> 75.8 | BB17: 80.5 | BD17: 44.4 | BE17: 47 | BF17: 50.9 | BH17: =AZ17/AV17 -> 0.083216783 | BJ17: =Y17 -> 100.54 | BK17: =AA17 -> 110.51 | BL17: =AB17 -> 138.88 | BN17: =(BL17/BJ17)-1 -> 0.38134076 | BQ17: =H17/AZ17 -> 8.4691877 | BR17: 7.98 | BS17: 7.51 | BU17: =BA17/AW17 -> 0.087863684 | BV17: =AN17 -> -0.37 | BW17: =1/AQ17 -> 0.052910053 | BX17: =H17/J17 -> 0.70477855 | BY17: =H17/BD17 -> 13.619369 | CA17: 22.47 | CB17: 19.04 | CC17: 15.15 | CE17: =BN17 -> 0.38134076 | CG17: =CC17/38.13 -> 0.39732494 | CH17: 0.0285 | CJ17: - | CS17: 2027E Tier 1 | CU17: =BB5 -> 110.3 | CW17: 8.00x-12.00x | CY17: 8 | CZ17: =DA17-CY17 -> 4 | DA17: 12 | DB17: =CU17*CY17 -> 882.4 | DC17: =CU17*CZ17 -> 441.2 | DD17: =CU17*DA17 -> 1323.6 | DE17: 81.445 | DF17: =DB17-DE17 -> 800.955 | DG17: =DC17-DE17 -> 359.755 | DH17: =DD17-DE17 -> 1242.155 | DI17: 0.303 | DK17: =DF17/DI17 -> 2643.4158 | DL17: =DG17/DI17 -> 1187.3102 | DM17: =DH17/DI17 -> 4099.5215 | DN17: =(DK17+DM17)/2 -> 3371.4686
CS18: LTM Tier 2 | CU18: =CU15 -> 89.5 | CW18: 8.9x-12.81x | CY18: 8.9 | CZ18: =DA18-CY18 -> 3.91 | DA18: 12.81 | DB18: =CU18*CY18 -> 796.55 | DC18: =CU18*CZ18 -> 349.945 | DD18: =CU18*DA18 -> 1146.495 | DE18: 81.445 | DF18: =DB18-DE18 -> 715.105 | DG18: =DC18-DE18 -> 268.5 | DH18: =DD18-DE18 -> 1065.05 | DI18: 0.303 | DK18: =DF18/DI18 -> 2360.0825 | DL18: =DG18/DI18 -> 886.13861 | DM18: =DH18/DI18 -> 3515.0165 | DN18: =(DK18+DM18)/2 -> 2937.5495
B19: Ezaki Glico | E19: 2206 JT | F19: JPY | G19: 394 | H19: 342.4 | J19: 354.7 | K19: 132.4 | L19: 26.7 | M19: 5.6 | O19: =K19/J19 -> 0.37327319 | P19: =L19/J19 -> 0.07527488 | Q19: =BD19/J19 -> 0.020862701 | R19: =M19/J19 -> 0.01578799 | T19: 332.6 | U19: 353.5 | V19: 32.6 | W19: 28.8 | Y19: 88.64 | Z19: 238.4 | AA19: 132.31 | AB19: 179.17 | AE19: 0.516 | AG19: 0.0173 | AH19: 0.021 | AI19: 0.0153 | AJ19: =CH19 -> 0.0165 | AL19: 0.0089 | AM19: 0.11 | AN19: -1.95 | AO19: -19.15 | AQ19: 302.38 | AV19: =J19 -> 354.7 | AW19: =U19 -> 353.5 | AX19: 362.8 | AZ19: =L19 -> 26.7 | BA19: =W19 -> 28.8 | BB19: 33.9 | BD19: 7.4 | BE19: 10.5 | BF19: 15.2 | BH19: =AZ19/AV19 -> 0.07527488 | BJ19: =Y19 -> 88.64 | BK19: =AA19 -> 132.31 | BL19: =AB19 -> 179.17 | BN19: =(BL19/BJ19)-1 -> 1.0213222 | BQ19: =H19/AZ19 -> 12.82397 | BR19: 11.89 | BS19: 10.09 | BU19: =BA19/AW19 -> 0.081471004 | BV19: =AN19 -> -1.95 | BW19: =1/AQ19 -> 0.003307097 | BX19: =H19/J19 -> 0.96532281 | BY19: =H19/BD19 -> 46.27027 | CA19: 51.12 | CB19: 43.5 | CC19: 32.12 | CE19: =BN19 -> 1.0213222 | CG19: =CC19/102.13 -> 0.31450113 | CH19: 0.0165 | CJ19: - | CS19: 2026E Tier 2 | CU19: =CU16 -> 100.5 | CW19: 7.91x-12.33x | CY19: 7.91 | CZ19: =DA19-CY19 -> 4.42 | DA19: 12.33 | DB19: =CU19*CY19 -> 794.955 | DC19: =CU19*CZ19 -> 444.21 | DD19: =CU19*DA19 -> 1239.165 | DE19: 81.445 | DF19: =DB19-DE19 -> 713.51 | DG19: =DC19-DE19 -> 362.765 | DH19: =DD19-DE19 -> 1157.72 | DI19: 0.303 | DK19: =DF19/DI19 -> 2354.8185 | DL19: =DG19/DI19 -> 1197.2442 | DM19: =DH19/DI19 -> 3820.8581 | DN19: =(DK19+DM19)/2 -> 3087.8383
CS20: 2027E Tier 2 | CU20: =CU17 -> 110.3 | CW20: 7.53x-9.68x | CY20: 7.53 | CZ20: =DA20-CY20 -> 2.15 | DA20: 9.68 | DB20: =CU20*CY20 -> 830.559 | DC20: =CU20*CZ20 -> 237.145 | DD20: =CU20*DA20 -> 1067.704 | DE20: 81.445 | DF20: =DB20-DE20 -> 749.114 | DG20: =DC20-DE20 -> 155.7 | DH20: =DD20-DE20 -> 986.259 | DI20: 0.303 | DK20: =DF20/DI20 -> 2472.3234 | DL20: =DG20/DI20 -> 513.86139 | DM20: =DH20/DI20 -> 3254.9802 | DN20: =(DK20+DM20)/2 -> 2863.6518
B21: House Foods Group | E21: 2810 JT | F21: JPY | G21: 305.4 | H21: 270 | J21: 318 | K21: 116.8 | L21: 31.1 | M21: 13 | O21: =K21/J21 -> 0.3672956 | P21: =L21/J21 -> 0.097798742 | Q21: =BD21/J21 -> 0.05408805 | R21: =M21/J21 -> 0.040880503 | T21: 299.6 | U21: 321.3 | V21: 33.1 | W21: 33.7 | Y21: 140.06 | Z21: 187.36 | AA21: 141.3 | AB21: 148.44 | AE21: 0.487 | AG21: 0.0376 | AH21: 0.0448 | AI21: 0.0302 | AJ21: =CH21 -> 0.0155 | AL21: 0.047 | AM21: 0.59 | AN21: -2.08 | AO21: -20.1 | AQ21: 347.67 | AV21: =J21 -> 318 | AW21: =U21 -> 321.3 | AX21: 322.1 | AZ21: =L21 -> 31.1 | BA21: =W21 -> 33.7 | BB21: 36 | BD21: 17.2 | BE21: 18.3 | BF21: 19.8 | BH21: =AZ21/AV21 -> 0.097798742 | BJ21: =Y21 -> 140.06 | BK21: =AA21 -> 141.3 | BL21: =AB21 -> 148.44 | BN21: =(BL21/BJ21)-1 -> 0.059831501 | BQ21: 8.68 | BR21: 8.01 | BS21: 7.5 | BU21: =BA21/AW21 -> 0.1048864 | BV21: =AN21 -> -2.08 | BW21: =1/AQ21 -> 0.0028762907 | BX21: =H21/J21 -> 0.8490566 | BY21: =H21/BD21 -> 15.697674 | CA21: 23.77 | CB21: 21.95 | CC21: 20.89 | CE21: =BN21 -> 0.059831501 | CG21: =CC21/5.98 -> 3.493311 | CH21: 0.0155 | CJ21: - | CS21: LTM Tier 3 | CU21: =CU15 -> 89.5 | CW21: 5.91x-12.96x | CY21: 5.91 | CZ21: =DA21-CY21 -> 7.05 | DA21: 12.96 | DB21: =CU21*CY21 -> 528.945 | DC21: =CU21*CZ21 -> 630.975 | DD21: =CU21*DA21 -> 1159.92 | DE21: 81.445 | DF21: =DB21-DE21 -> 447.5 | DG21: =DC21-DE21 -> 549.53 | DH21: =DD21-DE21 -> 1078.475 | DI21: 0.303 | DK21: =DF21/DI21 -> 1476.8977 | DL21: =DG21/DI21 -> 1813.6304 | DM21: =DH21/DI21 -> 3559.3234 | DN21: =(DK21+DM21)/2 -> 2518.1106
CS22: 2026E Tier 3 | CU22: =CU16 -> 100.5 | CW22: 5.26x-12.08x | CY22: 5.26 | CZ22: =DA22-CY22 -> 6.82 | DA22: 12.08 | DB22: =CU22*CY22 -> 528.63 | DC22: =CU22*CZ22 -> 685.41 | DD22: =CU22*DA22 -> 1214.04 | DE22: 81.445 | DF22: =DB22-DE22 -> 447.185 | DG22: =DC22-DE22 -> 603.965 | DH22: =DD22-DE22 -> 1132.595 | DI22: 0.303 | DK22: =DF22/DI22 -> 1475.8581 | DL22: =DG22/DI22 -> 1993.2838 | DM22: =DH22/DI22 -> 3737.9373 | DN22: =(DK22+DM22)/2 -> 2606.8977
B23: Mean | G23: =AVERAGE(G11:G21) -> 1119.85 | H23: =AVERAGE(H11:H21) -> 1173.1667 | J23: =AVERAGE(J11:J21) -> 689.36667 | K23: =AVERAGE(K11:K21) -> 227.85 | L23: =AVERAGE(L11:L21) -> 85.533333 | M23: =AVERAGE(M11:M21) -> 39.366667 | O23: =AVERAGE(O11:O21) -> 0.33244635 | P23: =AVERAGE(P11:P21) -> 0.11241638 | Q23: =AVERAGE(Q11:Q21) -> 0.066848439 | R23: =AVERAGE(R11:R21) -> 0.049368573 | T23: =AVERAGE(T11:T21) -> 648.9 | U23: =AVERAGE(U11:U21) -> 695.88333 | V23: =AVERAGE(V11:V21) -> 81.033333 | W23: =AVERAGE(W11:W21) -> 92.45 | Y23: =AVERAGE(Y11:Y21) -> 107.105 | Z23: =AVERAGE(Z11:Z21) -> 139.86167 | AA23: =AVERAGE(AA11:AA21) -> 118.93167 | AB23: =AVERAGE(AB11:AB21) -> 138.97 | AE23: Mean | AG23: =AVERAGE(AG11:AG21) -> 0.050383333 | AH23: =AVERAGE(AH11:AH21) -> 0.069783333 | AI23: =AVERAGE(AI11:AI21) -> 0.038366667 | AJ23: =AVERAGE(AJ11:AJ21) -> 0.01805 | AL23: =AVERAGE(AL11:AL21) -> 0.109 | AM23: =AVERAGE(AM11:AM21) -> 1.0233333 | AN23: =AVERAGE(AN11:AN21) -> -0.51 | AO23: =AVERAGE(AO11:AO21) -> -0.47 | AQ23: =AVERAGE(AQ11:AQ21) -> 146.30833 | AU23: Mean | AV23: =AVERAGE(AV11:AV21) -> 825.6 | AW23: =AVERAGE(AW11:AW21) -> 695.88333 | AX23: =AVERAGE(AX11:AX21) -> 725.3 | AZ23: =AVERAGE(AZ11:AZ21) -> 85.533333 | BA23: =AVERAGE(BA11:BA21) -> 92.45 | BB23: =AVERAGE(BB11:BB21) -> 100.48333 | BD23: =AVERAGE(BD11:BD21) -> 53.65 | BE23: =AVERAGE(BE11:BE21) -> 59.866667 | BF23: =AVERAGE(BF11:BF21) -> 66.2 | BH23: =AVERAGE(BH11:BH21) -> 0.099998275 | BJ23: =AVERAGE(BJ11:BJ21) -> 101.52833 | BK23: =AVERAGE(BK11:BK21) -> 118.78 | BL23: =AVERAGE(BL11:BL21) -> 138.885 | BN23: =AVERAGE(BN11:BN21) -> 0.40584509 | BP23: Mean | BQ23: =AVERAGE(BQ11:BQ21) -> 11.829537 | BR23: =AVERAGE(BR11:BR21) -> 11.065 | BS23: =AVERAGE(BS11:BS21) -> 10.115 | BU23: =AVERAGE(BU11:BU21) -> 0.11909806 | BV23: =AVERAGE(BV11:BV21) -> -0.51 | BW23: =AVERAGE(BW11:BW21) -> 0.020120651 | BX23: =AVERAGE(BX11:BX21) -> 1.3894576 | BY23: =AVERAGE(BY11:BY21) -> 23.075359 | CA23: =AVERAGE(CA11:CA21) -> 31.658333 | CB23: =AVERAGE(CB11:CB21) -> 26.438333 | CC23: =AVERAGE(CC11:CC21) -> 22.546667 | CE23: =AVERAGE(CE11:CE21) -> 0.40584509 | CG23: =AVERAGE(CG11:CG21) -> 1.6449437 | CH23: =AVERAGE(CH11:CH21) -> 0.01805 | CJ23: =AVERAGE(CJ11:CJ21) -> 3.01 | CS23: 2027E Tier 3 | CU23: =CU17 -> 110.3 | CW23: 6.50x-10.60x | CY23: 6.5 | CZ23: =DA23-CY23 -> 4.1 | DA23: 10.6 | DB23: =CU23*CY23 -> 716.95 | DC23: =CU23*CZ23 -> 452.23 | DD23: =CU23*DA23 -> 1169.18 | DE23: 81.445 | DF23: =DB23-DE23 -> 635.505 | DG23: =DC23-DE23 -> 370.785 | DH23: =DD23-DE23 -> 1087.735 | DI23: 0.303 | DK23: =DF23/DI23 -> 2097.3762 | DL23: =DG23/DI23 -> 1223.7129 | DM23: =DH23/DI23 -> 3589.8845 | DN23: =(DK23+DM23)/2 -> 2843.6304
B24: Median | G24: =MEDIAN(G11:G21) -> 508.75 | H24: =MEDIAN(H11:H21) -> 519.45 | J24: =MEDIAN(J11:J21) -> 540.5 | K24: =MEDIAN(K11:K21) -> 161.7 | L24: =MEDIAN(L11:L21) -> 56.05 | M24: =MEDIAN(M11:M21) -> 22.95 | O24: =MEDIAN(O11:O21) -> 0.35189783 | P24: =MEDIAN(P11:P21) -> 0.10955511 | Q24: =MEDIAN(Q11:Q21) -> 0.062513474 | R24: =MEDIAN(R11:R21) -> 0.045477509 | T24: =MEDIAN(T11:T21) -> 496.7 | U24: =MEDIAN(U11:U21) -> 543.2 | V24: =MEDIAN(V11:V21) -> 56.05 | W24: =MEDIAN(W11:W21) -> 59.15 | Y24: =MEDIAN(Y11:Y21) -> 106.83 | Z24: =MEDIAN(Z11:Z21) -> 136.575 | AA24: =MEDIAN(AA11:AA21) -> 127.455 | AB24: =MEDIAN(AB11:AB21) -> 143.71 | AE24: Median | AG24: =MEDIAN(AG11:AG21) -> 0.0514 | AH24: =MEDIAN(AH11:AH21) -> 0.0695 | AI24: =MEDIAN(AI11:AI21) -> 0.0393 | AJ24: =MEDIAN(AJ11:AJ21) -> 0.0165 | AL24: =MEDIAN(AL11:AL21) -> 0.0977 | AM24: =MEDIAN(AM11:AM21) -> 0.915 | AN24: =MEDIAN(AN11:AN21) -> -0.47 | AO24: =MEDIAN(AO11:AO21) -> -7.73 | AQ24: =MEDIAN(AQ11:AQ21) -> 90.865 | AU24: Median | AV24: =MEDIAN(AV11:AV21) -> 606.35 | AW24: =MEDIAN(AW11:AW21) -> 543.2 | AX24: =MEDIAN(AX11:AX21) -> 568.15 | AZ24: =MEDIAN(AZ11:AZ21) -> 56.05 | BA24: =MEDIAN(BA11:BA21) -> 59.15 | BB24: =MEDIAN(BB11:BB21) -> 63.2 | BD24: =MEDIAN(BD11:BD21) -> 34.1 | BE24: =MEDIAN(BE11:BE21) -> 36.5 | BF24: =MEDIAN(BF11:BF21) -> 39.95 | BH24: =MEDIAN(BH11:BH21) -> 0.090507763 | BJ24: =MEDIAN(BJ11:BJ21) -> 94.59 | BK24: =MEDIAN(BK11:BK21) -> 127 | BL24: =MEDIAN(BL11:BL21) -> 143.66 | BN24: =MEDIAN(BN11:BN21) -> 0.28202612 | BP24: Median | BQ24: =MEDIAN(BQ11:BQ21) -> 11.746137 | BR24: =MEDIAN(BR11:BR21) -> 11.05 | BS24: =MEDIAN(BS11:BS21) -> 9.775 | BU24: =MEDIAN(BU11:BU21) -> 0.1154435 | BV24: =MEDIAN(BV11:BV21) -> -0.47 | BW24: =MEDIAN(BW11:BW21) -> 0.012412583 | BX24: =MEDIAN(BX11:BX21) -> 1.1297553 | BY24: =MEDIAN(BY11:BY21) -> 18.507941 | CA24: =MEDIAN(CA11:CA21) -> 23.815 | CB24: =MEDIAN(CB11:CB21) -> 22.62 | CC24: =MEDIAN(CC11:CC21) -> 21.535 | CE24: =MEDIAN(CE11:CE21) -> 0.28202612 | CG24: =MEDIAN(CG11:CG21) -> 0.71672487 | CH24: =MEDIAN(CH11:CH21) -> 0.0165 | CJ24: =MEDIAN(CJ11:CJ21) -> 3.01
B25: 25th | G25: =_xlfn.PERCENTILE.INC(G11:G21,0.25) -> 396.95 | H25: =_xlfn.PERCENTILE.INC(H11:H21,0.25) -> 365.35 | J25: =_xlfn.PERCENTILE.INC(J11:J21,0.25) -> 340.3 | K25: =_xlfn.PERCENTILE.INC(K11:K21,0.25) -> 120.7 | L25: =_xlfn.PERCENTILE.INC(L11:L21,0.25) -> 33.5 | M25: =_xlfn.PERCENTILE.INC(M11:M21,0.25) -> 13.95 | O25: =_xlfn.PERCENTILE.INC(O11:O21,0.25) -> 0.32644991 | P25: =_xlfn.PERCENTILE.INC(P11:P21,0.25) -> 0.086862273 | Q25: =_xlfn.PERCENTILE.INC(Q11:Q21,0.25) -> 0.052333201 | R25: =_xlfn.PERCENTILE.INC(R11:R21,0.25) -> 0.035657189 | T25: =_xlfn.PERCENTILE.INC(T11:T21,0.25) -> 310.4 | U25: =_xlfn.PERCENTILE.INC(U11:U21,0.25) -> 341.35 | V25: =_xlfn.PERCENTILE.INC(V11:V21,0.25) -> 34.825 | W25: =_xlfn.PERCENTILE.INC(W11:W21,0.25) -> 35.9 | Y25: =_xlfn.PERCENTILE.INC(Y11:Y21,0.25) -> 91.615 | Z25: =_xlfn.PERCENTILE.INC(Z11:Z21,0.25) -> 87.17 | AA25: =_xlfn.PERCENTILE.INC(AA11:AA21,0.25) -> 113.5325 | AB25: =_xlfn.PERCENTILE.INC(AB11:AB21,0.25) -> 138.905 | AE25: 25th | AG25: =_xlfn.PERCENTILE.INC(AG11:AG21,0.25) -> 0.03865 | AH25: =_xlfn.PERCENTILE.INC(AH11:AH21,0.25) -> 0.04785 | AI25: =_xlfn.PERCENTILE.INC(AI11:AI21,0.25) -> 0.0313 | AJ25: =_xlfn.PERCENTILE.INC(AJ11:AJ21,0.25) -> 0.01575 | AL25: =_xlfn.PERCENTILE.INC(AL11:AL21,0.25) -> 0.056975 | AM25: =_xlfn.PERCENTILE.INC(AM11:AM21,0.25) -> 0.59 | AN25: =_xlfn.PERCENTILE.INC(AN11:AN21,0.25) -> -1.605 | AO25: =_xlfn.PERCENTILE.INC(AO11:AO21,0.25) -> -16.98 | AQ25: =_xlfn.PERCENTILE.INC(AQ11:AQ21,0.25) -> 35.445 | AU25: 25th | AV25: =_xlfn.PERCENTILE.INC(AV11:AV21,0.25) -> 340.3 | AW25: =_xlfn.PERCENTILE.INC(AW11:AW21,0.25) -> 341.35 | AX25: =_xlfn.PERCENTILE.INC(AX11:AX21,0.25) -> 354.925 | AZ25: =_xlfn.PERCENTILE.INC(AZ11:AZ21,0.25) -> 33.5 | BA25: =_xlfn.PERCENTILE.INC(BA11:BA21,0.25) -> 35.9 | BB25: =_xlfn.PERCENTILE.INC(BB11:BB21,0.25) -> 38.475 | BD25: =_xlfn.PERCENTILE.INC(BD11:BD21,0.25) -> 18.85 | BE25: =_xlfn.PERCENTILE.INC(BE11:BE21,0.25) -> 20.225 | BF25: =_xlfn.PERCENTILE.INC(BF11:BF21,0.25) -> 22.1 | BH25: =_xlfn.PERCENTILE.INC(BH11:BH21,0.25) -> 0.077260356 | BJ25: =_xlfn.PERCENTILE.INC(BJ11:BJ21,0.25) -> 81.905 | BK25: =_xlfn.PERCENTILE.INC(BK11:BK21,0.25) -> 113.305 | BL25: =_xlfn.PERCENTILE.INC(BL11:BL21,0.25) -> 138.5725 | BN25: =_xlfn.PERCENTILE.INC(BN11:BN21,0.25) -> 0.090551498 | BP25: 25th | BQ25: =_xlfn.PERCENTILE.INC(BQ11:BQ21,0.25) -> 9.1770762 | BR25: =_xlfn.PERCENTILE.INC(BR11:BR21,0.25) -> 8.56 | BS25: =_xlfn.PERCENTILE.INC(BS11:BS21,0.25) -> 7.9975 | BU25: =_xlfn.PERCENTILE.INC(BU11:BU21,0.25) -> 0.092119363 | BV25: =_xlfn.PERCENTILE.INC(BV11:BV21,0.25) -> -1.605 | BW25: =_xlfn.PERCENTILE.INC(BW11:BW21,0.25) -> 0.0045386136 | BX25: =_xlfn.PERCENTILE.INC(BX11:BX21,0.25) -> 0.87812315 | BY25: =_xlfn.PERCENTILE.INC(BY11:BY21,0.25) -> 16.33418 | CA25: =_xlfn.PERCENTILE.INC(CA11:CA21,0.25) -> 23.455 | CB25: =_xlfn.PERCENTILE.INC(CB11:CB21,0.25) -> 21.5075 | CC25: =_xlfn.PERCENTILE.INC(CC11:CC21,0.25) -> 19.42 | CE25: =_xlfn.PERCENTILE.INC(CE11:CE21,0.25) -> 0.090551498 | CG25: =_xlfn.PERCENTILE.INC(CG11:CG21,0.25) -> 0.34679413 | CH25: =_xlfn.PERCENTILE.INC(CH11:CH21,0.25) -> 0.01575 | CJ25: =_xlfn.PERCENTILE.INC(CJ11:CJ21,0.25) -> 2.83
